2022-11-10 16:18:47,052 - INFO - 

_____________________________new_log_____________________________
2022-11-10 16:18:48,620 - ERROR - {'message: exception when get comment in api': 'https://thanhnien.vn/api/comments/get/by-obj?object_type=20&object_id={1519473}', 'status_code': 200, 'link_post': 'https://thanhnien.vn/chay-nha-o-quan-8-nguoi-dan-hoang-so-nhieu-tai-san-bi-thieu-rui-post1519473.html'}
Traceback (most recent call last):
  File "C:\Users\Admin\Documents\schedule_crawl_comment\crawl_cmt.py", line 106, in crawl_in_post
    comment = check_regex(config_site['comment_in_post']['detect']['re'], [str(data)])[0]
IndexError: list index out of range
2022-11-10 16:18:48,629 - ERROR - {'message: exception when get comment in api': 'https://thanhnien.vn/api/comments/get/by-obj?object_type=20&object_id={1519591}', 'status_code': 200, 'link_post': 'https://thanhnien.vn/hang-tram-nguoi-tham-gia-dien-tap-chua-chay-toa-nha-time-square-post1519591.html'}
Traceback (most recent call last):
  File "C:\Users\Admin\Documents\schedule_crawl_comment\crawl_cmt.py", line 106, in crawl_in_post
    comment = check_regex(config_site['comment_in_post']['detect']['re'], [str(data)])[0]
IndexError: list index out of range
2022-11-10 16:18:48,629 - ERROR - {'message: exception when get comment in api': 'https://thanhnien.vn/api/comments/get/by-obj?object_type=20&object_id={1519476}', 'status_code': 200, 'link_post': 'https://thanhnien.vn/bi-csgt-lap-bien-ban-tai-xe-ngang-nguoc-cho-xe-dau-keo-chan-cao-toc-gay-un-tac-post1519476.html'}
Traceback (most recent call last):
  File "C:\Users\Admin\Documents\schedule_crawl_comment\crawl_cmt.py", line 106, in crawl_in_post
    comment = check_regex(config_site['comment_in_post']['detect']['re'], [str(data)])[0]
IndexError: list index out of range
2022-11-10 16:18:48,733 - ERROR - {'message: exception when get comment in api': 'https://thanhnien.vn/api/comments/get/by-obj?object_type=20&object_id={1519237}', 'status_code': 200, 'link_post': 'https://thanhnien.vn/son-da-ga-nghe-huynh-lap-ke-gap-ma-khi-quay-phim-ke-doc-hanh-post1519237.html'}
Traceback (most recent call last):
  File "C:\Users\Admin\Documents\schedule_crawl_comment\crawl_cmt.py", line 106, in crawl_in_post
    comment = check_regex(config_site['comment_in_post']['detect']['re'], [str(data)])[0]
IndexError: list index out of range
2022-11-10 16:18:48,763 - ERROR - {'message: exception when get comment in api': 'https://thanhnien.vn/api/comments/get/by-obj?object_type=20&object_id={1519574}', 'status_code': 200, 'link_post': 'https://thanhnien.vn/tam-dinh-chi-vu-an-lien-quan-ba-bo-con-chu-tich-tap-doan-tan-hiep-phat-post1519574.html'}
Traceback (most recent call last):
  File "C:\Users\Admin\Documents\schedule_crawl_comment\crawl_cmt.py", line 106, in crawl_in_post
    comment = check_regex(config_site['comment_in_post']['detect']['re'], [str(data)])[0]
IndexError: list index out of range
2022-11-10 16:18:48,773 - ERROR - {'message: exception when get comment in api': 'https://thanhnien.vn/api/comments/get/by-obj?object_type=20&object_id={1519497}', 'status_code': 200, 'link_post': 'https://thanhnien.vn/mao-danh-si-quan-quan-doi-muon-tien-nhung-khong-tra-hinh-su-hay-dan-su-post1519497.html'}
Traceback (most recent call last):
  File "C:\Users\Admin\Documents\schedule_crawl_comment\crawl_cmt.py", line 106, in crawl_in_post
    comment = check_regex(config_site['comment_in_post']['detect']['re'], [str(data)])[0]
IndexError: list index out of range
2022-11-10 16:18:48,864 - ERROR - {'message: exception when get comment in api': 'https://thanhnien.vn/api/comments/get/by-obj?object_type=20&object_id={1519432}', 'status_code': 200, 'link_post': 'https://thanhnien.vn/them-con-pho-o-ha-noi-co-lo-cot-an-ngu-day-dac-khien-dan-keu-troi-post1519432.html'}
Traceback (most recent call last):
  File "C:\Users\Admin\Documents\schedule_crawl_comment\crawl_cmt.py", line 106, in crawl_in_post
    comment = check_regex(config_site['comment_in_post']['detect']['re'], [str(data)])[0]
IndexError: list index out of range
2022-11-10 16:18:48,894 - ERROR - {'message: exception when get comment in api': 'https://thanhnien.vn/api/comments/get/by-obj?object_type=20&object_id={1519513}', 'status_code': 200, 'link_post': 'https://thanhnien.vn/tphcm-khach-uong-nuoc-mia-tien-tay-cuom-2-dien-thoai-cua-chu-quan-post1519513.html'}
Traceback (most recent call last):
  File "C:\Users\Admin\Documents\schedule_crawl_comment\crawl_cmt.py", line 106, in crawl_in_post
    comment = check_regex(config_site['comment_in_post']['detect']['re'], [str(data)])[0]
IndexError: list index out of range
2022-11-10 16:18:48,904 - ERROR - {'message: exception when get comment in api': 'https://thanhnien.vn/api/comments/get/by-obj?object_type=20&object_id={1519578}', 'status_code': 200, 'link_post': 'https://thanhnien.vn/viet-nam-campuchia-ky-ket-ban-ghi-nho-hop-tac-ve-lao-dong-post1519578.html'}
Traceback (most recent call last):
  File "C:\Users\Admin\Documents\schedule_crawl_comment\crawl_cmt.py", line 106, in crawl_in_post
    comment = check_regex(config_site['comment_in_post']['detect']['re'], [str(data)])[0]
IndexError: list index out of range
2022-11-10 16:18:49,013 - ERROR - {'message: exception when get comment in api': 'https://thanhnien.vn/api/comments/get/by-obj?object_type=20&object_id={1519494}', 'status_code': 200, 'link_post': 'https://thanhnien.vn/lam-dong-bat-tam-giam-4-nghi-pham-cuong-doat-tai-san-post1519494.html'}
Traceback (most recent call last):
  File "C:\Users\Admin\Documents\schedule_crawl_comment\crawl_cmt.py", line 106, in crawl_in_post
    comment = check_regex(config_site['comment_in_post']['detect']['re'], [str(data)])[0]
IndexError: list index out of range
2022-11-10 16:18:49,024 - ERROR - {'message: exception when get comment in api': 'https://thanhnien.vn/api/comments/get/by-obj?object_type=20&object_id={1519280}', 'status_code': 200, 'link_post': 'https://thanhnien.vn/binh-dinh-cham-giai-ngan-hon-50-kinh-phi-ho-tro-khac-phuc-hau-qua-thien-tai-post1519280.html'}
Traceback (most recent call last):
  File "C:\Users\Admin\Documents\schedule_crawl_comment\crawl_cmt.py", line 106, in crawl_in_post
    comment = check_regex(config_site['comment_in_post']['detect']['re'], [str(data)])[0]
IndexError: list index out of range
2022-11-10 16:18:49,024 - ERROR - {'message: exception when get comment in api': 'https://thanhnien.vn/api/comments/get/by-obj?object_type=20&object_id={1519561}', 'status_code': 200, 'link_post': 'https://thanhnien.vn/tphcm-bao-ve-dan-pho-cuong-doat-tai-san-5-trieu-dong-bi-phat-tu-post1519561.html'}
Traceback (most recent call last):
  File "C:\Users\Admin\Documents\schedule_crawl_comment\crawl_cmt.py", line 106, in crawl_in_post
    comment = check_regex(config_site['comment_in_post']['detect']['re'], [str(data)])[0]
IndexError: list index out of range
2022-11-10 16:18:49,162 - ERROR - {'message: exception when get comment in api': 'https://thanhnien.vn/api/comments/get/by-obj?object_type=20&object_id={1519491}', 'status_code': 200, 'link_post': 'https://thanhnien.vn/8-gio-tu-tphcm-ra-ha-noi-duong-sat-cao-toc-co-the-canh-tranh-voi-may-bay-post1519491.html'}
Traceback (most recent call last):
  File "C:\Users\Admin\Documents\schedule_crawl_comment\crawl_cmt.py", line 106, in crawl_in_post
    comment = check_regex(config_site['comment_in_post']['detect']['re'], [str(data)])[0]
IndexError: list index out of range
2022-11-10 16:18:49,172 - ERROR - {'message: exception when get comment in api': 'https://thanhnien.vn/api/comments/get/by-obj?object_type=20&object_id={1519574}', 'status_code': 200, 'link_post': 'https://thanhnien.vn/tam-dinh-chi-vu-an-lien-quan-ba-bo-con-chu-tich-tap-doan-tan-hiep-phat-post1519574.html'}
Traceback (most recent call last):
  File "C:\Users\Admin\Documents\schedule_crawl_comment\crawl_cmt.py", line 106, in crawl_in_post
    comment = check_regex(config_site['comment_in_post']['detect']['re'], [str(data)])[0]
IndexError: list index out of range
2022-11-10 16:18:49,172 - ERROR - {'message: exception when get comment in api': 'https://thanhnien.vn/api/comments/get/by-obj?object_type=20&object_id={1519501}', 'status_code': 200, 'link_post': 'https://thanhnien.vn/nguoi-ha-noi-kien-nhan-xep-hang-ca-dem-doi-mua-xang-post1519501.html'}
Traceback (most recent call last):
  File "C:\Users\Admin\Documents\schedule_crawl_comment\crawl_cmt.py", line 106, in crawl_in_post
    comment = check_regex(config_site['comment_in_post']['detect']['re'], [str(data)])[0]
IndexError: list index out of range
2022-11-10 16:18:49,284 - ERROR - {'message: exception when get comment in api': 'https://thanhnien.vn/api/comments/get/by-obj?object_type=20&object_id={1519561}', 'status_code': 200, 'link_post': 'https://thanhnien.vn/tphcm-bao-ve-dan-pho-cuong-doat-tai-san-5-trieu-dong-bi-phat-tu-post1519561.html'}
Traceback (most recent call last):
  File "C:\Users\Admin\Documents\schedule_crawl_comment\crawl_cmt.py", line 106, in crawl_in_post
    comment = check_regex(config_site['comment_in_post']['detect']['re'], [str(data)])[0]
IndexError: list index out of range
2022-11-10 16:18:49,294 - ERROR - {'message: exception when get comment in api': 'https://thanhnien.vn/api/comments/get/by-obj?object_type=20&object_id={1519546}', 'status_code': 200, 'link_post': 'https://thanhnien.vn/vinh-long-mot-cong-ty-vi-pham-pccc-bi-phat-90-trieu-dong-post1519546.html'}
Traceback (most recent call last):
  File "C:\Users\Admin\Documents\schedule_crawl_comment\crawl_cmt.py", line 106, in crawl_in_post
    comment = check_regex(config_site['comment_in_post']['detect']['re'], [str(data)])[0]
IndexError: list index out of range
2022-11-10 16:18:49,304 - ERROR - {'message: exception when get comment in api': 'https://thanhnien.vn/api/comments/get/by-obj?object_type=20&object_id={1519493}', 'status_code': 200, 'link_post': 'https://thanhnien.vn/binh-thuan-chuyen-ho-so-sai-pham-dat-dai-o-xa-hai-ninh-cho-cong-an-post1519493.html'}
Traceback (most recent call last):
  File "C:\Users\Admin\Documents\schedule_crawl_comment\crawl_cmt.py", line 106, in crawl_in_post
    comment = check_regex(config_site['comment_in_post']['detect']['re'], [str(data)])[0]
IndexError: list index out of range
2022-11-10 16:18:49,409 - ERROR - {'message: exception when get comment in api': 'https://thanhnien.vn/api/comments/get/by-obj?object_type=20&object_id={1519497}', 'status_code': 200, 'link_post': 'https://thanhnien.vn/mao-danh-si-quan-quan-doi-muon-tien-nhung-khong-tra-hinh-su-hay-dan-su-post1519497.html'}
Traceback (most recent call last):
  File "C:\Users\Admin\Documents\schedule_crawl_comment\crawl_cmt.py", line 106, in crawl_in_post
    comment = check_regex(config_site['comment_in_post']['detect']['re'], [str(data)])[0]
IndexError: list index out of range
2022-11-10 16:18:49,419 - ERROR - {'message: exception when get comment in api': 'https://thanhnien.vn/api/comments/get/by-obj?object_type=20&object_id={1519519}', 'status_code': 200, 'link_post': 'https://thanhnien.vn/cong-an-tphcm-dien-tap-tinh-huong-chay-no-cuu-nan-tai-toa-nha-times-square-post1519519.html'}
Traceback (most recent call last):
  File "C:\Users\Admin\Documents\schedule_crawl_comment\crawl_cmt.py", line 106, in crawl_in_post
    comment = check_regex(config_site['comment_in_post']['detect']['re'], [str(data)])[0]
IndexError: list index out of range
2022-11-10 16:18:49,421 - ERROR - {'message: exception when get comment in api': 'https://thanhnien.vn/api/comments/get/by-obj?object_type=20&object_id={1519319}', 'status_code': 200, 'link_post': 'https://thanhnien.vn/vu-san-tap-golf-sung-sung-tren-hanh-lang-de-viec-xu-ly-quay-lai-moc-ban-dau-post1519319.html'}
Traceback (most recent call last):
  File "C:\Users\Admin\Documents\schedule_crawl_comment\crawl_cmt.py", line 106, in crawl_in_post
    comment = check_regex(config_site['comment_in_post']['detect']['re'], [str(data)])[0]
IndexError: list index out of range
2022-11-10 16:18:49,523 - ERROR - {'message: exception when get comment in api': 'https://thanhnien.vn/api/comments/get/by-obj?object_type=20&object_id={1519574}', 'status_code': 200, 'link_post': 'https://thanhnien.vn/tam-dinh-chi-vu-an-lien-quan-ba-bo-con-chu-tich-tap-doan-tan-hiep-phat-post1519574.html'}
Traceback (most recent call last):
  File "C:\Users\Admin\Documents\schedule_crawl_comment\crawl_cmt.py", line 106, in crawl_in_post
    comment = check_regex(config_site['comment_in_post']['detect']['re'], [str(data)])[0]
IndexError: list index out of range
2022-11-10 16:18:49,543 - ERROR - {'message: exception when get comment in api': 'https://thanhnien.vn/api/comments/get/by-obj?object_type=20&object_id={1519501}', 'status_code': 200, 'link_post': 'https://thanhnien.vn/nguoi-ha-noi-kien-nhan-xep-hang-ca-dem-doi-mua-xang-post1519501.html'}
Traceback (most recent call last):
  File "C:\Users\Admin\Documents\schedule_crawl_comment\crawl_cmt.py", line 106, in crawl_in_post
    comment = check_regex(config_site['comment_in_post']['detect']['re'], [str(data)])[0]
IndexError: list index out of range
2022-11-10 16:18:49,569 - ERROR - {'message: exception when get comment in api': 'https://thanhnien.vn/api/comments/get/by-obj?object_type=20&object_id={1519510}', 'status_code': 200, 'link_post': 'https://thanhnien.vn/viet-nam-ho-tro-nhan-dao-305-cong-dan-sri-lanka-gap-nan-tren-bien-post1519510.html'}
Traceback (most recent call last):
  File "C:\Users\Admin\Documents\schedule_crawl_comment\crawl_cmt.py", line 106, in crawl_in_post
    comment = check_regex(config_site['comment_in_post']['detect']['re'], [str(data)])[0]
IndexError: list index out of range
2022-11-10 16:18:49,630 - ERROR - {'message: exception when get comment in api': 'https://thanhnien.vn/api/comments/get/by-obj?object_type=20&object_id={1519497}', 'status_code': 200, 'link_post': 'https://thanhnien.vn/mao-danh-si-quan-quan-doi-muon-tien-nhung-khong-tra-hinh-su-hay-dan-su-post1519497.html'}
Traceback (most recent call last):
  File "C:\Users\Admin\Documents\schedule_crawl_comment\crawl_cmt.py", line 106, in crawl_in_post
    comment = check_regex(config_site['comment_in_post']['detect']['re'], [str(data)])[0]
IndexError: list index out of range
2022-11-10 16:18:49,650 - ERROR - {'message: exception when get comment in api': 'https://thanhnien.vn/api/comments/get/by-obj?object_type=20&object_id={1519468}', 'status_code': 200, 'link_post': 'https://thanhnien.vn/phu-quoc-cuong-che-pha-do-2-can-biet-thu-xay-dung-trai-phep-post1519468.html'}
Traceback (most recent call last):
  File "C:\Users\Admin\Documents\schedule_crawl_comment\crawl_cmt.py", line 106, in crawl_in_post
    comment = check_regex(config_site['comment_in_post']['detect']['re'], [str(data)])[0]
IndexError: list index out of range
2022-11-10 16:18:49,672 - ERROR - {'message: exception when get comment in api': 'https://thanhnien.vn/api/comments/get/by-obj?object_type=20&object_id={1519319}', 'status_code': 200, 'link_post': 'https://thanhnien.vn/vu-san-tap-golf-sung-sung-tren-hanh-lang-de-viec-xu-ly-quay-lai-moc-ban-dau-post1519319.html'}
Traceback (most recent call last):
  File "C:\Users\Admin\Documents\schedule_crawl_comment\crawl_cmt.py", line 106, in crawl_in_post
    comment = check_regex(config_site['comment_in_post']['detect']['re'], [str(data)])[0]
IndexError: list index out of range
2022-11-10 16:18:49,744 - ERROR - {'message: exception when get comment in api': 'https://thanhnien.vn/api/comments/get/by-obj?object_type=20&object_id={1519467}', 'status_code': 200, 'link_post': 'https://thanhnien.vn/quyen-linh-phan-khich-co-gai-33-tuoi-chua-tung-yeu-thanh-doi-voi-giam-doc-tre-post1519467.html'}
Traceback (most recent call last):
  File "C:\Users\Admin\Documents\schedule_crawl_comment\crawl_cmt.py", line 106, in crawl_in_post
    comment = check_regex(config_site['comment_in_post']['detect']['re'], [str(data)])[0]
IndexError: list index out of range
2022-11-10 16:18:49,765 - ERROR - {'message: exception when get comment in api': 'https://thanhnien.vn/api/comments/get/by-obj?object_type=20&object_id={1472779}', 'status_code': 200, 'link_post': 'https://thanhnien.vn/chuyen-tinh-tu-ung-dung-hen-ho-co-gai-viet-ket-anh-tay-dien-trai-cao-1m95-post1472779.html'}
Traceback (most recent call last):
  File "C:\Users\Admin\Documents\schedule_crawl_comment\crawl_cmt.py", line 106, in crawl_in_post
    comment = check_regex(config_site['comment_in_post']['detect']['re'], [str(data)])[0]
IndexError: list index out of range
2022-11-10 16:18:49,795 - ERROR - {'message: exception when get comment in api': 'https://thanhnien.vn/api/comments/get/by-obj?object_type=20&object_id={1519406}', 'status_code': 200, 'link_post': 'https://thanhnien.vn/tranh-cai-co-nen-mac-ao-crop-top-ho-eo-di-lam-post1519406.html'}
Traceback (most recent call last):
  File "C:\Users\Admin\Documents\schedule_crawl_comment\crawl_cmt.py", line 106, in crawl_in_post
    comment = check_regex(config_site['comment_in_post']['detect']['re'], [str(data)])[0]
IndexError: list index out of range
2022-11-10 16:18:49,851 - ERROR - {'message: exception when get comment in api': 'https://thanhnien.vn/api/comments/get/by-obj?object_type=20&object_id={1519521}', 'status_code': 200, 'link_post': 'https://thanhnien.vn/giu-loi-hua-dam-vinh-hung-tai-tro-hon-300-trieu-giup-ban-sao-phau-thuat-mat-post1519521.html'}
Traceback (most recent call last):
  File "C:\Users\Admin\Documents\schedule_crawl_comment\crawl_cmt.py", line 106, in crawl_in_post
    comment = check_regex(config_site['comment_in_post']['detect']['re'], [str(data)])[0]
IndexError: list index out of range
2022-11-10 16:18:49,861 - ERROR - {'message: exception when get comment in api': 'https://thanhnien.vn/api/comments/get/by-obj?object_type=20&object_id={1518145}', 'status_code': 200, 'link_post': 'https://thanhnien.vn/honda-wr-v-2023-gia-duoi-500-trieu-ky-vong-ve-viet-nam-dau-toyota-raize-post1518145.html'}
Traceback (most recent call last):
  File "C:\Users\Admin\Documents\schedule_crawl_comment\crawl_cmt.py", line 106, in crawl_in_post
    comment = check_regex(config_site['comment_in_post']['detect']['re'], [str(data)])[0]
IndexError: list index out of range
2022-11-10 16:18:49,901 - ERROR - {'message: exception when get comment in api': 'https://thanhnien.vn/api/comments/get/by-obj?object_type=20&object_id={1519489}', 'status_code': 200, 'link_post': 'https://thanhnien.vn/lo-anh-tran-trui-toyota-innova-2023-dang-gan-giong-suv-post1519489.html'}
Traceback (most recent call last):
  File "C:\Users\Admin\Documents\schedule_crawl_comment\crawl_cmt.py", line 106, in crawl_in_post
    comment = check_regex(config_site['comment_in_post']['detect']['re'], [str(data)])[0]
IndexError: list index out of range
2022-11-10 16:18:49,943 - ERROR - {'message: exception when get comment in api': 'https://thanhnien.vn/api/comments/get/by-obj?object_type=20&object_id={1519491}', 'status_code': 200, 'link_post': 'https://thanhnien.vn/8-gio-tu-tphcm-ra-ha-noi-duong-sat-cao-toc-co-the-canh-tranh-voi-may-bay-post1519491.html'}
Traceback (most recent call last):
  File "C:\Users\Admin\Documents\schedule_crawl_comment\crawl_cmt.py", line 106, in crawl_in_post
    comment = check_regex(config_site['comment_in_post']['detect']['re'], [str(data)])[0]
IndexError: list index out of range
2022-11-10 16:18:49,977 - ERROR - {'message: exception when get comment in api': 'https://thanhnien.vn/api/comments/get/by-obj?object_type=20&object_id={1519578}', 'status_code': 200, 'link_post': 'https://thanhnien.vn/viet-nam-campuchia-ky-ket-ban-ghi-nho-hop-tac-ve-lao-dong-post1519578.html'}
Traceback (most recent call last):
  File "C:\Users\Admin\Documents\schedule_crawl_comment\crawl_cmt.py", line 106, in crawl_in_post
    comment = check_regex(config_site['comment_in_post']['detect']['re'], [str(data)])[0]
IndexError: list index out of range
2022-11-10 16:18:50,008 - ERROR - {'message: exception when get comment in api': 'https://thanhnien.vn/api/comments/get/by-obj?object_type=20&object_id={1519561}', 'status_code': 200, 'link_post': 'https://thanhnien.vn/tphcm-bao-ve-dan-pho-cuong-doat-tai-san-5-trieu-dong-bi-phat-tu-post1519561.html'}
Traceback (most recent call last):
  File "C:\Users\Admin\Documents\schedule_crawl_comment\crawl_cmt.py", line 106, in crawl_in_post
    comment = check_regex(config_site['comment_in_post']['detect']['re'], [str(data)])[0]
IndexError: list index out of range
2022-11-10 16:18:50,038 - ERROR - {'message: exception when get comment in api': 'https://thanhnien.vn/api/comments/get/by-obj?object_type=20&object_id={1519546}', 'status_code': 200, 'link_post': 'https://thanhnien.vn/vinh-long-mot-cong-ty-vi-pham-pccc-bi-phat-90-trieu-dong-post1519546.html'}
Traceback (most recent call last):
  File "C:\Users\Admin\Documents\schedule_crawl_comment\crawl_cmt.py", line 106, in crawl_in_post
    comment = check_regex(config_site['comment_in_post']['detect']['re'], [str(data)])[0]
IndexError: list index out of range
2022-11-10 16:18:50,078 - ERROR - {'message: exception when get comment in api': 'https://thanhnien.vn/api/comments/get/by-obj?object_type=20&object_id={1519508}', 'status_code': 200, 'link_post': 'https://thanhnien.vn/ca-mau-hoa-hoan-luc-rang-sang-4-can-nha-bi-thieu-rui-post1519508.html'}
Traceback (most recent call last):
  File "C:\Users\Admin\Documents\schedule_crawl_comment\crawl_cmt.py", line 106, in crawl_in_post
    comment = check_regex(config_site['comment_in_post']['detect']['re'], [str(data)])[0]
IndexError: list index out of range
2022-11-10 16:18:50,115 - ERROR - {'message: exception when get comment in api': 'https://thanhnien.vn/api/comments/get/by-obj?object_type=20&object_id={1519493}', 'status_code': 200, 'link_post': 'https://thanhnien.vn/binh-thuan-chuyen-ho-so-sai-pham-dat-dai-o-xa-hai-ninh-cho-cong-an-post1519493.html'}
Traceback (most recent call last):
  File "C:\Users\Admin\Documents\schedule_crawl_comment\crawl_cmt.py", line 106, in crawl_in_post
    comment = check_regex(config_site['comment_in_post']['detect']['re'], [str(data)])[0]
IndexError: list index out of range
2022-11-10 16:18:50,197 - ERROR - {'message: exception when get comment in api': 'https://thanhnien.vn/api/comments/get/by-obj?object_type=20&object_id={1519516}', 'status_code': 200, 'link_post': 'https://thanhnien.vn/bo-chqs-tinh-thua-thien-hue-tang-qua-chia-se-kho-khan-voi-dong-nghiep-lao-post1519516.html'}
Traceback (most recent call last):
  File "C:\Users\Admin\Documents\schedule_crawl_comment\crawl_cmt.py", line 106, in crawl_in_post
    comment = check_regex(config_site['comment_in_post']['detect']['re'], [str(data)])[0]
IndexError: list index out of range
2022-11-10 16:18:50,197 - ERROR - {'message: exception when get comment in api': 'https://thanhnien.vn/api/comments/get/by-obj?object_type=20&object_id={1519552}', 'status_code': 200, 'link_post': 'https://thanhnien.vn/doanh-nghiep-cong-an-quan-doi-duoc-cap-them-bang-tan-de-phat-trien-kinh-te-post1519552.html'}
Traceback (most recent call last):
  File "C:\Users\Admin\Documents\schedule_crawl_comment\crawl_cmt.py", line 106, in crawl_in_post
    comment = check_regex(config_site['comment_in_post']['detect']['re'], [str(data)])[0]
IndexError: list index out of range
2022-11-10 16:18:50,259 - ERROR - {'message: exception when get comment in api': 'https://thanhnien.vn/api/comments/get/by-obj?object_type=20&object_id={1519418}', 'status_code': 200, 'link_post': 'https://thanhnien.vn/tu-tai-xe-uber-thanh-nghi-si-gen-z-dau-tien-tai-quoc-hoi-my-post1519418.html'}
Traceback (most recent call last):
  File "C:\Users\Admin\Documents\schedule_crawl_comment\crawl_cmt.py", line 106, in crawl_in_post
    comment = check_regex(config_site['comment_in_post']['detect']['re'], [str(data)])[0]
IndexError: list index out of range
2022-11-10 16:18:50,309 - ERROR - {'message: exception when get comment in api': 'https://thanhnien.vn/api/comments/get/by-obj?object_type=20&object_id={1519483}', 'status_code': 200, 'link_post': 'https://thanhnien.vn/to-chuc-giai-thuong-thuong-kotler-awards-danh-cho-cac-nha-marketing-post1519483.html'}
Traceback (most recent call last):
  File "C:\Users\Admin\Documents\schedule_crawl_comment\crawl_cmt.py", line 106, in crawl_in_post
    comment = check_regex(config_site['comment_in_post']['detect']['re'], [str(data)])[0]
IndexError: list index out of range
2022-11-10 16:18:50,309 - ERROR - {'message: exception when get comment in api': 'https://thanhnien.vn/api/comments/get/by-obj?object_type=20&object_id={1519474}', 'status_code': 200, 'link_post': 'https://thanhnien.vn/mot-thanh-nien-bi-cao-buoc-dot-7-toa-nha-trong-ngay-bau-cu-o-my-post1519474.html'}
Traceback (most recent call last):
  File "C:\Users\Admin\Documents\schedule_crawl_comment\crawl_cmt.py", line 106, in crawl_in_post
    comment = check_regex(config_site['comment_in_post']['detect']['re'], [str(data)])[0]
IndexError: list index out of range
2022-11-10 16:18:50,376 - ERROR - {'message: exception when get comment in api': 'https://thanhnien.vn/api/comments/get/by-obj?object_type=20&object_id={1519446}', 'status_code': 200, 'link_post': 'https://thanhnien.vn/lanh-dao-the-gioi-di-dong-chung-khoan-everest-chi-tien-ti-gom-mua-co-phieu-post1519446.html'}
Traceback (most recent call last):
  File "C:\Users\Admin\Documents\schedule_crawl_comment\crawl_cmt.py", line 106, in crawl_in_post
    comment = check_regex(config_site['comment_in_post']['detect']['re'], [str(data)])[0]
IndexError: list index out of range
2022-11-10 16:18:50,426 - ERROR - {'message: exception when get comment in api': 'https://thanhnien.vn/api/comments/get/by-obj?object_type=20&object_id={1519514}', 'status_code': 200, 'link_post': 'https://thanhnien.vn/giang-vien-khoa-duoc-re-loi-sang-day-tieng-anh-va-ly-do-bat-ngo-post1519514.html'}
Traceback (most recent call last):
  File "C:\Users\Admin\Documents\schedule_crawl_comment\crawl_cmt.py", line 106, in crawl_in_post
    comment = check_regex(config_site['comment_in_post']['detect']['re'], [str(data)])[0]
IndexError: list index out of range
2022-11-10 16:18:50,439 - ERROR - {'message: exception when get comment in api': 'https://thanhnien.vn/api/comments/get/by-obj?object_type=20&object_id={1519557}', 'status_code': 200, 'link_post': 'https://thanhnien.vn/nu-sinh-lop-8-bi-nhom-ban-den-phong-tro-danh-dap-quay-clip-tung-len-mang-post1519557.html'}
Traceback (most recent call last):
  File "C:\Users\Admin\Documents\schedule_crawl_comment\crawl_cmt.py", line 106, in crawl_in_post
    comment = check_regex(config_site['comment_in_post']['detect']['re'], [str(data)])[0]
IndexError: list index out of range
2022-11-10 16:18:50,489 - ERROR - {'message: exception when get comment in api': 'https://thanhnien.vn/api/comments/get/by-obj?object_type=20&object_id={1519488}', 'status_code': 200, 'link_post': 'https://thanhnien.vn/vi-sao-nhieu-sinh-vien-su-pham-van-phai-dong-hoc-phi-post1519488.html'}
Traceback (most recent call last):
  File "C:\Users\Admin\Documents\schedule_crawl_comment\crawl_cmt.py", line 106, in crawl_in_post
    comment = check_regex(config_site['comment_in_post']['detect']['re'], [str(data)])[0]
IndexError: list index out of range
2022-11-10 16:18:50,563 - ERROR - {'message: exception when get comment in api': 'https://thanhnien.vn/api/comments/get/by-obj?object_type=20&object_id={1519259}', 'status_code': 200, 'link_post': 'https://thanhnien.vn/hanh-trinh-dong-day-yeu-thuong-den-voi-tre-em-vung-cao-post1519259.html'}
Traceback (most recent call last):
  File "C:\Users\Admin\Documents\schedule_crawl_comment\crawl_cmt.py", line 106, in crawl_in_post
    comment = check_regex(config_site['comment_in_post']['detect']['re'], [str(data)])[0]
IndexError: list index out of range
2022-11-10 16:18:50,563 - ERROR - {'message: exception when get comment in api': 'https://thanhnien.vn/api/comments/get/by-obj?object_type=20&object_id={1519464}', 'status_code': 200, 'link_post': 'https://thanhnien.vn/ha-noi-khuyen-khich-phu-huynh-dung-so-lien-lac-dien-tu-mien-phi-post1519464.html'}
Traceback (most recent call last):
  File "C:\Users\Admin\Documents\schedule_crawl_comment\crawl_cmt.py", line 106, in crawl_in_post
    comment = check_regex(config_site['comment_in_post']['detect']['re'], [str(data)])[0]
IndexError: list index out of range
2022-11-10 16:18:50,614 - ERROR - {'message: exception when call api': 'https://thanhnien.vn/api/comments/get/by-obj?object_type=20&object_id={1519392}', 'status_code': 403, 'link_post': 'https://thanhnien.vn/co-gai-cao-nhat-the-gioi-di-may-bay-nhu-the-nao-post1519392.html'}
Traceback (most recent call last):
  File "C:\Users\Admin\Documents\schedule_crawl_comment\venv\lib\site-packages\requests\models.py", line 971, in json
    return complexjson.loads(self.text, **kwargs)
  File "C:\Python\Python39\lib\json\__init__.py", line 346, in loads
    return _default_decoder.decode(s)
  File "C:\Python\Python39\lib\json\decoder.py", line 337, in decode
    obj, end = self.raw_decode(s, idx=_w(s, 0).end())
  File "C:\Python\Python39\lib\json\decoder.py", line 355, in raw_decode
    raise JSONDecodeError("Expecting value", s, err.value) from None
json.decoder.JSONDecodeError: Expecting value: line 1 column 1 (char 0)

During handling of the above exception, another exception occurred:

Traceback (most recent call last):
  File "C:\Users\Admin\Documents\schedule_crawl_comment\crawl_cmt.py", line 98, in crawl_in_post
    data = detect_responseType(config_site['comment_in_post']['responseType'], res)
  File "C:\Users\Admin\Documents\schedule_crawl_comment\crawl_cmt.py", line 177, in detect_responseType
    return res.json()
  File "C:\Users\Admin\Documents\schedule_crawl_comment\venv\lib\site-packages\requests\models.py", line 975, in json
    raise RequestsJSONDecodeError(e.msg, e.doc, e.pos)
requests.exceptions.JSONDecodeError: Expecting value: line 1 column 1 (char 0)
2022-11-10 16:18:50,634 - ERROR - {'message: exception when get comment in api': 'https://thanhnien.vn/api/comments/get/by-obj?object_type=20&object_id={1519392}', 'status_code': 403, 'link_post': 'https://thanhnien.vn/co-gai-cao-nhat-the-gioi-di-may-bay-nhu-the-nao-post1519392.html'}
Traceback (most recent call last):
  File "C:\Users\Admin\Documents\schedule_crawl_comment\crawl_cmt.py", line 106, in crawl_in_post
    comment = check_regex(config_site['comment_in_post']['detect']['re'], [str(data)])[0]
UnboundLocalError: local variable 'data' referenced before assignment
2022-11-10 16:18:50,674 - ERROR - {'message: exception when call api': 'https://thanhnien.vn/api/comments/get/by-obj?object_type=20&object_id={1519500}', 'status_code': 403, 'link_post': 'https://thanhnien.vn/cuoc-song-cua-khanh-trung-khanh-don-sau-17-nam-nhom-huyen-thoai-ra-mat-post1519500.html'}
Traceback (most recent call last):
  File "C:\Users\Admin\Documents\schedule_crawl_comment\venv\lib\site-packages\requests\models.py", line 971, in json
    return complexjson.loads(self.text, **kwargs)
  File "C:\Python\Python39\lib\json\__init__.py", line 346, in loads
    return _default_decoder.decode(s)
  File "C:\Python\Python39\lib\json\decoder.py", line 337, in decode
    obj, end = self.raw_decode(s, idx=_w(s, 0).end())
  File "C:\Python\Python39\lib\json\decoder.py", line 355, in raw_decode
    raise JSONDecodeError("Expecting value", s, err.value) from None
json.decoder.JSONDecodeError: Expecting value: line 1 column 1 (char 0)

During handling of the above exception, another exception occurred:

Traceback (most recent call last):
  File "C:\Users\Admin\Documents\schedule_crawl_comment\crawl_cmt.py", line 98, in crawl_in_post
    data = detect_responseType(config_site['comment_in_post']['responseType'], res)
  File "C:\Users\Admin\Documents\schedule_crawl_comment\crawl_cmt.py", line 177, in detect_responseType
    return res.json()
  File "C:\Users\Admin\Documents\schedule_crawl_comment\venv\lib\site-packages\requests\models.py", line 975, in json
    raise RequestsJSONDecodeError(e.msg, e.doc, e.pos)
requests.exceptions.JSONDecodeError: Expecting value: line 1 column 1 (char 0)
2022-11-10 16:18:50,674 - ERROR - {'message: exception when get comment in api': 'https://thanhnien.vn/api/comments/get/by-obj?object_type=20&object_id={1519500}', 'status_code': 403, 'link_post': 'https://thanhnien.vn/cuoc-song-cua-khanh-trung-khanh-don-sau-17-nam-nhom-huyen-thoai-ra-mat-post1519500.html'}
Traceback (most recent call last):
  File "C:\Users\Admin\Documents\schedule_crawl_comment\crawl_cmt.py", line 106, in crawl_in_post
    comment = check_regex(config_site['comment_in_post']['detect']['re'], [str(data)])[0]
UnboundLocalError: local variable 'data' referenced before assignment
2022-11-10 16:18:50,694 - ERROR - {'message: exception when call api': 'https://thanhnien.vn/api/comments/get/by-obj?object_type=20&object_id={1519108}', 'status_code': 403, 'link_post': 'https://thanhnien.vn/bui-anh-duc-hat-giong-lanh-truyen-cam-hung-hoc-tap-noi-dat-doc-post1519108.html'}
Traceback (most recent call last):
  File "C:\Users\Admin\Documents\schedule_crawl_comment\venv\lib\site-packages\requests\models.py", line 971, in json
    return complexjson.loads(self.text, **kwargs)
  File "C:\Python\Python39\lib\json\__init__.py", line 346, in loads
    return _default_decoder.decode(s)
  File "C:\Python\Python39\lib\json\decoder.py", line 337, in decode
    obj, end = self.raw_decode(s, idx=_w(s, 0).end())
  File "C:\Python\Python39\lib\json\decoder.py", line 355, in raw_decode
    raise JSONDecodeError("Expecting value", s, err.value) from None
json.decoder.JSONDecodeError: Expecting value: line 1 column 1 (char 0)

During handling of the above exception, another exception occurred:

Traceback (most recent call last):
  File "C:\Users\Admin\Documents\schedule_crawl_comment\crawl_cmt.py", line 98, in crawl_in_post
    data = detect_responseType(config_site['comment_in_post']['responseType'], res)
  File "C:\Users\Admin\Documents\schedule_crawl_comment\crawl_cmt.py", line 177, in detect_responseType
    return res.json()
  File "C:\Users\Admin\Documents\schedule_crawl_comment\venv\lib\site-packages\requests\models.py", line 975, in json
    raise RequestsJSONDecodeError(e.msg, e.doc, e.pos)
requests.exceptions.JSONDecodeError: Expecting value: line 1 column 1 (char 0)
2022-11-10 16:18:50,694 - ERROR - {'message: exception when get comment in api': 'https://thanhnien.vn/api/comments/get/by-obj?object_type=20&object_id={1519108}', 'status_code': 403, 'link_post': 'https://thanhnien.vn/bui-anh-duc-hat-giong-lanh-truyen-cam-hung-hoc-tap-noi-dat-doc-post1519108.html'}
Traceback (most recent call last):
  File "C:\Users\Admin\Documents\schedule_crawl_comment\crawl_cmt.py", line 106, in crawl_in_post
    comment = check_regex(config_site['comment_in_post']['detect']['re'], [str(data)])[0]
UnboundLocalError: local variable 'data' referenced before assignment
2022-11-10 16:18:50,753 - ERROR - {'message: exception when call api': 'https://thanhnien.vn/api/comments/get/by-obj?object_type=20&object_id={1519478}', 'status_code': 403, 'link_post': 'https://thanhnien.vn/ban-sao-nhi-nguyen-phi-hung-ba-mat-vi-covid-19-di-hat-dam-cuoi-dam-ma-post1519478.html'}
Traceback (most recent call last):
  File "C:\Users\Admin\Documents\schedule_crawl_comment\venv\lib\site-packages\requests\models.py", line 971, in json
    return complexjson.loads(self.text, **kwargs)
  File "C:\Python\Python39\lib\json\__init__.py", line 346, in loads
    return _default_decoder.decode(s)
  File "C:\Python\Python39\lib\json\decoder.py", line 337, in decode
    obj, end = self.raw_decode(s, idx=_w(s, 0).end())
  File "C:\Python\Python39\lib\json\decoder.py", line 355, in raw_decode
    raise JSONDecodeError("Expecting value", s, err.value) from None
json.decoder.JSONDecodeError: Expecting value: line 1 column 1 (char 0)

During handling of the above exception, another exception occurred:

Traceback (most recent call last):
  File "C:\Users\Admin\Documents\schedule_crawl_comment\crawl_cmt.py", line 98, in crawl_in_post
    data = detect_responseType(config_site['comment_in_post']['responseType'], res)
  File "C:\Users\Admin\Documents\schedule_crawl_comment\crawl_cmt.py", line 177, in detect_responseType
    return res.json()
  File "C:\Users\Admin\Documents\schedule_crawl_comment\venv\lib\site-packages\requests\models.py", line 975, in json
    raise RequestsJSONDecodeError(e.msg, e.doc, e.pos)
requests.exceptions.JSONDecodeError: Expecting value: line 1 column 1 (char 0)
2022-11-10 16:18:50,753 - ERROR - {'message: exception when get comment in api': 'https://thanhnien.vn/api/comments/get/by-obj?object_type=20&object_id={1519478}', 'status_code': 403, 'link_post': 'https://thanhnien.vn/ban-sao-nhi-nguyen-phi-hung-ba-mat-vi-covid-19-di-hat-dam-cuoi-dam-ma-post1519478.html'}
Traceback (most recent call last):
  File "C:\Users\Admin\Documents\schedule_crawl_comment\crawl_cmt.py", line 106, in crawl_in_post
    comment = check_regex(config_site['comment_in_post']['detect']['re'], [str(data)])[0]
UnboundLocalError: local variable 'data' referenced before assignment
2022-11-10 16:18:50,804 - ERROR - {'message: exception when call api': 'https://thanhnien.vn/api/comments/get/by-obj?object_type=20&object_id={1519477}', 'status_code': 403, 'link_post': 'https://thanhnien.vn/hanh-trinh-cong-ly-tap-15-ai-se-cuu-thua-cho-phuong-thang-kien-phut-chot-post1519477.html'}
Traceback (most recent call last):
  File "C:\Users\Admin\Documents\schedule_crawl_comment\venv\lib\site-packages\requests\models.py", line 971, in json
    return complexjson.loads(self.text, **kwargs)
  File "C:\Python\Python39\lib\json\__init__.py", line 346, in loads
    return _default_decoder.decode(s)
  File "C:\Python\Python39\lib\json\decoder.py", line 337, in decode
    obj, end = self.raw_decode(s, idx=_w(s, 0).end())
  File "C:\Python\Python39\lib\json\decoder.py", line 355, in raw_decode
    raise JSONDecodeError("Expecting value", s, err.value) from None
json.decoder.JSONDecodeError: Expecting value: line 1 column 1 (char 0)

During handling of the above exception, another exception occurred:

Traceback (most recent call last):
  File "C:\Users\Admin\Documents\schedule_crawl_comment\crawl_cmt.py", line 98, in crawl_in_post
    data = detect_responseType(config_site['comment_in_post']['responseType'], res)
  File "C:\Users\Admin\Documents\schedule_crawl_comment\crawl_cmt.py", line 177, in detect_responseType
    return res.json()
  File "C:\Users\Admin\Documents\schedule_crawl_comment\venv\lib\site-packages\requests\models.py", line 975, in json
    raise RequestsJSONDecodeError(e.msg, e.doc, e.pos)
requests.exceptions.JSONDecodeError: Expecting value: line 1 column 1 (char 0)
2022-11-10 16:18:50,814 - ERROR - {'message: exception when get comment in api': 'https://thanhnien.vn/api/comments/get/by-obj?object_type=20&object_id={1519477}', 'status_code': 403, 'link_post': 'https://thanhnien.vn/hanh-trinh-cong-ly-tap-15-ai-se-cuu-thua-cho-phuong-thang-kien-phut-chot-post1519477.html'}
Traceback (most recent call last):
  File "C:\Users\Admin\Documents\schedule_crawl_comment\crawl_cmt.py", line 106, in crawl_in_post
    comment = check_regex(config_site['comment_in_post']['detect']['re'], [str(data)])[0]
UnboundLocalError: local variable 'data' referenced before assignment
2022-11-10 16:18:50,814 - ERROR - {'message: exception when call api': 'https://thanhnien.vn/api/comments/get/by-obj?object_type=20&object_id={1519462}', 'status_code': 403, 'link_post': 'https://thanhnien.vn/tro-cung-cua-hlv-mourinho-tu-choi-du-world-cup-vi-ly-do-bat-ngo-post1519462.html'}
Traceback (most recent call last):
  File "C:\Users\Admin\Documents\schedule_crawl_comment\venv\lib\site-packages\requests\models.py", line 971, in json
    return complexjson.loads(self.text, **kwargs)
  File "C:\Python\Python39\lib\json\__init__.py", line 346, in loads
    return _default_decoder.decode(s)
  File "C:\Python\Python39\lib\json\decoder.py", line 337, in decode
    obj, end = self.raw_decode(s, idx=_w(s, 0).end())
  File "C:\Python\Python39\lib\json\decoder.py", line 355, in raw_decode
    raise JSONDecodeError("Expecting value", s, err.value) from None
json.decoder.JSONDecodeError: Expecting value: line 1 column 1 (char 0)

During handling of the above exception, another exception occurred:

Traceback (most recent call last):
  File "C:\Users\Admin\Documents\schedule_crawl_comment\crawl_cmt.py", line 98, in crawl_in_post
    data = detect_responseType(config_site['comment_in_post']['responseType'], res)
  File "C:\Users\Admin\Documents\schedule_crawl_comment\crawl_cmt.py", line 177, in detect_responseType
    return res.json()
  File "C:\Users\Admin\Documents\schedule_crawl_comment\venv\lib\site-packages\requests\models.py", line 975, in json
    raise RequestsJSONDecodeError(e.msg, e.doc, e.pos)
requests.exceptions.JSONDecodeError: Expecting value: line 1 column 1 (char 0)
2022-11-10 16:18:50,814 - ERROR - {'message: exception when get comment in api': 'https://thanhnien.vn/api/comments/get/by-obj?object_type=20&object_id={1519462}', 'status_code': 403, 'link_post': 'https://thanhnien.vn/tro-cung-cua-hlv-mourinho-tu-choi-du-world-cup-vi-ly-do-bat-ngo-post1519462.html'}
Traceback (most recent call last):
  File "C:\Users\Admin\Documents\schedule_crawl_comment\crawl_cmt.py", line 106, in crawl_in_post
    comment = check_regex(config_site['comment_in_post']['detect']['re'], [str(data)])[0]
UnboundLocalError: local variable 'data' referenced before assignment
2022-11-10 16:18:50,875 - ERROR - {'message: exception when call api': 'https://thanhnien.vn/api/comments/get/by-obj?object_type=20&object_id={1519440}', 'status_code': 403, 'link_post': 'https://thanhnien.vn/neymar-ganh-trong-trach-nang-ne-tai-world-cup-2022-post1519440.html'}
Traceback (most recent call last):
  File "C:\Users\Admin\Documents\schedule_crawl_comment\venv\lib\site-packages\requests\models.py", line 971, in json
    return complexjson.loads(self.text, **kwargs)
  File "C:\Python\Python39\lib\json\__init__.py", line 346, in loads
    return _default_decoder.decode(s)
  File "C:\Python\Python39\lib\json\decoder.py", line 337, in decode
    obj, end = self.raw_decode(s, idx=_w(s, 0).end())
  File "C:\Python\Python39\lib\json\decoder.py", line 355, in raw_decode
    raise JSONDecodeError("Expecting value", s, err.value) from None
json.decoder.JSONDecodeError: Expecting value: line 1 column 1 (char 0)

During handling of the above exception, another exception occurred:

Traceback (most recent call last):
  File "C:\Users\Admin\Documents\schedule_crawl_comment\crawl_cmt.py", line 98, in crawl_in_post
    data = detect_responseType(config_site['comment_in_post']['responseType'], res)
  File "C:\Users\Admin\Documents\schedule_crawl_comment\crawl_cmt.py", line 177, in detect_responseType
    return res.json()
  File "C:\Users\Admin\Documents\schedule_crawl_comment\venv\lib\site-packages\requests\models.py", line 975, in json
    raise RequestsJSONDecodeError(e.msg, e.doc, e.pos)
requests.exceptions.JSONDecodeError: Expecting value: line 1 column 1 (char 0)
2022-11-10 16:18:50,875 - ERROR - {'message: exception when get comment in api': 'https://thanhnien.vn/api/comments/get/by-obj?object_type=20&object_id={1519440}', 'status_code': 403, 'link_post': 'https://thanhnien.vn/neymar-ganh-trong-trach-nang-ne-tai-world-cup-2022-post1519440.html'}
Traceback (most recent call last):
  File "C:\Users\Admin\Documents\schedule_crawl_comment\crawl_cmt.py", line 106, in crawl_in_post
    comment = check_regex(config_site['comment_in_post']['detect']['re'], [str(data)])[0]
UnboundLocalError: local variable 'data' referenced before assignment
2022-11-10 16:18:50,945 - ERROR - {'message: exception when call api': 'https://thanhnien.vn/api/comments/get/by-obj?object_type=20&object_id={1519471}', 'status_code': 403, 'link_post': 'https://thanhnien.vn/chu-tich-fifa-chuc-mung-tan-chu-tich-vff-va-bong-da-viet-nam-post1519471.html'}
Traceback (most recent call last):
  File "C:\Users\Admin\Documents\schedule_crawl_comment\venv\lib\site-packages\requests\models.py", line 971, in json
    return complexjson.loads(self.text, **kwargs)
  File "C:\Python\Python39\lib\json\__init__.py", line 346, in loads
    return _default_decoder.decode(s)
  File "C:\Python\Python39\lib\json\decoder.py", line 337, in decode
    obj, end = self.raw_decode(s, idx=_w(s, 0).end())
  File "C:\Python\Python39\lib\json\decoder.py", line 355, in raw_decode
    raise JSONDecodeError("Expecting value", s, err.value) from None
json.decoder.JSONDecodeError: Expecting value: line 1 column 1 (char 0)

During handling of the above exception, another exception occurred:

Traceback (most recent call last):
  File "C:\Users\Admin\Documents\schedule_crawl_comment\crawl_cmt.py", line 98, in crawl_in_post
    data = detect_responseType(config_site['comment_in_post']['responseType'], res)
  File "C:\Users\Admin\Documents\schedule_crawl_comment\crawl_cmt.py", line 177, in detect_responseType
    return res.json()
  File "C:\Users\Admin\Documents\schedule_crawl_comment\venv\lib\site-packages\requests\models.py", line 975, in json
    raise RequestsJSONDecodeError(e.msg, e.doc, e.pos)
requests.exceptions.JSONDecodeError: Expecting value: line 1 column 1 (char 0)
2022-11-10 16:18:50,945 - ERROR - {'message: exception when get comment in api': 'https://thanhnien.vn/api/comments/get/by-obj?object_type=20&object_id={1519471}', 'status_code': 403, 'link_post': 'https://thanhnien.vn/chu-tich-fifa-chuc-mung-tan-chu-tich-vff-va-bong-da-viet-nam-post1519471.html'}
Traceback (most recent call last):
  File "C:\Users\Admin\Documents\schedule_crawl_comment\crawl_cmt.py", line 106, in crawl_in_post
    comment = check_regex(config_site['comment_in_post']['detect']['re'], [str(data)])[0]
UnboundLocalError: local variable 'data' referenced before assignment
2022-11-10 16:18:50,956 - ERROR - {'message: exception when call api': 'https://thanhnien.vn/api/comments/get/by-obj?object_type=20&object_id={1519517}', 'status_code': 403, 'link_post': 'https://thanhnien.vn/giai-billiards-3-bang-the-gioi-cuu-a-quan-nguyen-duc-anh-chien-xuat-tran-post1519517.html'}
Traceback (most recent call last):
  File "C:\Users\Admin\Documents\schedule_crawl_comment\venv\lib\site-packages\requests\models.py", line 971, in json
    return complexjson.loads(self.text, **kwargs)
  File "C:\Python\Python39\lib\json\__init__.py", line 346, in loads
    return _default_decoder.decode(s)
  File "C:\Python\Python39\lib\json\decoder.py", line 337, in decode
    obj, end = self.raw_decode(s, idx=_w(s, 0).end())
  File "C:\Python\Python39\lib\json\decoder.py", line 355, in raw_decode
    raise JSONDecodeError("Expecting value", s, err.value) from None
json.decoder.JSONDecodeError: Expecting value: line 1 column 1 (char 0)

During handling of the above exception, another exception occurred:

Traceback (most recent call last):
  File "C:\Users\Admin\Documents\schedule_crawl_comment\crawl_cmt.py", line 98, in crawl_in_post
    data = detect_responseType(config_site['comment_in_post']['responseType'], res)
  File "C:\Users\Admin\Documents\schedule_crawl_comment\crawl_cmt.py", line 177, in detect_responseType
    return res.json()
  File "C:\Users\Admin\Documents\schedule_crawl_comment\venv\lib\site-packages\requests\models.py", line 975, in json
    raise RequestsJSONDecodeError(e.msg, e.doc, e.pos)
requests.exceptions.JSONDecodeError: Expecting value: line 1 column 1 (char 0)
2022-11-10 16:18:50,956 - ERROR - {'message: exception when get comment in api': 'https://thanhnien.vn/api/comments/get/by-obj?object_type=20&object_id={1519517}', 'status_code': 403, 'link_post': 'https://thanhnien.vn/giai-billiards-3-bang-the-gioi-cuu-a-quan-nguyen-duc-anh-chien-xuat-tran-post1519517.html'}
Traceback (most recent call last):
  File "C:\Users\Admin\Documents\schedule_crawl_comment\crawl_cmt.py", line 106, in crawl_in_post
    comment = check_regex(config_site['comment_in_post']['detect']['re'], [str(data)])[0]
UnboundLocalError: local variable 'data' referenced before assignment
2022-11-10 16:18:51,012 - ERROR - {'message: exception when call api': 'https://thanhnien.vn/api/comments/get/by-obj?object_type=20&object_id={1519452}', 'status_code': 403, 'link_post': 'https://thanhnien.vn/chieu-troi-tren-hoi-pho-post1519452.html'}
Traceback (most recent call last):
  File "C:\Users\Admin\Documents\schedule_crawl_comment\venv\lib\site-packages\requests\models.py", line 971, in json
    return complexjson.loads(self.text, **kwargs)
  File "C:\Python\Python39\lib\json\__init__.py", line 346, in loads
    return _default_decoder.decode(s)
  File "C:\Python\Python39\lib\json\decoder.py", line 337, in decode
    obj, end = self.raw_decode(s, idx=_w(s, 0).end())
  File "C:\Python\Python39\lib\json\decoder.py", line 355, in raw_decode
    raise JSONDecodeError("Expecting value", s, err.value) from None
json.decoder.JSONDecodeError: Expecting value: line 1 column 1 (char 0)

During handling of the above exception, another exception occurred:

Traceback (most recent call last):
  File "C:\Users\Admin\Documents\schedule_crawl_comment\crawl_cmt.py", line 98, in crawl_in_post
    data = detect_responseType(config_site['comment_in_post']['responseType'], res)
  File "C:\Users\Admin\Documents\schedule_crawl_comment\crawl_cmt.py", line 177, in detect_responseType
    return res.json()
  File "C:\Users\Admin\Documents\schedule_crawl_comment\venv\lib\site-packages\requests\models.py", line 975, in json
    raise RequestsJSONDecodeError(e.msg, e.doc, e.pos)
requests.exceptions.JSONDecodeError: Expecting value: line 1 column 1 (char 0)
2022-11-10 16:18:51,012 - ERROR - {'message: exception when get comment in api': 'https://thanhnien.vn/api/comments/get/by-obj?object_type=20&object_id={1519452}', 'status_code': 403, 'link_post': 'https://thanhnien.vn/chieu-troi-tren-hoi-pho-post1519452.html'}
Traceback (most recent call last):
  File "C:\Users\Admin\Documents\schedule_crawl_comment\crawl_cmt.py", line 106, in crawl_in_post
    comment = check_regex(config_site['comment_in_post']['detect']['re'], [str(data)])[0]
UnboundLocalError: local variable 'data' referenced before assignment
2022-11-10 16:18:51,052 - ERROR - {'message: exception when call api': 'https://thanhnien.vn/api/comments/get/by-obj?object_type=20&object_id={1517980}', 'status_code': 403, 'link_post': 'https://thanhnien.vn/tham-cong-binh-xuong-noi-nguoi-ukraine-hoi-sinh-xe-tang-nga-de-tro-lai-chien-dau-post1517980.html'}
Traceback (most recent call last):
  File "C:\Users\Admin\Documents\schedule_crawl_comment\venv\lib\site-packages\requests\models.py", line 971, in json
    return complexjson.loads(self.text, **kwargs)
  File "C:\Python\Python39\lib\json\__init__.py", line 346, in loads
    return _default_decoder.decode(s)
  File "C:\Python\Python39\lib\json\decoder.py", line 337, in decode
    obj, end = self.raw_decode(s, idx=_w(s, 0).end())
  File "C:\Python\Python39\lib\json\decoder.py", line 355, in raw_decode
    raise JSONDecodeError("Expecting value", s, err.value) from None
json.decoder.JSONDecodeError: Expecting value: line 1 column 1 (char 0)

During handling of the above exception, another exception occurred:

Traceback (most recent call last):
  File "C:\Users\Admin\Documents\schedule_crawl_comment\crawl_cmt.py", line 98, in crawl_in_post
    data = detect_responseType(config_site['comment_in_post']['responseType'], res)
  File "C:\Users\Admin\Documents\schedule_crawl_comment\crawl_cmt.py", line 177, in detect_responseType
    return res.json()
  File "C:\Users\Admin\Documents\schedule_crawl_comment\venv\lib\site-packages\requests\models.py", line 975, in json
    raise RequestsJSONDecodeError(e.msg, e.doc, e.pos)
requests.exceptions.JSONDecodeError: Expecting value: line 1 column 1 (char 0)
2022-11-10 16:18:51,062 - ERROR - {'message: exception when get comment in api': 'https://thanhnien.vn/api/comments/get/by-obj?object_type=20&object_id={1517980}', 'status_code': 403, 'link_post': 'https://thanhnien.vn/tham-cong-binh-xuong-noi-nguoi-ukraine-hoi-sinh-xe-tang-nga-de-tro-lai-chien-dau-post1517980.html'}
Traceback (most recent call last):
  File "C:\Users\Admin\Documents\schedule_crawl_comment\crawl_cmt.py", line 106, in crawl_in_post
    comment = check_regex(config_site['comment_in_post']['detect']['re'], [str(data)])[0]
UnboundLocalError: local variable 'data' referenced before assignment
2022-11-10 16:18:51,062 - ERROR - {'message: exception when call api': 'https://thanhnien.vn/api/comments/get/by-obj?object_type=20&object_id={1519518}', 'status_code': 403, 'link_post': 'https://thanhnien.vn/ten-lua-boi-sieu-thanh-moi-ra-mat-chien-dau-co-tang-hinh-j-20-dong-dien-o-trien-lam-chu-hai-post1519518.html'}
Traceback (most recent call last):
  File "C:\Users\Admin\Documents\schedule_crawl_comment\venv\lib\site-packages\requests\models.py", line 971, in json
    return complexjson.loads(self.text, **kwargs)
  File "C:\Python\Python39\lib\json\__init__.py", line 346, in loads
    return _default_decoder.decode(s)
  File "C:\Python\Python39\lib\json\decoder.py", line 337, in decode
    obj, end = self.raw_decode(s, idx=_w(s, 0).end())
  File "C:\Python\Python39\lib\json\decoder.py", line 355, in raw_decode
    raise JSONDecodeError("Expecting value", s, err.value) from None
json.decoder.JSONDecodeError: Expecting value: line 1 column 1 (char 0)

During handling of the above exception, another exception occurred:

Traceback (most recent call last):
  File "C:\Users\Admin\Documents\schedule_crawl_comment\crawl_cmt.py", line 98, in crawl_in_post
    data = detect_responseType(config_site['comment_in_post']['responseType'], res)
  File "C:\Users\Admin\Documents\schedule_crawl_comment\crawl_cmt.py", line 177, in detect_responseType
    return res.json()
  File "C:\Users\Admin\Documents\schedule_crawl_comment\venv\lib\site-packages\requests\models.py", line 975, in json
    raise RequestsJSONDecodeError(e.msg, e.doc, e.pos)
requests.exceptions.JSONDecodeError: Expecting value: line 1 column 1 (char 0)
2022-11-10 16:18:51,062 - ERROR - {'message: exception when get comment in api': 'https://thanhnien.vn/api/comments/get/by-obj?object_type=20&object_id={1519518}', 'status_code': 403, 'link_post': 'https://thanhnien.vn/ten-lua-boi-sieu-thanh-moi-ra-mat-chien-dau-co-tang-hinh-j-20-dong-dien-o-trien-lam-chu-hai-post1519518.html'}
Traceback (most recent call last):
  File "C:\Users\Admin\Documents\schedule_crawl_comment\crawl_cmt.py", line 106, in crawl_in_post
    comment = check_regex(config_site['comment_in_post']['detect']['re'], [str(data)])[0]
UnboundLocalError: local variable 'data' referenced before assignment
2022-11-10 16:18:51,123 - ERROR - {'message: exception when call api': 'https://thanhnien.vn/api/comments/get/by-obj?object_type=20&object_id={1519469}', 'status_code': 403, 'link_post': 'https://thanhnien.vn/my-co-nguoi-trung-so-doc-dac-hon-2-ti-usd-post1519469.html'}
Traceback (most recent call last):
  File "C:\Users\Admin\Documents\schedule_crawl_comment\venv\lib\site-packages\requests\models.py", line 971, in json
    return complexjson.loads(self.text, **kwargs)
  File "C:\Python\Python39\lib\json\__init__.py", line 346, in loads
    return _default_decoder.decode(s)
  File "C:\Python\Python39\lib\json\decoder.py", line 337, in decode
    obj, end = self.raw_decode(s, idx=_w(s, 0).end())
  File "C:\Python\Python39\lib\json\decoder.py", line 355, in raw_decode
    raise JSONDecodeError("Expecting value", s, err.value) from None
json.decoder.JSONDecodeError: Expecting value: line 1 column 1 (char 0)

During handling of the above exception, another exception occurred:

Traceback (most recent call last):
  File "C:\Users\Admin\Documents\schedule_crawl_comment\crawl_cmt.py", line 98, in crawl_in_post
    data = detect_responseType(config_site['comment_in_post']['responseType'], res)
  File "C:\Users\Admin\Documents\schedule_crawl_comment\crawl_cmt.py", line 177, in detect_responseType
    return res.json()
  File "C:\Users\Admin\Documents\schedule_crawl_comment\venv\lib\site-packages\requests\models.py", line 975, in json
    raise RequestsJSONDecodeError(e.msg, e.doc, e.pos)
requests.exceptions.JSONDecodeError: Expecting value: line 1 column 1 (char 0)
2022-11-10 16:18:51,123 - ERROR - {'message: exception when get comment in api': 'https://thanhnien.vn/api/comments/get/by-obj?object_type=20&object_id={1519469}', 'status_code': 403, 'link_post': 'https://thanhnien.vn/my-co-nguoi-trung-so-doc-dac-hon-2-ti-usd-post1519469.html'}
Traceback (most recent call last):
  File "C:\Users\Admin\Documents\schedule_crawl_comment\crawl_cmt.py", line 106, in crawl_in_post
    comment = check_regex(config_site['comment_in_post']['detect']['re'], [str(data)])[0]
UnboundLocalError: local variable 'data' referenced before assignment
2022-11-10 16:18:51,173 - ERROR - {'message: exception when call api': 'https://thanhnien.vn/api/comments/get/by-obj?object_type=20&object_id={1519507}', 'status_code': 403, 'link_post': 'https://thanhnien.vn/doc-dao-le-cung-trang-cua-dong-bao-khmer-dien-ra-ngay-ngay-nguyet-thuc-toan-phan-post1519507.html'}
Traceback (most recent call last):
  File "C:\Users\Admin\Documents\schedule_crawl_comment\venv\lib\site-packages\requests\models.py", line 971, in json
    return complexjson.loads(self.text, **kwargs)
  File "C:\Python\Python39\lib\json\__init__.py", line 346, in loads
    return _default_decoder.decode(s)
  File "C:\Python\Python39\lib\json\decoder.py", line 337, in decode
    obj, end = self.raw_decode(s, idx=_w(s, 0).end())
  File "C:\Python\Python39\lib\json\decoder.py", line 355, in raw_decode
    raise JSONDecodeError("Expecting value", s, err.value) from None
json.decoder.JSONDecodeError: Expecting value: line 1 column 1 (char 0)

During handling of the above exception, another exception occurred:

Traceback (most recent call last):
  File "C:\Users\Admin\Documents\schedule_crawl_comment\crawl_cmt.py", line 98, in crawl_in_post
    data = detect_responseType(config_site['comment_in_post']['responseType'], res)
  File "C:\Users\Admin\Documents\schedule_crawl_comment\crawl_cmt.py", line 177, in detect_responseType
    return res.json()
  File "C:\Users\Admin\Documents\schedule_crawl_comment\venv\lib\site-packages\requests\models.py", line 975, in json
    raise RequestsJSONDecodeError(e.msg, e.doc, e.pos)
requests.exceptions.JSONDecodeError: Expecting value: line 1 column 1 (char 0)
2022-11-10 16:18:51,173 - ERROR - {'message: exception when get comment in api': 'https://thanhnien.vn/api/comments/get/by-obj?object_type=20&object_id={1519507}', 'status_code': 403, 'link_post': 'https://thanhnien.vn/doc-dao-le-cung-trang-cua-dong-bao-khmer-dien-ra-ngay-ngay-nguyet-thuc-toan-phan-post1519507.html'}
Traceback (most recent call last):
  File "C:\Users\Admin\Documents\schedule_crawl_comment\crawl_cmt.py", line 106, in crawl_in_post
    comment = check_regex(config_site['comment_in_post']['detect']['re'], [str(data)])[0]
UnboundLocalError: local variable 'data' referenced before assignment
2022-11-10 16:18:51,205 - ERROR - {'message: exception when call api': 'https://thanhnien.vn/api/comments/get/by-obj?object_type=20&object_id={1519310}', 'status_code': 403, 'link_post': 'https://thanhnien.vn/yeu-cai-dep-thi-ban-khong-nen-bo-lo-nhung-mon-phu-kien-thoi-trang-duoi-day-post1519310.html'}
Traceback (most recent call last):
  File "C:\Users\Admin\Documents\schedule_crawl_comment\venv\lib\site-packages\requests\models.py", line 971, in json
    return complexjson.loads(self.text, **kwargs)
  File "C:\Python\Python39\lib\json\__init__.py", line 346, in loads
    return _default_decoder.decode(s)
  File "C:\Python\Python39\lib\json\decoder.py", line 337, in decode
    obj, end = self.raw_decode(s, idx=_w(s, 0).end())
  File "C:\Python\Python39\lib\json\decoder.py", line 355, in raw_decode
    raise JSONDecodeError("Expecting value", s, err.value) from None
json.decoder.JSONDecodeError: Expecting value: line 1 column 1 (char 0)

During handling of the above exception, another exception occurred:

Traceback (most recent call last):
  File "C:\Users\Admin\Documents\schedule_crawl_comment\crawl_cmt.py", line 98, in crawl_in_post
    data = detect_responseType(config_site['comment_in_post']['responseType'], res)
  File "C:\Users\Admin\Documents\schedule_crawl_comment\crawl_cmt.py", line 177, in detect_responseType
    return res.json()
  File "C:\Users\Admin\Documents\schedule_crawl_comment\venv\lib\site-packages\requests\models.py", line 975, in json
    raise RequestsJSONDecodeError(e.msg, e.doc, e.pos)
requests.exceptions.JSONDecodeError: Expecting value: line 1 column 1 (char 0)
2022-11-10 16:18:51,205 - ERROR - {'message: exception when get comment in api': 'https://thanhnien.vn/api/comments/get/by-obj?object_type=20&object_id={1519310}', 'status_code': 403, 'link_post': 'https://thanhnien.vn/yeu-cai-dep-thi-ban-khong-nen-bo-lo-nhung-mon-phu-kien-thoi-trang-duoi-day-post1519310.html'}
Traceback (most recent call last):
  File "C:\Users\Admin\Documents\schedule_crawl_comment\crawl_cmt.py", line 106, in crawl_in_post
    comment = check_regex(config_site['comment_in_post']['detect']['re'], [str(data)])[0]
UnboundLocalError: local variable 'data' referenced before assignment
2022-11-10 16:18:51,245 - ERROR - {'message: exception when call api': 'https://thanhnien.vn/api/comments/get/by-obj?object_type=20&object_id={1519165}', 'status_code': 403, 'link_post': 'https://thanhnien.vn/hoa-hau-doanh-nhan-dong-nam-a-2023-khong-gian-ket-noi-cua-nu-doanh-nhan-post1519165.html'}
Traceback (most recent call last):
  File "C:\Users\Admin\Documents\schedule_crawl_comment\venv\lib\site-packages\requests\models.py", line 971, in json
    return complexjson.loads(self.text, **kwargs)
  File "C:\Python\Python39\lib\json\__init__.py", line 346, in loads
    return _default_decoder.decode(s)
  File "C:\Python\Python39\lib\json\decoder.py", line 337, in decode
    obj, end = self.raw_decode(s, idx=_w(s, 0).end())
  File "C:\Python\Python39\lib\json\decoder.py", line 355, in raw_decode
    raise JSONDecodeError("Expecting value", s, err.value) from None
json.decoder.JSONDecodeError: Expecting value: line 1 column 1 (char 0)

During handling of the above exception, another exception occurred:

Traceback (most recent call last):
  File "C:\Users\Admin\Documents\schedule_crawl_comment\crawl_cmt.py", line 98, in crawl_in_post
    data = detect_responseType(config_site['comment_in_post']['responseType'], res)
  File "C:\Users\Admin\Documents\schedule_crawl_comment\crawl_cmt.py", line 177, in detect_responseType
    return res.json()
  File "C:\Users\Admin\Documents\schedule_crawl_comment\venv\lib\site-packages\requests\models.py", line 975, in json
    raise RequestsJSONDecodeError(e.msg, e.doc, e.pos)
requests.exceptions.JSONDecodeError: Expecting value: line 1 column 1 (char 0)
2022-11-10 16:18:51,245 - ERROR - {'message: exception when get comment in api': 'https://thanhnien.vn/api/comments/get/by-obj?object_type=20&object_id={1519165}', 'status_code': 403, 'link_post': 'https://thanhnien.vn/hoa-hau-doanh-nhan-dong-nam-a-2023-khong-gian-ket-noi-cua-nu-doanh-nhan-post1519165.html'}
Traceback (most recent call last):
  File "C:\Users\Admin\Documents\schedule_crawl_comment\crawl_cmt.py", line 106, in crawl_in_post
    comment = check_regex(config_site['comment_in_post']['detect']['re'], [str(data)])[0]
UnboundLocalError: local variable 'data' referenced before assignment
2022-11-10 16:18:51,311 - ERROR - {'message: exception when call api': 'https://thanhnien.vn/api/comments/get/by-obj?object_type=20&object_id={1519414}', 'status_code': 403, 'link_post': 'https://thanhnien.vn/cap-nhat-ket-qua-bau-cu-my-bam-duoi-kich-tinh-post1519414.html'}
Traceback (most recent call last):
  File "C:\Users\Admin\Documents\schedule_crawl_comment\venv\lib\site-packages\requests\models.py", line 971, in json
    return complexjson.loads(self.text, **kwargs)
  File "C:\Python\Python39\lib\json\__init__.py", line 346, in loads
    return _default_decoder.decode(s)
  File "C:\Python\Python39\lib\json\decoder.py", line 337, in decode
    obj, end = self.raw_decode(s, idx=_w(s, 0).end())
  File "C:\Python\Python39\lib\json\decoder.py", line 355, in raw_decode
    raise JSONDecodeError("Expecting value", s, err.value) from None
json.decoder.JSONDecodeError: Expecting value: line 1 column 1 (char 0)

During handling of the above exception, another exception occurred:

Traceback (most recent call last):
  File "C:\Users\Admin\Documents\schedule_crawl_comment\crawl_cmt.py", line 98, in crawl_in_post
    data = detect_responseType(config_site['comment_in_post']['responseType'], res)
  File "C:\Users\Admin\Documents\schedule_crawl_comment\crawl_cmt.py", line 177, in detect_responseType
    return res.json()
  File "C:\Users\Admin\Documents\schedule_crawl_comment\venv\lib\site-packages\requests\models.py", line 975, in json
    raise RequestsJSONDecodeError(e.msg, e.doc, e.pos)
requests.exceptions.JSONDecodeError: Expecting value: line 1 column 1 (char 0)
2022-11-10 16:18:51,311 - ERROR - {'message: exception when get comment in api': 'https://thanhnien.vn/api/comments/get/by-obj?object_type=20&object_id={1519414}', 'status_code': 403, 'link_post': 'https://thanhnien.vn/cap-nhat-ket-qua-bau-cu-my-bam-duoi-kich-tinh-post1519414.html'}
Traceback (most recent call last):
  File "C:\Users\Admin\Documents\schedule_crawl_comment\crawl_cmt.py", line 106, in crawl_in_post
    comment = check_regex(config_site['comment_in_post']['detect']['re'], [str(data)])[0]
UnboundLocalError: local variable 'data' referenced before assignment
2022-11-10 16:18:51,311 - ERROR - {'message: exception when call api': 'https://thanhnien.vn/api/comments/get/by-obj?object_type=20&object_id={1519556}', 'status_code': 403, 'link_post': 'https://thanhnien.vn/tong-thong-zelensky-ra-tuyen-bo-cung-ran-xe-tang-ukraine-tien-vao-thi-tran-mien-nam-post1519556.html'}
Traceback (most recent call last):
  File "C:\Users\Admin\Documents\schedule_crawl_comment\venv\lib\site-packages\requests\models.py", line 971, in json
    return complexjson.loads(self.text, **kwargs)
  File "C:\Python\Python39\lib\json\__init__.py", line 346, in loads
    return _default_decoder.decode(s)
  File "C:\Python\Python39\lib\json\decoder.py", line 337, in decode
    obj, end = self.raw_decode(s, idx=_w(s, 0).end())
  File "C:\Python\Python39\lib\json\decoder.py", line 355, in raw_decode
    raise JSONDecodeError("Expecting value", s, err.value) from None
json.decoder.JSONDecodeError: Expecting value: line 1 column 1 (char 0)

During handling of the above exception, another exception occurred:

Traceback (most recent call last):
  File "C:\Users\Admin\Documents\schedule_crawl_comment\crawl_cmt.py", line 98, in crawl_in_post
    data = detect_responseType(config_site['comment_in_post']['responseType'], res)
  File "C:\Users\Admin\Documents\schedule_crawl_comment\crawl_cmt.py", line 177, in detect_responseType
    return res.json()
  File "C:\Users\Admin\Documents\schedule_crawl_comment\venv\lib\site-packages\requests\models.py", line 975, in json
    raise RequestsJSONDecodeError(e.msg, e.doc, e.pos)
requests.exceptions.JSONDecodeError: Expecting value: line 1 column 1 (char 0)
2022-11-10 16:18:51,322 - ERROR - {'message: exception when get comment in api': 'https://thanhnien.vn/api/comments/get/by-obj?object_type=20&object_id={1519556}', 'status_code': 403, 'link_post': 'https://thanhnien.vn/tong-thong-zelensky-ra-tuyen-bo-cung-ran-xe-tang-ukraine-tien-vao-thi-tran-mien-nam-post1519556.html'}
Traceback (most recent call last):
  File "C:\Users\Admin\Documents\schedule_crawl_comment\crawl_cmt.py", line 106, in crawl_in_post
    comment = check_regex(config_site['comment_in_post']['detect']['re'], [str(data)])[0]
UnboundLocalError: local variable 'data' referenced before assignment
2022-11-10 16:18:51,347 - ERROR - {'message: exception when call api': 'https://thanhnien.vn/api/comments/get/by-obj?object_type=20&object_id={1519418}', 'status_code': 403, 'link_post': 'https://thanhnien.vn/tu-tai-xe-uber-thanh-nghi-si-gen-z-dau-tien-tai-quoc-hoi-my-post1519418.html'}
Traceback (most recent call last):
  File "C:\Users\Admin\Documents\schedule_crawl_comment\venv\lib\site-packages\requests\models.py", line 971, in json
    return complexjson.loads(self.text, **kwargs)
  File "C:\Python\Python39\lib\json\__init__.py", line 346, in loads
    return _default_decoder.decode(s)
  File "C:\Python\Python39\lib\json\decoder.py", line 337, in decode
    obj, end = self.raw_decode(s, idx=_w(s, 0).end())
  File "C:\Python\Python39\lib\json\decoder.py", line 355, in raw_decode
    raise JSONDecodeError("Expecting value", s, err.value) from None
json.decoder.JSONDecodeError: Expecting value: line 1 column 1 (char 0)

During handling of the above exception, another exception occurred:

Traceback (most recent call last):
  File "C:\Users\Admin\Documents\schedule_crawl_comment\crawl_cmt.py", line 98, in crawl_in_post
    data = detect_responseType(config_site['comment_in_post']['responseType'], res)
  File "C:\Users\Admin\Documents\schedule_crawl_comment\crawl_cmt.py", line 177, in detect_responseType
    return res.json()
  File "C:\Users\Admin\Documents\schedule_crawl_comment\venv\lib\site-packages\requests\models.py", line 975, in json
    raise RequestsJSONDecodeError(e.msg, e.doc, e.pos)
requests.exceptions.JSONDecodeError: Expecting value: line 1 column 1 (char 0)
2022-11-10 16:18:51,357 - ERROR - {'message: exception when get comment in api': 'https://thanhnien.vn/api/comments/get/by-obj?object_type=20&object_id={1519418}', 'status_code': 403, 'link_post': 'https://thanhnien.vn/tu-tai-xe-uber-thanh-nghi-si-gen-z-dau-tien-tai-quoc-hoi-my-post1519418.html'}
Traceback (most recent call last):
  File "C:\Users\Admin\Documents\schedule_crawl_comment\crawl_cmt.py", line 106, in crawl_in_post
    comment = check_regex(config_site['comment_in_post']['detect']['re'], [str(data)])[0]
UnboundLocalError: local variable 'data' referenced before assignment
2022-11-10 16:18:51,417 - ERROR - {'message: exception when call api': 'https://thanhnien.vn/api/comments/get/by-obj?object_type=20&object_id={1519566}', 'status_code': 403, 'link_post': 'https://thanhnien.vn/nha-dau-tu-quan-tam-den-tien-do-du-an-trong-boi-canh-thi-truong-bien-dong-post1519566.html'}
Traceback (most recent call last):
  File "C:\Users\Admin\Documents\schedule_crawl_comment\venv\lib\site-packages\requests\models.py", line 971, in json
    return complexjson.loads(self.text, **kwargs)
  File "C:\Python\Python39\lib\json\__init__.py", line 346, in loads
    return _default_decoder.decode(s)
  File "C:\Python\Python39\lib\json\decoder.py", line 337, in decode
    obj, end = self.raw_decode(s, idx=_w(s, 0).end())
  File "C:\Python\Python39\lib\json\decoder.py", line 355, in raw_decode
    raise JSONDecodeError("Expecting value", s, err.value) from None
json.decoder.JSONDecodeError: Expecting value: line 1 column 1 (char 0)

During handling of the above exception, another exception occurred:

Traceback (most recent call last):
  File "C:\Users\Admin\Documents\schedule_crawl_comment\crawl_cmt.py", line 98, in crawl_in_post
    data = detect_responseType(config_site['comment_in_post']['responseType'], res)
  File "C:\Users\Admin\Documents\schedule_crawl_comment\crawl_cmt.py", line 177, in detect_responseType
    return res.json()
  File "C:\Users\Admin\Documents\schedule_crawl_comment\venv\lib\site-packages\requests\models.py", line 975, in json
    raise RequestsJSONDecodeError(e.msg, e.doc, e.pos)
requests.exceptions.JSONDecodeError: Expecting value: line 1 column 1 (char 0)
2022-11-10 16:18:51,427 - ERROR - {'message: exception when call api': 'https://thanhnien.vn/api/comments/get/by-obj?object_type=20&object_id={1519563}', 'status_code': 403, 'link_post': 'https://thanhnien.vn/trieu-tien-vua-phong-ten-lua-dan-dao-giua-luc-my-kiem-phieu-bau-giua-ky-post1519563.html'}
Traceback (most recent call last):
  File "C:\Users\Admin\Documents\schedule_crawl_comment\venv\lib\site-packages\requests\models.py", line 971, in json
    return complexjson.loads(self.text, **kwargs)
  File "C:\Python\Python39\lib\json\__init__.py", line 346, in loads
    return _default_decoder.decode(s)
  File "C:\Python\Python39\lib\json\decoder.py", line 337, in decode
    obj, end = self.raw_decode(s, idx=_w(s, 0).end())
  File "C:\Python\Python39\lib\json\decoder.py", line 355, in raw_decode
    raise JSONDecodeError("Expecting value", s, err.value) from None
json.decoder.JSONDecodeError: Expecting value: line 1 column 1 (char 0)

During handling of the above exception, another exception occurred:

Traceback (most recent call last):
  File "C:\Users\Admin\Documents\schedule_crawl_comment\crawl_cmt.py", line 98, in crawl_in_post
    data = detect_responseType(config_site['comment_in_post']['responseType'], res)
  File "C:\Users\Admin\Documents\schedule_crawl_comment\crawl_cmt.py", line 177, in detect_responseType
    return res.json()
  File "C:\Users\Admin\Documents\schedule_crawl_comment\venv\lib\site-packages\requests\models.py", line 975, in json
    raise RequestsJSONDecodeError(e.msg, e.doc, e.pos)
requests.exceptions.JSONDecodeError: Expecting value: line 1 column 1 (char 0)
2022-11-10 16:18:51,427 - ERROR - {'message: exception when get comment in api': 'https://thanhnien.vn/api/comments/get/by-obj?object_type=20&object_id={1519566}', 'status_code': 403, 'link_post': 'https://thanhnien.vn/nha-dau-tu-quan-tam-den-tien-do-du-an-trong-boi-canh-thi-truong-bien-dong-post1519566.html'}
Traceback (most recent call last):
  File "C:\Users\Admin\Documents\schedule_crawl_comment\crawl_cmt.py", line 106, in crawl_in_post
    comment = check_regex(config_site['comment_in_post']['detect']['re'], [str(data)])[0]
UnboundLocalError: local variable 'data' referenced before assignment
2022-11-10 16:18:51,427 - ERROR - {'message: exception when get comment in api': 'https://thanhnien.vn/api/comments/get/by-obj?object_type=20&object_id={1519563}', 'status_code': 403, 'link_post': 'https://thanhnien.vn/trieu-tien-vua-phong-ten-lua-dan-dao-giua-luc-my-kiem-phieu-bau-giua-ky-post1519563.html'}
Traceback (most recent call last):
  File "C:\Users\Admin\Documents\schedule_crawl_comment\crawl_cmt.py", line 106, in crawl_in_post
    comment = check_regex(config_site['comment_in_post']['detect']['re'], [str(data)])[0]
UnboundLocalError: local variable 'data' referenced before assignment
2022-11-10 16:18:51,503 - ERROR - {'message: exception when call api': 'https://thanhnien.vn/api/comments/get/by-obj?object_type=20&object_id={1519553}', 'status_code': 403, 'link_post': 'https://thanhnien.vn/thaco-agriculture-trao-tang-15-xe-kham-chua-benh-co-dong-cho-hoi-chu-thap-do-campuchia-post1519553.html'}
Traceback (most recent call last):
  File "C:\Users\Admin\Documents\schedule_crawl_comment\venv\lib\site-packages\requests\models.py", line 971, in json
    return complexjson.loads(self.text, **kwargs)
  File "C:\Python\Python39\lib\json\__init__.py", line 346, in loads
    return _default_decoder.decode(s)
  File "C:\Python\Python39\lib\json\decoder.py", line 337, in decode
    obj, end = self.raw_decode(s, idx=_w(s, 0).end())
  File "C:\Python\Python39\lib\json\decoder.py", line 355, in raw_decode
    raise JSONDecodeError("Expecting value", s, err.value) from None
json.decoder.JSONDecodeError: Expecting value: line 1 column 1 (char 0)

During handling of the above exception, another exception occurred:

Traceback (most recent call last):
  File "C:\Users\Admin\Documents\schedule_crawl_comment\crawl_cmt.py", line 98, in crawl_in_post
    data = detect_responseType(config_site['comment_in_post']['responseType'], res)
  File "C:\Users\Admin\Documents\schedule_crawl_comment\crawl_cmt.py", line 177, in detect_responseType
    return res.json()
  File "C:\Users\Admin\Documents\schedule_crawl_comment\venv\lib\site-packages\requests\models.py", line 975, in json
    raise RequestsJSONDecodeError(e.msg, e.doc, e.pos)
requests.exceptions.JSONDecodeError: Expecting value: line 1 column 1 (char 0)
2022-11-10 16:18:51,503 - ERROR - {'message: exception when get comment in api': 'https://thanhnien.vn/api/comments/get/by-obj?object_type=20&object_id={1519553}', 'status_code': 403, 'link_post': 'https://thanhnien.vn/thaco-agriculture-trao-tang-15-xe-kham-chua-benh-co-dong-cho-hoi-chu-thap-do-campuchia-post1519553.html'}
Traceback (most recent call last):
  File "C:\Users\Admin\Documents\schedule_crawl_comment\crawl_cmt.py", line 106, in crawl_in_post
    comment = check_regex(config_site['comment_in_post']['detect']['re'], [str(data)])[0]
UnboundLocalError: local variable 'data' referenced before assignment
2022-11-10 16:18:51,564 - ERROR - {'message: exception when call api': 'https://thanhnien.vn/api/comments/get/by-obj?object_type=20&object_id={1519558}', 'status_code': 403, 'link_post': 'https://thanhnien.vn/vinamilk-nang-von-dau-tu-cho-du-an-tai-campuchia-len-42-trieu-usd-post1519558.html'}
Traceback (most recent call last):
  File "C:\Users\Admin\Documents\schedule_crawl_comment\venv\lib\site-packages\requests\models.py", line 971, in json
    return complexjson.loads(self.text, **kwargs)
  File "C:\Python\Python39\lib\json\__init__.py", line 346, in loads
    return _default_decoder.decode(s)
  File "C:\Python\Python39\lib\json\decoder.py", line 337, in decode
    obj, end = self.raw_decode(s, idx=_w(s, 0).end())
  File "C:\Python\Python39\lib\json\decoder.py", line 355, in raw_decode
    raise JSONDecodeError("Expecting value", s, err.value) from None
json.decoder.JSONDecodeError: Expecting value: line 1 column 1 (char 0)

During handling of the above exception, another exception occurred:

Traceback (most recent call last):
  File "C:\Users\Admin\Documents\schedule_crawl_comment\crawl_cmt.py", line 98, in crawl_in_post
    data = detect_responseType(config_site['comment_in_post']['responseType'], res)
  File "C:\Users\Admin\Documents\schedule_crawl_comment\crawl_cmt.py", line 177, in detect_responseType
    return res.json()
  File "C:\Users\Admin\Documents\schedule_crawl_comment\venv\lib\site-packages\requests\models.py", line 975, in json
    raise RequestsJSONDecodeError(e.msg, e.doc, e.pos)
requests.exceptions.JSONDecodeError: Expecting value: line 1 column 1 (char 0)
2022-11-10 16:18:51,564 - ERROR - {'message: exception when get comment in api': 'https://thanhnien.vn/api/comments/get/by-obj?object_type=20&object_id={1519558}', 'status_code': 403, 'link_post': 'https://thanhnien.vn/vinamilk-nang-von-dau-tu-cho-du-an-tai-campuchia-len-42-trieu-usd-post1519558.html'}
Traceback (most recent call last):
  File "C:\Users\Admin\Documents\schedule_crawl_comment\crawl_cmt.py", line 106, in crawl_in_post
    comment = check_regex(config_site['comment_in_post']['detect']['re'], [str(data)])[0]
UnboundLocalError: local variable 'data' referenced before assignment
2022-11-10 16:18:51,665 - ERROR - {'message: exception when call api': 'https://thanhnien.vn/api/comments/get/by-obj?object_type=20&object_id={1519495}', 'status_code': 403, 'link_post': 'https://thanhnien.vn/giai-phap-san-epoxy-cho-moi-doanh-nghiep-trong-linh-vuc-cong-nghiep-post1519495.html'}
Traceback (most recent call last):
  File "C:\Users\Admin\Documents\schedule_crawl_comment\venv\lib\site-packages\requests\models.py", line 971, in json
    return complexjson.loads(self.text, **kwargs)
  File "C:\Python\Python39\lib\json\__init__.py", line 346, in loads
    return _default_decoder.decode(s)
  File "C:\Python\Python39\lib\json\decoder.py", line 337, in decode
    obj, end = self.raw_decode(s, idx=_w(s, 0).end())
  File "C:\Python\Python39\lib\json\decoder.py", line 355, in raw_decode
    raise JSONDecodeError("Expecting value", s, err.value) from None
json.decoder.JSONDecodeError: Expecting value: line 1 column 1 (char 0)

During handling of the above exception, another exception occurred:

Traceback (most recent call last):
  File "C:\Users\Admin\Documents\schedule_crawl_comment\crawl_cmt.py", line 98, in crawl_in_post
    data = detect_responseType(config_site['comment_in_post']['responseType'], res)
  File "C:\Users\Admin\Documents\schedule_crawl_comment\crawl_cmt.py", line 177, in detect_responseType
    return res.json()
  File "C:\Users\Admin\Documents\schedule_crawl_comment\venv\lib\site-packages\requests\models.py", line 975, in json
    raise RequestsJSONDecodeError(e.msg, e.doc, e.pos)
requests.exceptions.JSONDecodeError: Expecting value: line 1 column 1 (char 0)
2022-11-10 16:18:51,665 - ERROR - {'message: exception when get comment in api': 'https://thanhnien.vn/api/comments/get/by-obj?object_type=20&object_id={1519495}', 'status_code': 403, 'link_post': 'https://thanhnien.vn/giai-phap-san-epoxy-cho-moi-doanh-nghiep-trong-linh-vuc-cong-nghiep-post1519495.html'}
Traceback (most recent call last):
  File "C:\Users\Admin\Documents\schedule_crawl_comment\crawl_cmt.py", line 106, in crawl_in_post
    comment = check_regex(config_site['comment_in_post']['detect']['re'], [str(data)])[0]
UnboundLocalError: local variable 'data' referenced before assignment
2022-11-10 16:18:51,701 - ERROR - {'message: exception when call api': 'https://thanhnien.vn/api/comments/get/by-obj?object_type=20&object_id={1519482}', 'status_code': 403, 'link_post': 'https://thanhnien.vn/3-ti-dong-danh-tang-doanh-nghiep-sme-gui-tien-tai-vietinbank-post1519482.html'}
Traceback (most recent call last):
  File "C:\Users\Admin\Documents\schedule_crawl_comment\venv\lib\site-packages\requests\models.py", line 971, in json
    return complexjson.loads(self.text, **kwargs)
  File "C:\Python\Python39\lib\json\__init__.py", line 346, in loads
    return _default_decoder.decode(s)
  File "C:\Python\Python39\lib\json\decoder.py", line 337, in decode
    obj, end = self.raw_decode(s, idx=_w(s, 0).end())
  File "C:\Python\Python39\lib\json\decoder.py", line 355, in raw_decode
    raise JSONDecodeError("Expecting value", s, err.value) from None
json.decoder.JSONDecodeError: Expecting value: line 1 column 1 (char 0)

During handling of the above exception, another exception occurred:

Traceback (most recent call last):
  File "C:\Users\Admin\Documents\schedule_crawl_comment\crawl_cmt.py", line 98, in crawl_in_post
    data = detect_responseType(config_site['comment_in_post']['responseType'], res)
  File "C:\Users\Admin\Documents\schedule_crawl_comment\crawl_cmt.py", line 177, in detect_responseType
    return res.json()
  File "C:\Users\Admin\Documents\schedule_crawl_comment\venv\lib\site-packages\requests\models.py", line 975, in json
    raise RequestsJSONDecodeError(e.msg, e.doc, e.pos)
requests.exceptions.JSONDecodeError: Expecting value: line 1 column 1 (char 0)
2022-11-10 16:18:51,701 - ERROR - {'message: exception when get comment in api': 'https://thanhnien.vn/api/comments/get/by-obj?object_type=20&object_id={1519482}', 'status_code': 403, 'link_post': 'https://thanhnien.vn/3-ti-dong-danh-tang-doanh-nghiep-sme-gui-tien-tai-vietinbank-post1519482.html'}
Traceback (most recent call last):
  File "C:\Users\Admin\Documents\schedule_crawl_comment\crawl_cmt.py", line 106, in crawl_in_post
    comment = check_regex(config_site['comment_in_post']['detect']['re'], [str(data)])[0]
UnboundLocalError: local variable 'data' referenced before assignment
2022-11-10 16:18:51,741 - ERROR - {'message: exception when call api': 'https://thanhnien.vn/api/comments/get/by-obj?object_type=20&object_id={1519502}', 'status_code': 403, 'link_post': 'https://thanhnien.vn/ket-qua-xo-so-hom-nay-kqxs-xo-so-truc-tiep-thu-tu-ngay-9112022-post1519502.html'}
Traceback (most recent call last):
  File "C:\Users\Admin\Documents\schedule_crawl_comment\venv\lib\site-packages\requests\models.py", line 971, in json
    return complexjson.loads(self.text, **kwargs)
  File "C:\Python\Python39\lib\json\__init__.py", line 346, in loads
    return _default_decoder.decode(s)
  File "C:\Python\Python39\lib\json\decoder.py", line 337, in decode
    obj, end = self.raw_decode(s, idx=_w(s, 0).end())
  File "C:\Python\Python39\lib\json\decoder.py", line 355, in raw_decode
    raise JSONDecodeError("Expecting value", s, err.value) from None
json.decoder.JSONDecodeError: Expecting value: line 1 column 1 (char 0)

During handling of the above exception, another exception occurred:

Traceback (most recent call last):
  File "C:\Users\Admin\Documents\schedule_crawl_comment\crawl_cmt.py", line 98, in crawl_in_post
    data = detect_responseType(config_site['comment_in_post']['responseType'], res)
  File "C:\Users\Admin\Documents\schedule_crawl_comment\crawl_cmt.py", line 177, in detect_responseType
    return res.json()
  File "C:\Users\Admin\Documents\schedule_crawl_comment\venv\lib\site-packages\requests\models.py", line 975, in json
    raise RequestsJSONDecodeError(e.msg, e.doc, e.pos)
requests.exceptions.JSONDecodeError: Expecting value: line 1 column 1 (char 0)
2022-11-10 16:18:51,752 - ERROR - {'message: exception when get comment in api': 'https://thanhnien.vn/api/comments/get/by-obj?object_type=20&object_id={1519502}', 'status_code': 403, 'link_post': 'https://thanhnien.vn/ket-qua-xo-so-hom-nay-kqxs-xo-so-truc-tiep-thu-tu-ngay-9112022-post1519502.html'}
Traceback (most recent call last):
  File "C:\Users\Admin\Documents\schedule_crawl_comment\crawl_cmt.py", line 106, in crawl_in_post
    comment = check_regex(config_site['comment_in_post']['detect']['re'], [str(data)])[0]
UnboundLocalError: local variable 'data' referenced before assignment
2022-11-10 16:18:51,782 - ERROR - {'message: exception when call api': 'https://thanhnien.vn/api/comments/get/by-obj?object_type=20&object_id={1519596}', 'status_code': 403, 'link_post': 'https://thanhnien.vn/su-quan-tam-cua-nguoi-chong-co-the-lam-voi-diu-nhung-kho-khan-xa-cach-post1519596.html'}
Traceback (most recent call last):
  File "C:\Users\Admin\Documents\schedule_crawl_comment\venv\lib\site-packages\requests\models.py", line 971, in json
    return complexjson.loads(self.text, **kwargs)
  File "C:\Python\Python39\lib\json\__init__.py", line 346, in loads
    return _default_decoder.decode(s)
  File "C:\Python\Python39\lib\json\decoder.py", line 337, in decode
    obj, end = self.raw_decode(s, idx=_w(s, 0).end())
  File "C:\Python\Python39\lib\json\decoder.py", line 355, in raw_decode
    raise JSONDecodeError("Expecting value", s, err.value) from None
json.decoder.JSONDecodeError: Expecting value: line 1 column 1 (char 0)

During handling of the above exception, another exception occurred:

Traceback (most recent call last):
  File "C:\Users\Admin\Documents\schedule_crawl_comment\crawl_cmt.py", line 98, in crawl_in_post
    data = detect_responseType(config_site['comment_in_post']['responseType'], res)
  File "C:\Users\Admin\Documents\schedule_crawl_comment\crawl_cmt.py", line 177, in detect_responseType
    return res.json()
  File "C:\Users\Admin\Documents\schedule_crawl_comment\venv\lib\site-packages\requests\models.py", line 975, in json
    raise RequestsJSONDecodeError(e.msg, e.doc, e.pos)
requests.exceptions.JSONDecodeError: Expecting value: line 1 column 1 (char 0)
2022-11-10 16:18:51,792 - ERROR - {'message: exception when get comment in api': 'https://thanhnien.vn/api/comments/get/by-obj?object_type=20&object_id={1519596}', 'status_code': 403, 'link_post': 'https://thanhnien.vn/su-quan-tam-cua-nguoi-chong-co-the-lam-voi-diu-nhung-kho-khan-xa-cach-post1519596.html'}
Traceback (most recent call last):
  File "C:\Users\Admin\Documents\schedule_crawl_comment\crawl_cmt.py", line 106, in crawl_in_post
    comment = check_regex(config_site['comment_in_post']['detect']['re'], [str(data)])[0]
UnboundLocalError: local variable 'data' referenced before assignment
2022-11-10 16:18:51,822 - ERROR - {'message: exception when call api': 'https://thanhnien.vn/api/comments/get/by-obj?object_type=20&object_id={1516919}', 'status_code': 403, 'link_post': 'https://thanhnien.vn/truc-tiep-bong-da-clb-binh-duong-vs-clb-thanh-hoa-vleague-1-1700-09112022-post1516919.html'}
Traceback (most recent call last):
  File "C:\Users\Admin\Documents\schedule_crawl_comment\venv\lib\site-packages\requests\models.py", line 971, in json
    return complexjson.loads(self.text, **kwargs)
  File "C:\Python\Python39\lib\json\__init__.py", line 346, in loads
    return _default_decoder.decode(s)
  File "C:\Python\Python39\lib\json\decoder.py", line 337, in decode
    obj, end = self.raw_decode(s, idx=_w(s, 0).end())
  File "C:\Python\Python39\lib\json\decoder.py", line 355, in raw_decode
    raise JSONDecodeError("Expecting value", s, err.value) from None
json.decoder.JSONDecodeError: Expecting value: line 1 column 1 (char 0)

During handling of the above exception, another exception occurred:

Traceback (most recent call last):
  File "C:\Users\Admin\Documents\schedule_crawl_comment\crawl_cmt.py", line 98, in crawl_in_post
    data = detect_responseType(config_site['comment_in_post']['responseType'], res)
  File "C:\Users\Admin\Documents\schedule_crawl_comment\crawl_cmt.py", line 177, in detect_responseType
    return res.json()
  File "C:\Users\Admin\Documents\schedule_crawl_comment\venv\lib\site-packages\requests\models.py", line 975, in json
    raise RequestsJSONDecodeError(e.msg, e.doc, e.pos)
requests.exceptions.JSONDecodeError: Expecting value: line 1 column 1 (char 0)
2022-11-10 16:18:51,832 - ERROR - {'message: exception when get comment in api': 'https://thanhnien.vn/api/comments/get/by-obj?object_type=20&object_id={1516919}', 'status_code': 403, 'link_post': 'https://thanhnien.vn/truc-tiep-bong-da-clb-binh-duong-vs-clb-thanh-hoa-vleague-1-1700-09112022-post1516919.html'}
Traceback (most recent call last):
  File "C:\Users\Admin\Documents\schedule_crawl_comment\crawl_cmt.py", line 106, in crawl_in_post
    comment = check_regex(config_site['comment_in_post']['detect']['re'], [str(data)])[0]
UnboundLocalError: local variable 'data' referenced before assignment
2022-11-10 16:18:51,842 - ERROR - {'message: exception when call api': 'https://thanhnien.vn/api/comments/get/by-obj?object_type=20&object_id={1519565}', 'status_code': 403, 'link_post': 'https://thanhnien.vn/gia-ve-may-bay-ve-tet-tang-cao-nguoi-tre-chua-biet-phai-tinh-sao-post1519565.html'}
Traceback (most recent call last):
  File "C:\Users\Admin\Documents\schedule_crawl_comment\venv\lib\site-packages\requests\models.py", line 971, in json
    return complexjson.loads(self.text, **kwargs)
  File "C:\Python\Python39\lib\json\__init__.py", line 346, in loads
    return _default_decoder.decode(s)
  File "C:\Python\Python39\lib\json\decoder.py", line 337, in decode
    obj, end = self.raw_decode(s, idx=_w(s, 0).end())
  File "C:\Python\Python39\lib\json\decoder.py", line 355, in raw_decode
    raise JSONDecodeError("Expecting value", s, err.value) from None
json.decoder.JSONDecodeError: Expecting value: line 1 column 1 (char 0)

During handling of the above exception, another exception occurred:

Traceback (most recent call last):
  File "C:\Users\Admin\Documents\schedule_crawl_comment\crawl_cmt.py", line 98, in crawl_in_post
    data = detect_responseType(config_site['comment_in_post']['responseType'], res)
  File "C:\Users\Admin\Documents\schedule_crawl_comment\crawl_cmt.py", line 177, in detect_responseType
    return res.json()
  File "C:\Users\Admin\Documents\schedule_crawl_comment\venv\lib\site-packages\requests\models.py", line 975, in json
    raise RequestsJSONDecodeError(e.msg, e.doc, e.pos)
requests.exceptions.JSONDecodeError: Expecting value: line 1 column 1 (char 0)
2022-11-10 16:18:51,852 - ERROR - {'message: exception when get comment in api': 'https://thanhnien.vn/api/comments/get/by-obj?object_type=20&object_id={1519565}', 'status_code': 403, 'link_post': 'https://thanhnien.vn/gia-ve-may-bay-ve-tet-tang-cao-nguoi-tre-chua-biet-phai-tinh-sao-post1519565.html'}
Traceback (most recent call last):
  File "C:\Users\Admin\Documents\schedule_crawl_comment\crawl_cmt.py", line 106, in crawl_in_post
    comment = check_regex(config_site['comment_in_post']['detect']['re'], [str(data)])[0]
UnboundLocalError: local variable 'data' referenced before assignment
2022-11-10 16:18:51,882 - ERROR - {'message: exception when call api': 'https://thanhnien.vn/api/comments/get/by-obj?object_type=20&object_id={1517689}', 'status_code': 403, 'link_post': 'https://thanhnien.vn/mon-ngon-qbinh-thanh-tphcm-pha-lau-vit-co-ngay-ban-200kg-nho-gia-vi-la-post1517689.html'}
Traceback (most recent call last):
  File "C:\Users\Admin\Documents\schedule_crawl_comment\venv\lib\site-packages\requests\models.py", line 971, in json
    return complexjson.loads(self.text, **kwargs)
  File "C:\Python\Python39\lib\json\__init__.py", line 346, in loads
    return _default_decoder.decode(s)
  File "C:\Python\Python39\lib\json\decoder.py", line 337, in decode
    obj, end = self.raw_decode(s, idx=_w(s, 0).end())
  File "C:\Python\Python39\lib\json\decoder.py", line 355, in raw_decode
    raise JSONDecodeError("Expecting value", s, err.value) from None
json.decoder.JSONDecodeError: Expecting value: line 1 column 1 (char 0)

During handling of the above exception, another exception occurred:

Traceback (most recent call last):
  File "C:\Users\Admin\Documents\schedule_crawl_comment\crawl_cmt.py", line 98, in crawl_in_post
    data = detect_responseType(config_site['comment_in_post']['responseType'], res)
  File "C:\Users\Admin\Documents\schedule_crawl_comment\crawl_cmt.py", line 177, in detect_responseType
    return res.json()
  File "C:\Users\Admin\Documents\schedule_crawl_comment\venv\lib\site-packages\requests\models.py", line 975, in json
    raise RequestsJSONDecodeError(e.msg, e.doc, e.pos)
requests.exceptions.JSONDecodeError: Expecting value: line 1 column 1 (char 0)
2022-11-10 16:18:51,882 - ERROR - {'message: exception when get comment in api': 'https://thanhnien.vn/api/comments/get/by-obj?object_type=20&object_id={1517689}', 'status_code': 403, 'link_post': 'https://thanhnien.vn/mon-ngon-qbinh-thanh-tphcm-pha-lau-vit-co-ngay-ban-200kg-nho-gia-vi-la-post1517689.html'}
Traceback (most recent call last):
  File "C:\Users\Admin\Documents\schedule_crawl_comment\crawl_cmt.py", line 106, in crawl_in_post
    comment = check_regex(config_site['comment_in_post']['detect']['re'], [str(data)])[0]
UnboundLocalError: local variable 'data' referenced before assignment
2022-11-10 16:18:51,933 - ERROR - {'message: exception when call api': 'https://thanhnien.vn/api/comments/get/by-obj?object_type=20&object_id={1519496}', 'status_code': 403, 'link_post': 'https://thanhnien.vn/chibooks-xay-dung-300-tu-sach-thu-vien-cho-nhieu-truong-trong-ca-nuoc-post1519496.html'}
Traceback (most recent call last):
  File "C:\Users\Admin\Documents\schedule_crawl_comment\venv\lib\site-packages\requests\models.py", line 971, in json
    return complexjson.loads(self.text, **kwargs)
  File "C:\Python\Python39\lib\json\__init__.py", line 346, in loads
    return _default_decoder.decode(s)
  File "C:\Python\Python39\lib\json\decoder.py", line 337, in decode
    obj, end = self.raw_decode(s, idx=_w(s, 0).end())
  File "C:\Python\Python39\lib\json\decoder.py", line 355, in raw_decode
    raise JSONDecodeError("Expecting value", s, err.value) from None
json.decoder.JSONDecodeError: Expecting value: line 1 column 1 (char 0)

During handling of the above exception, another exception occurred:

Traceback (most recent call last):
  File "C:\Users\Admin\Documents\schedule_crawl_comment\crawl_cmt.py", line 98, in crawl_in_post
    data = detect_responseType(config_site['comment_in_post']['responseType'], res)
  File "C:\Users\Admin\Documents\schedule_crawl_comment\crawl_cmt.py", line 177, in detect_responseType
    return res.json()
  File "C:\Users\Admin\Documents\schedule_crawl_comment\venv\lib\site-packages\requests\models.py", line 975, in json
    raise RequestsJSONDecodeError(e.msg, e.doc, e.pos)
requests.exceptions.JSONDecodeError: Expecting value: line 1 column 1 (char 0)
2022-11-10 16:18:51,933 - ERROR - {'message: exception when get comment in api': 'https://thanhnien.vn/api/comments/get/by-obj?object_type=20&object_id={1519496}', 'status_code': 403, 'link_post': 'https://thanhnien.vn/chibooks-xay-dung-300-tu-sach-thu-vien-cho-nhieu-truong-trong-ca-nuoc-post1519496.html'}
Traceback (most recent call last):
  File "C:\Users\Admin\Documents\schedule_crawl_comment\crawl_cmt.py", line 106, in crawl_in_post
    comment = check_regex(config_site['comment_in_post']['detect']['re'], [str(data)])[0]
UnboundLocalError: local variable 'data' referenced before assignment
2022-11-10 16:18:51,944 - ERROR - {'message: exception when call api': 'https://thanhnien.vn/api/comments/get/by-obj?object_type=20&object_id={1519565}', 'status_code': 403, 'link_post': 'https://thanhnien.vn/gia-ve-may-bay-ve-tet-tang-cao-nguoi-tre-chua-biet-phai-tinh-sao-post1519565.html'}
Traceback (most recent call last):
  File "C:\Users\Admin\Documents\schedule_crawl_comment\venv\lib\site-packages\requests\models.py", line 971, in json
    return complexjson.loads(self.text, **kwargs)
  File "C:\Python\Python39\lib\json\__init__.py", line 346, in loads
    return _default_decoder.decode(s)
  File "C:\Python\Python39\lib\json\decoder.py", line 337, in decode
    obj, end = self.raw_decode(s, idx=_w(s, 0).end())
  File "C:\Python\Python39\lib\json\decoder.py", line 355, in raw_decode
    raise JSONDecodeError("Expecting value", s, err.value) from None
json.decoder.JSONDecodeError: Expecting value: line 1 column 1 (char 0)

During handling of the above exception, another exception occurred:

Traceback (most recent call last):
  File "C:\Users\Admin\Documents\schedule_crawl_comment\crawl_cmt.py", line 98, in crawl_in_post
    data = detect_responseType(config_site['comment_in_post']['responseType'], res)
  File "C:\Users\Admin\Documents\schedule_crawl_comment\crawl_cmt.py", line 177, in detect_responseType
    return res.json()
  File "C:\Users\Admin\Documents\schedule_crawl_comment\venv\lib\site-packages\requests\models.py", line 975, in json
    raise RequestsJSONDecodeError(e.msg, e.doc, e.pos)
requests.exceptions.JSONDecodeError: Expecting value: line 1 column 1 (char 0)
2022-11-10 16:18:51,944 - ERROR - {'message: exception when get comment in api': 'https://thanhnien.vn/api/comments/get/by-obj?object_type=20&object_id={1519565}', 'status_code': 403, 'link_post': 'https://thanhnien.vn/gia-ve-may-bay-ve-tet-tang-cao-nguoi-tre-chua-biet-phai-tinh-sao-post1519565.html'}
Traceback (most recent call last):
  File "C:\Users\Admin\Documents\schedule_crawl_comment\crawl_cmt.py", line 106, in crawl_in_post
    comment = check_regex(config_site['comment_in_post']['detect']['re'], [str(data)])[0]
UnboundLocalError: local variable 'data' referenced before assignment
2022-11-10 16:18:52,006 - ERROR - {'message: exception when call api': 'https://thanhnien.vn/api/comments/get/by-obj?object_type=20&object_id={1519484}', 'status_code': 403, 'link_post': 'https://thanhnien.vn/sieu-mau-irina-shayk-muon-quay-lai-voi-tinh-cu-bradley-cooper-post1519484.html'}
Traceback (most recent call last):
  File "C:\Users\Admin\Documents\schedule_crawl_comment\venv\lib\site-packages\requests\models.py", line 971, in json
    return complexjson.loads(self.text, **kwargs)
  File "C:\Python\Python39\lib\json\__init__.py", line 346, in loads
    return _default_decoder.decode(s)
  File "C:\Python\Python39\lib\json\decoder.py", line 337, in decode
    obj, end = self.raw_decode(s, idx=_w(s, 0).end())
  File "C:\Python\Python39\lib\json\decoder.py", line 355, in raw_decode
    raise JSONDecodeError("Expecting value", s, err.value) from None
json.decoder.JSONDecodeError: Expecting value: line 1 column 1 (char 0)

During handling of the above exception, another exception occurred:

Traceback (most recent call last):
  File "C:\Users\Admin\Documents\schedule_crawl_comment\crawl_cmt.py", line 98, in crawl_in_post
    data = detect_responseType(config_site['comment_in_post']['responseType'], res)
  File "C:\Users\Admin\Documents\schedule_crawl_comment\crawl_cmt.py", line 177, in detect_responseType
    return res.json()
  File "C:\Users\Admin\Documents\schedule_crawl_comment\venv\lib\site-packages\requests\models.py", line 975, in json
    raise RequestsJSONDecodeError(e.msg, e.doc, e.pos)
requests.exceptions.JSONDecodeError: Expecting value: line 1 column 1 (char 0)
2022-11-10 16:18:52,006 - ERROR - {'message: exception when get comment in api': 'https://thanhnien.vn/api/comments/get/by-obj?object_type=20&object_id={1519484}', 'status_code': 403, 'link_post': 'https://thanhnien.vn/sieu-mau-irina-shayk-muon-quay-lai-voi-tinh-cu-bradley-cooper-post1519484.html'}
Traceback (most recent call last):
  File "C:\Users\Admin\Documents\schedule_crawl_comment\crawl_cmt.py", line 106, in crawl_in_post
    comment = check_regex(config_site['comment_in_post']['detect']['re'], [str(data)])[0]
UnboundLocalError: local variable 'data' referenced before assignment
2022-11-10 16:18:52,036 - ERROR - {'message: exception when call api': 'https://thanhnien.vn/api/comments/get/by-obj?object_type=20&object_id={1519496}', 'status_code': 403, 'link_post': 'https://thanhnien.vn/chibooks-xay-dung-300-tu-sach-thu-vien-cho-nhieu-truong-trong-ca-nuoc-post1519496.html'}
Traceback (most recent call last):
  File "C:\Users\Admin\Documents\schedule_crawl_comment\venv\lib\site-packages\requests\models.py", line 971, in json
    return complexjson.loads(self.text, **kwargs)
  File "C:\Python\Python39\lib\json\__init__.py", line 346, in loads
    return _default_decoder.decode(s)
  File "C:\Python\Python39\lib\json\decoder.py", line 337, in decode
    obj, end = self.raw_decode(s, idx=_w(s, 0).end())
  File "C:\Python\Python39\lib\json\decoder.py", line 355, in raw_decode
    raise JSONDecodeError("Expecting value", s, err.value) from None
json.decoder.JSONDecodeError: Expecting value: line 1 column 1 (char 0)

During handling of the above exception, another exception occurred:

Traceback (most recent call last):
  File "C:\Users\Admin\Documents\schedule_crawl_comment\crawl_cmt.py", line 98, in crawl_in_post
    data = detect_responseType(config_site['comment_in_post']['responseType'], res)
  File "C:\Users\Admin\Documents\schedule_crawl_comment\crawl_cmt.py", line 177, in detect_responseType
    return res.json()
  File "C:\Users\Admin\Documents\schedule_crawl_comment\venv\lib\site-packages\requests\models.py", line 975, in json
    raise RequestsJSONDecodeError(e.msg, e.doc, e.pos)
requests.exceptions.JSONDecodeError: Expecting value: line 1 column 1 (char 0)
2022-11-10 16:18:52,036 - ERROR - {'message: exception when get comment in api': 'https://thanhnien.vn/api/comments/get/by-obj?object_type=20&object_id={1519496}', 'status_code': 403, 'link_post': 'https://thanhnien.vn/chibooks-xay-dung-300-tu-sach-thu-vien-cho-nhieu-truong-trong-ca-nuoc-post1519496.html'}
Traceback (most recent call last):
  File "C:\Users\Admin\Documents\schedule_crawl_comment\crawl_cmt.py", line 106, in crawl_in_post
    comment = check_regex(config_site['comment_in_post']['detect']['re'], [str(data)])[0]
UnboundLocalError: local variable 'data' referenced before assignment
2022-11-10 16:18:52,077 - ERROR - {'message: exception when call api': 'https://thanhnien.vn/api/comments/get/by-obj?object_type=20&object_id={1519584}', 'status_code': 403, 'link_post': 'https://thanhnien.vn/nhom-nhac-kpop-cua-hanbin-thang-giai-nghe-si-moi-xuat-sac-post1519584.html'}
Traceback (most recent call last):
  File "C:\Users\Admin\Documents\schedule_crawl_comment\venv\lib\site-packages\requests\models.py", line 971, in json
    return complexjson.loads(self.text, **kwargs)
  File "C:\Python\Python39\lib\json\__init__.py", line 346, in loads
    return _default_decoder.decode(s)
  File "C:\Python\Python39\lib\json\decoder.py", line 337, in decode
    obj, end = self.raw_decode(s, idx=_w(s, 0).end())
  File "C:\Python\Python39\lib\json\decoder.py", line 355, in raw_decode
    raise JSONDecodeError("Expecting value", s, err.value) from None
json.decoder.JSONDecodeError: Expecting value: line 1 column 1 (char 0)

During handling of the above exception, another exception occurred:

Traceback (most recent call last):
  File "C:\Users\Admin\Documents\schedule_crawl_comment\crawl_cmt.py", line 98, in crawl_in_post
    data = detect_responseType(config_site['comment_in_post']['responseType'], res)
  File "C:\Users\Admin\Documents\schedule_crawl_comment\crawl_cmt.py", line 177, in detect_responseType
    return res.json()
  File "C:\Users\Admin\Documents\schedule_crawl_comment\venv\lib\site-packages\requests\models.py", line 975, in json
    raise RequestsJSONDecodeError(e.msg, e.doc, e.pos)
requests.exceptions.JSONDecodeError: Expecting value: line 1 column 1 (char 0)
2022-11-10 16:18:52,077 - ERROR - {'message: exception when get comment in api': 'https://thanhnien.vn/api/comments/get/by-obj?object_type=20&object_id={1519584}', 'status_code': 403, 'link_post': 'https://thanhnien.vn/nhom-nhac-kpop-cua-hanbin-thang-giai-nghe-si-moi-xuat-sac-post1519584.html'}
Traceback (most recent call last):
  File "C:\Users\Admin\Documents\schedule_crawl_comment\crawl_cmt.py", line 106, in crawl_in_post
    comment = check_regex(config_site['comment_in_post']['detect']['re'], [str(data)])[0]
UnboundLocalError: local variable 'data' referenced before assignment
2022-11-10 16:18:52,108 - ERROR - {'message: exception when call api': 'https://thanhnien.vn/api/comments/get/by-obj?object_type=20&object_id={1519224}', 'status_code': 403, 'link_post': 'https://thanhnien.vn/my-nhan-nong-bong-nhat-hanh-tinh-chat-vat-sau-khi-chia-tay-nick-jonas-post1519224.html'}
Traceback (most recent call last):
  File "C:\Users\Admin\Documents\schedule_crawl_comment\venv\lib\site-packages\requests\models.py", line 971, in json
    return complexjson.loads(self.text, **kwargs)
  File "C:\Python\Python39\lib\json\__init__.py", line 346, in loads
    return _default_decoder.decode(s)
  File "C:\Python\Python39\lib\json\decoder.py", line 337, in decode
    obj, end = self.raw_decode(s, idx=_w(s, 0).end())
  File "C:\Python\Python39\lib\json\decoder.py", line 355, in raw_decode
    raise JSONDecodeError("Expecting value", s, err.value) from None
json.decoder.JSONDecodeError: Expecting value: line 1 column 1 (char 0)

During handling of the above exception, another exception occurred:

Traceback (most recent call last):
  File "C:\Users\Admin\Documents\schedule_crawl_comment\crawl_cmt.py", line 98, in crawl_in_post
    data = detect_responseType(config_site['comment_in_post']['responseType'], res)
  File "C:\Users\Admin\Documents\schedule_crawl_comment\crawl_cmt.py", line 177, in detect_responseType
    return res.json()
  File "C:\Users\Admin\Documents\schedule_crawl_comment\venv\lib\site-packages\requests\models.py", line 975, in json
    raise RequestsJSONDecodeError(e.msg, e.doc, e.pos)
requests.exceptions.JSONDecodeError: Expecting value: line 1 column 1 (char 0)
2022-11-10 16:18:52,108 - ERROR - {'message: exception when get comment in api': 'https://thanhnien.vn/api/comments/get/by-obj?object_type=20&object_id={1519224}', 'status_code': 403, 'link_post': 'https://thanhnien.vn/my-nhan-nong-bong-nhat-hanh-tinh-chat-vat-sau-khi-chia-tay-nick-jonas-post1519224.html'}
Traceback (most recent call last):
  File "C:\Users\Admin\Documents\schedule_crawl_comment\crawl_cmt.py", line 106, in crawl_in_post
    comment = check_regex(config_site['comment_in_post']['detect']['re'], [str(data)])[0]
UnboundLocalError: local variable 'data' referenced before assignment
2022-11-10 16:18:52,158 - ERROR - {'message: exception when call api': 'https://thanhnien.vn/api/comments/get/by-obj?object_type=20&object_id={1519121}', 'status_code': 403, 'link_post': 'https://thanhnien.vn/trang-tu-man-ly-hon-chong-doanh-nhan-sau-2-nam-cuoi-post1519121.html'}
Traceback (most recent call last):
  File "C:\Users\Admin\Documents\schedule_crawl_comment\venv\lib\site-packages\requests\models.py", line 971, in json
    return complexjson.loads(self.text, **kwargs)
  File "C:\Python\Python39\lib\json\__init__.py", line 346, in loads
    return _default_decoder.decode(s)
  File "C:\Python\Python39\lib\json\decoder.py", line 337, in decode
    obj, end = self.raw_decode(s, idx=_w(s, 0).end())
  File "C:\Python\Python39\lib\json\decoder.py", line 355, in raw_decode
    raise JSONDecodeError("Expecting value", s, err.value) from None
json.decoder.JSONDecodeError: Expecting value: line 1 column 1 (char 0)

During handling of the above exception, another exception occurred:

Traceback (most recent call last):
  File "C:\Users\Admin\Documents\schedule_crawl_comment\crawl_cmt.py", line 98, in crawl_in_post
    data = detect_responseType(config_site['comment_in_post']['responseType'], res)
  File "C:\Users\Admin\Documents\schedule_crawl_comment\crawl_cmt.py", line 177, in detect_responseType
    return res.json()
  File "C:\Users\Admin\Documents\schedule_crawl_comment\venv\lib\site-packages\requests\models.py", line 975, in json
    raise RequestsJSONDecodeError(e.msg, e.doc, e.pos)
requests.exceptions.JSONDecodeError: Expecting value: line 1 column 1 (char 0)
2022-11-10 16:18:52,158 - ERROR - {'message: exception when get comment in api': 'https://thanhnien.vn/api/comments/get/by-obj?object_type=20&object_id={1519121}', 'status_code': 403, 'link_post': 'https://thanhnien.vn/trang-tu-man-ly-hon-chong-doanh-nhan-sau-2-nam-cuoi-post1519121.html'}
Traceback (most recent call last):
  File "C:\Users\Admin\Documents\schedule_crawl_comment\crawl_cmt.py", line 106, in crawl_in_post
    comment = check_regex(config_site['comment_in_post']['detect']['re'], [str(data)])[0]
UnboundLocalError: local variable 'data' referenced before assignment
2022-11-10 16:18:52,168 - ERROR - {'message: exception when call api': 'https://thanhnien.vn/api/comments/get/by-obj?object_type=20&object_id={1519475}', 'status_code': 403, 'link_post': 'https://thanhnien.vn/nhat-kim-anh-lan-phuong-do-sac-voi-loat-hoa-hau-tren-tham-do-post1519475.html'}
Traceback (most recent call last):
  File "C:\Users\Admin\Documents\schedule_crawl_comment\venv\lib\site-packages\requests\models.py", line 971, in json
    return complexjson.loads(self.text, **kwargs)
  File "C:\Python\Python39\lib\json\__init__.py", line 346, in loads
    return _default_decoder.decode(s)
  File "C:\Python\Python39\lib\json\decoder.py", line 337, in decode
    obj, end = self.raw_decode(s, idx=_w(s, 0).end())
  File "C:\Python\Python39\lib\json\decoder.py", line 355, in raw_decode
    raise JSONDecodeError("Expecting value", s, err.value) from None
json.decoder.JSONDecodeError: Expecting value: line 1 column 1 (char 0)

During handling of the above exception, another exception occurred:

Traceback (most recent call last):
  File "C:\Users\Admin\Documents\schedule_crawl_comment\crawl_cmt.py", line 98, in crawl_in_post
    data = detect_responseType(config_site['comment_in_post']['responseType'], res)
  File "C:\Users\Admin\Documents\schedule_crawl_comment\crawl_cmt.py", line 177, in detect_responseType
    return res.json()
  File "C:\Users\Admin\Documents\schedule_crawl_comment\venv\lib\site-packages\requests\models.py", line 975, in json
    raise RequestsJSONDecodeError(e.msg, e.doc, e.pos)
requests.exceptions.JSONDecodeError: Expecting value: line 1 column 1 (char 0)
2022-11-10 16:18:52,168 - ERROR - {'message: exception when get comment in api': 'https://thanhnien.vn/api/comments/get/by-obj?object_type=20&object_id={1519475}', 'status_code': 403, 'link_post': 'https://thanhnien.vn/nhat-kim-anh-lan-phuong-do-sac-voi-loat-hoa-hau-tren-tham-do-post1519475.html'}
Traceback (most recent call last):
  File "C:\Users\Admin\Documents\schedule_crawl_comment\crawl_cmt.py", line 106, in crawl_in_post
    comment = check_regex(config_site['comment_in_post']['detect']['re'], [str(data)])[0]
UnboundLocalError: local variable 'data' referenced before assignment
2022-11-10 16:18:52,221 - ERROR - {'message: exception when call api': 'https://thanhnien.vn/api/comments/get/by-obj?object_type=20&object_id={1519584}', 'status_code': 403, 'link_post': 'https://thanhnien.vn/nhom-nhac-kpop-cua-hanbin-thang-giai-nghe-si-moi-xuat-sac-post1519584.html'}
Traceback (most recent call last):
  File "C:\Users\Admin\Documents\schedule_crawl_comment\venv\lib\site-packages\requests\models.py", line 971, in json
    return complexjson.loads(self.text, **kwargs)
  File "C:\Python\Python39\lib\json\__init__.py", line 346, in loads
    return _default_decoder.decode(s)
  File "C:\Python\Python39\lib\json\decoder.py", line 337, in decode
    obj, end = self.raw_decode(s, idx=_w(s, 0).end())
  File "C:\Python\Python39\lib\json\decoder.py", line 355, in raw_decode
    raise JSONDecodeError("Expecting value", s, err.value) from None
json.decoder.JSONDecodeError: Expecting value: line 1 column 1 (char 0)

During handling of the above exception, another exception occurred:

Traceback (most recent call last):
  File "C:\Users\Admin\Documents\schedule_crawl_comment\crawl_cmt.py", line 98, in crawl_in_post
    data = detect_responseType(config_site['comment_in_post']['responseType'], res)
  File "C:\Users\Admin\Documents\schedule_crawl_comment\crawl_cmt.py", line 177, in detect_responseType
    return res.json()
  File "C:\Users\Admin\Documents\schedule_crawl_comment\venv\lib\site-packages\requests\models.py", line 975, in json
    raise RequestsJSONDecodeError(e.msg, e.doc, e.pos)
requests.exceptions.JSONDecodeError: Expecting value: line 1 column 1 (char 0)
2022-11-10 16:18:52,231 - ERROR - {'message: exception when get comment in api': 'https://thanhnien.vn/api/comments/get/by-obj?object_type=20&object_id={1519584}', 'status_code': 403, 'link_post': 'https://thanhnien.vn/nhom-nhac-kpop-cua-hanbin-thang-giai-nghe-si-moi-xuat-sac-post1519584.html'}
Traceback (most recent call last):
  File "C:\Users\Admin\Documents\schedule_crawl_comment\crawl_cmt.py", line 106, in crawl_in_post
    comment = check_regex(config_site['comment_in_post']['detect']['re'], [str(data)])[0]
UnboundLocalError: local variable 'data' referenced before assignment
2022-11-10 16:18:52,363 - ERROR - {'message: exception when call api': 'https://thanhnien.vn/api/comments/get/by-obj?object_type=20&object_id={1519589}', 'status_code': 403, 'link_post': 'https://thanhnien.vn/giai-billiards-the-gioi-quyet-chien-ra-quan-thanh-tu-doi-dau-voi-so-1-the-gioi-post1519589.html'}
Traceback (most recent call last):
  File "C:\Users\Admin\Documents\schedule_crawl_comment\venv\lib\site-packages\requests\models.py", line 971, in json
    return complexjson.loads(self.text, **kwargs)
  File "C:\Python\Python39\lib\json\__init__.py", line 346, in loads
    return _default_decoder.decode(s)
  File "C:\Python\Python39\lib\json\decoder.py", line 337, in decode
    obj, end = self.raw_decode(s, idx=_w(s, 0).end())
  File "C:\Python\Python39\lib\json\decoder.py", line 355, in raw_decode
    raise JSONDecodeError("Expecting value", s, err.value) from None
json.decoder.JSONDecodeError: Expecting value: line 1 column 1 (char 0)

During handling of the above exception, another exception occurred:

Traceback (most recent call last):
  File "C:\Users\Admin\Documents\schedule_crawl_comment\crawl_cmt.py", line 98, in crawl_in_post
    data = detect_responseType(config_site['comment_in_post']['responseType'], res)
  File "C:\Users\Admin\Documents\schedule_crawl_comment\crawl_cmt.py", line 177, in detect_responseType
    return res.json()
  File "C:\Users\Admin\Documents\schedule_crawl_comment\venv\lib\site-packages\requests\models.py", line 975, in json
    raise RequestsJSONDecodeError(e.msg, e.doc, e.pos)
requests.exceptions.JSONDecodeError: Expecting value: line 1 column 1 (char 0)
2022-11-10 16:18:52,363 - ERROR - {'message: exception when get comment in api': 'https://thanhnien.vn/api/comments/get/by-obj?object_type=20&object_id={1519589}', 'status_code': 403, 'link_post': 'https://thanhnien.vn/giai-billiards-the-gioi-quyet-chien-ra-quan-thanh-tu-doi-dau-voi-so-1-the-gioi-post1519589.html'}
Traceback (most recent call last):
  File "C:\Users\Admin\Documents\schedule_crawl_comment\crawl_cmt.py", line 106, in crawl_in_post
    comment = check_regex(config_site['comment_in_post']['detect']['re'], [str(data)])[0]
UnboundLocalError: local variable 'data' referenced before assignment
2022-11-10 16:18:52,383 - ERROR - {'message: exception when call api': 'https://thanhnien.vn/api/comments/get/by-obj?object_type=20&object_id={1519511}', 'status_code': 403, 'link_post': 'https://thanhnien.vn/truong-dai-hoc-bach-khoa-dhqg-hcm-to-chuc-hoi-thao-quoc-te-post1519511.html'}
Traceback (most recent call last):
  File "C:\Users\Admin\Documents\schedule_crawl_comment\venv\lib\site-packages\requests\models.py", line 971, in json
    return complexjson.loads(self.text, **kwargs)
  File "C:\Python\Python39\lib\json\__init__.py", line 346, in loads
    return _default_decoder.decode(s)
  File "C:\Python\Python39\lib\json\decoder.py", line 337, in decode
    obj, end = self.raw_decode(s, idx=_w(s, 0).end())
  File "C:\Python\Python39\lib\json\decoder.py", line 355, in raw_decode
    raise JSONDecodeError("Expecting value", s, err.value) from None
json.decoder.JSONDecodeError: Expecting value: line 1 column 1 (char 0)

During handling of the above exception, another exception occurred:

Traceback (most recent call last):
  File "C:\Users\Admin\Documents\schedule_crawl_comment\crawl_cmt.py", line 98, in crawl_in_post
    data = detect_responseType(config_site['comment_in_post']['responseType'], res)
  File "C:\Users\Admin\Documents\schedule_crawl_comment\crawl_cmt.py", line 177, in detect_responseType
    return res.json()
  File "C:\Users\Admin\Documents\schedule_crawl_comment\venv\lib\site-packages\requests\models.py", line 975, in json
    raise RequestsJSONDecodeError(e.msg, e.doc, e.pos)
requests.exceptions.JSONDecodeError: Expecting value: line 1 column 1 (char 0)
2022-11-10 16:18:52,383 - ERROR - {'message: exception when get comment in api': 'https://thanhnien.vn/api/comments/get/by-obj?object_type=20&object_id={1519511}', 'status_code': 403, 'link_post': 'https://thanhnien.vn/truong-dai-hoc-bach-khoa-dhqg-hcm-to-chuc-hoi-thao-quoc-te-post1519511.html'}
Traceback (most recent call last):
  File "C:\Users\Admin\Documents\schedule_crawl_comment\crawl_cmt.py", line 106, in crawl_in_post
    comment = check_regex(config_site['comment_in_post']['detect']['re'], [str(data)])[0]
UnboundLocalError: local variable 'data' referenced before assignment
2022-11-10 16:18:52,383 - ERROR - {'message: exception when call api': 'https://thanhnien.vn/api/comments/get/by-obj?object_type=20&object_id={1519485}', 'status_code': 403, 'link_post': 'https://thanhnien.vn/so-lien-lac-dien-tu-bi-che-so-gd-dt-tphcm-noi-gi-post1519485.html'}
Traceback (most recent call last):
  File "C:\Users\Admin\Documents\schedule_crawl_comment\venv\lib\site-packages\requests\models.py", line 971, in json
    return complexjson.loads(self.text, **kwargs)
  File "C:\Python\Python39\lib\json\__init__.py", line 346, in loads
    return _default_decoder.decode(s)
  File "C:\Python\Python39\lib\json\decoder.py", line 337, in decode
    obj, end = self.raw_decode(s, idx=_w(s, 0).end())
  File "C:\Python\Python39\lib\json\decoder.py", line 355, in raw_decode
    raise JSONDecodeError("Expecting value", s, err.value) from None
json.decoder.JSONDecodeError: Expecting value: line 1 column 1 (char 0)

During handling of the above exception, another exception occurred:

Traceback (most recent call last):
  File "C:\Users\Admin\Documents\schedule_crawl_comment\crawl_cmt.py", line 98, in crawl_in_post
    data = detect_responseType(config_site['comment_in_post']['responseType'], res)
  File "C:\Users\Admin\Documents\schedule_crawl_comment\crawl_cmt.py", line 177, in detect_responseType
    return res.json()
  File "C:\Users\Admin\Documents\schedule_crawl_comment\venv\lib\site-packages\requests\models.py", line 975, in json
    raise RequestsJSONDecodeError(e.msg, e.doc, e.pos)
requests.exceptions.JSONDecodeError: Expecting value: line 1 column 1 (char 0)
2022-11-10 16:18:52,383 - ERROR - {'message: exception when get comment in api': 'https://thanhnien.vn/api/comments/get/by-obj?object_type=20&object_id={1519485}', 'status_code': 403, 'link_post': 'https://thanhnien.vn/so-lien-lac-dien-tu-bi-che-so-gd-dt-tphcm-noi-gi-post1519485.html'}
Traceback (most recent call last):
  File "C:\Users\Admin\Documents\schedule_crawl_comment\crawl_cmt.py", line 106, in crawl_in_post
    comment = check_regex(config_site['comment_in_post']['detect']['re'], [str(data)])[0]
UnboundLocalError: local variable 'data' referenced before assignment
2022-11-10 16:18:52,478 - ERROR - {'message: exception when call api': 'https://thanhnien.vn/api/comments/get/by-obj?object_type=20&object_id={1519426}', 'status_code': 403, 'link_post': 'https://thanhnien.vn/them-2-ngoi-sao-chia-tay-world-cup-chi-con-hon-10-ngay-khai-mac-post1519426.html'}
Traceback (most recent call last):
  File "C:\Users\Admin\Documents\schedule_crawl_comment\venv\lib\site-packages\requests\models.py", line 971, in json
    return complexjson.loads(self.text, **kwargs)
  File "C:\Python\Python39\lib\json\__init__.py", line 346, in loads
    return _default_decoder.decode(s)
  File "C:\Python\Python39\lib\json\decoder.py", line 337, in decode
    obj, end = self.raw_decode(s, idx=_w(s, 0).end())
  File "C:\Python\Python39\lib\json\decoder.py", line 355, in raw_decode
    raise JSONDecodeError("Expecting value", s, err.value) from None
json.decoder.JSONDecodeError: Expecting value: line 1 column 1 (char 0)

During handling of the above exception, another exception occurred:

Traceback (most recent call last):
  File "C:\Users\Admin\Documents\schedule_crawl_comment\crawl_cmt.py", line 98, in crawl_in_post
    data = detect_responseType(config_site['comment_in_post']['responseType'], res)
  File "C:\Users\Admin\Documents\schedule_crawl_comment\crawl_cmt.py", line 177, in detect_responseType
    return res.json()
  File "C:\Users\Admin\Documents\schedule_crawl_comment\venv\lib\site-packages\requests\models.py", line 975, in json
    raise RequestsJSONDecodeError(e.msg, e.doc, e.pos)
requests.exceptions.JSONDecodeError: Expecting value: line 1 column 1 (char 0)
2022-11-10 16:18:52,478 - ERROR - {'message: exception when get comment in api': 'https://thanhnien.vn/api/comments/get/by-obj?object_type=20&object_id={1519426}', 'status_code': 403, 'link_post': 'https://thanhnien.vn/them-2-ngoi-sao-chia-tay-world-cup-chi-con-hon-10-ngay-khai-mac-post1519426.html'}
Traceback (most recent call last):
  File "C:\Users\Admin\Documents\schedule_crawl_comment\crawl_cmt.py", line 106, in crawl_in_post
    comment = check_regex(config_site['comment_in_post']['detect']['re'], [str(data)])[0]
UnboundLocalError: local variable 'data' referenced before assignment
2022-11-10 16:18:52,498 - ERROR - {'message: exception when call api': 'https://thanhnien.vn/api/comments/get/by-obj?object_type=20&object_id={1519393}', 'status_code': 403, 'link_post': 'https://thanhnien.vn/cuoc-dien-thoai-dau-don-cua-hlv-tuyen-anh-cho-hau-ve-chelsea-post1519393.html'}
Traceback (most recent call last):
  File "C:\Users\Admin\Documents\schedule_crawl_comment\venv\lib\site-packages\requests\models.py", line 971, in json
    return complexjson.loads(self.text, **kwargs)
  File "C:\Python\Python39\lib\json\__init__.py", line 346, in loads
    return _default_decoder.decode(s)
  File "C:\Python\Python39\lib\json\decoder.py", line 337, in decode
    obj, end = self.raw_decode(s, idx=_w(s, 0).end())
  File "C:\Python\Python39\lib\json\decoder.py", line 355, in raw_decode
    raise JSONDecodeError("Expecting value", s, err.value) from None
json.decoder.JSONDecodeError: Expecting value: line 1 column 1 (char 0)

During handling of the above exception, another exception occurred:

Traceback (most recent call last):
  File "C:\Users\Admin\Documents\schedule_crawl_comment\crawl_cmt.py", line 98, in crawl_in_post
    data = detect_responseType(config_site['comment_in_post']['responseType'], res)
  File "C:\Users\Admin\Documents\schedule_crawl_comment\crawl_cmt.py", line 177, in detect_responseType
    return res.json()
  File "C:\Users\Admin\Documents\schedule_crawl_comment\venv\lib\site-packages\requests\models.py", line 975, in json
    raise RequestsJSONDecodeError(e.msg, e.doc, e.pos)
requests.exceptions.JSONDecodeError: Expecting value: line 1 column 1 (char 0)
2022-11-10 16:18:52,498 - ERROR - {'message: exception when call api': 'https://thanhnien.vn/api/comments/get/by-obj?object_type=20&object_id={1519358}', 'status_code': 403, 'link_post': 'https://thanhnien.vn/v-league-2022-hai-phong-thang-hoa-clb-tphcm-thoat-hiem-post1519358.html'}
Traceback (most recent call last):
  File "C:\Users\Admin\Documents\schedule_crawl_comment\venv\lib\site-packages\requests\models.py", line 971, in json
    return complexjson.loads(self.text, **kwargs)
  File "C:\Python\Python39\lib\json\__init__.py", line 346, in loads
    return _default_decoder.decode(s)
  File "C:\Python\Python39\lib\json\decoder.py", line 337, in decode
    obj, end = self.raw_decode(s, idx=_w(s, 0).end())
  File "C:\Python\Python39\lib\json\decoder.py", line 355, in raw_decode
    raise JSONDecodeError("Expecting value", s, err.value) from None
json.decoder.JSONDecodeError: Expecting value: line 1 column 1 (char 0)

During handling of the above exception, another exception occurred:

Traceback (most recent call last):
  File "C:\Users\Admin\Documents\schedule_crawl_comment\crawl_cmt.py", line 98, in crawl_in_post
    data = detect_responseType(config_site['comment_in_post']['responseType'], res)
  File "C:\Users\Admin\Documents\schedule_crawl_comment\crawl_cmt.py", line 177, in detect_responseType
    return res.json()
  File "C:\Users\Admin\Documents\schedule_crawl_comment\venv\lib\site-packages\requests\models.py", line 975, in json
    raise RequestsJSONDecodeError(e.msg, e.doc, e.pos)
requests.exceptions.JSONDecodeError: Expecting value: line 1 column 1 (char 0)
2022-11-10 16:18:52,498 - ERROR - {'message: exception when get comment in api': 'https://thanhnien.vn/api/comments/get/by-obj?object_type=20&object_id={1519393}', 'status_code': 403, 'link_post': 'https://thanhnien.vn/cuoc-dien-thoai-dau-don-cua-hlv-tuyen-anh-cho-hau-ve-chelsea-post1519393.html'}
Traceback (most recent call last):
  File "C:\Users\Admin\Documents\schedule_crawl_comment\crawl_cmt.py", line 106, in crawl_in_post
    comment = check_regex(config_site['comment_in_post']['detect']['re'], [str(data)])[0]
UnboundLocalError: local variable 'data' referenced before assignment
2022-11-10 16:18:52,498 - ERROR - {'message: exception when get comment in api': 'https://thanhnien.vn/api/comments/get/by-obj?object_type=20&object_id={1519358}', 'status_code': 403, 'link_post': 'https://thanhnien.vn/v-league-2022-hai-phong-thang-hoa-clb-tphcm-thoat-hiem-post1519358.html'}
Traceback (most recent call last):
  File "C:\Users\Admin\Documents\schedule_crawl_comment\crawl_cmt.py", line 106, in crawl_in_post
    comment = check_regex(config_site['comment_in_post']['detect']['re'], [str(data)])[0]
UnboundLocalError: local variable 'data' referenced before assignment
2022-11-10 16:18:52,574 - ERROR - {'message: exception when call api': 'https://thanhnien.vn/api/comments/get/by-obj?object_type=20&object_id={1519351}', 'status_code': 403, 'link_post': 'https://thanhnien.vn/sony-se-loai-bo-nhua-khoi-tat-ca-hop-dung-post1519351.html'}
Traceback (most recent call last):
  File "C:\Users\Admin\Documents\schedule_crawl_comment\venv\lib\site-packages\requests\models.py", line 971, in json
    return complexjson.loads(self.text, **kwargs)
  File "C:\Python\Python39\lib\json\__init__.py", line 346, in loads
    return _default_decoder.decode(s)
  File "C:\Python\Python39\lib\json\decoder.py", line 337, in decode
    obj, end = self.raw_decode(s, idx=_w(s, 0).end())
  File "C:\Python\Python39\lib\json\decoder.py", line 355, in raw_decode
    raise JSONDecodeError("Expecting value", s, err.value) from None
json.decoder.JSONDecodeError: Expecting value: line 1 column 1 (char 0)

During handling of the above exception, another exception occurred:

Traceback (most recent call last):
  File "C:\Users\Admin\Documents\schedule_crawl_comment\crawl_cmt.py", line 98, in crawl_in_post
    data = detect_responseType(config_site['comment_in_post']['responseType'], res)
  File "C:\Users\Admin\Documents\schedule_crawl_comment\crawl_cmt.py", line 177, in detect_responseType
    return res.json()
  File "C:\Users\Admin\Documents\schedule_crawl_comment\venv\lib\site-packages\requests\models.py", line 975, in json
    raise RequestsJSONDecodeError(e.msg, e.doc, e.pos)
requests.exceptions.JSONDecodeError: Expecting value: line 1 column 1 (char 0)
2022-11-10 16:18:52,574 - ERROR - {'message: exception when get comment in api': 'https://thanhnien.vn/api/comments/get/by-obj?object_type=20&object_id={1519351}', 'status_code': 403, 'link_post': 'https://thanhnien.vn/sony-se-loai-bo-nhua-khoi-tat-ca-hop-dung-post1519351.html'}
Traceback (most recent call last):
  File "C:\Users\Admin\Documents\schedule_crawl_comment\crawl_cmt.py", line 106, in crawl_in_post
    comment = check_regex(config_site['comment_in_post']['detect']['re'], [str(data)])[0]
UnboundLocalError: local variable 'data' referenced before assignment
2022-11-10 16:18:52,604 - ERROR - {'message: exception when call api': 'https://thanhnien.vn/api/comments/get/by-obj?object_type=20&object_id={1519187}', 'status_code': 403, 'link_post': 'https://thanhnien.vn/ra-mat-lang-blockchain-thuc-day-su-phat-trien-cong-nghe-so-post1519187.html'}
Traceback (most recent call last):
  File "C:\Users\Admin\Documents\schedule_crawl_comment\venv\lib\site-packages\requests\models.py", line 971, in json
    return complexjson.loads(self.text, **kwargs)
  File "C:\Python\Python39\lib\json\__init__.py", line 346, in loads
    return _default_decoder.decode(s)
  File "C:\Python\Python39\lib\json\decoder.py", line 337, in decode
    obj, end = self.raw_decode(s, idx=_w(s, 0).end())
  File "C:\Python\Python39\lib\json\decoder.py", line 355, in raw_decode
    raise JSONDecodeError("Expecting value", s, err.value) from None
json.decoder.JSONDecodeError: Expecting value: line 1 column 1 (char 0)

During handling of the above exception, another exception occurred:

Traceback (most recent call last):
  File "C:\Users\Admin\Documents\schedule_crawl_comment\crawl_cmt.py", line 98, in crawl_in_post
    data = detect_responseType(config_site['comment_in_post']['responseType'], res)
  File "C:\Users\Admin\Documents\schedule_crawl_comment\crawl_cmt.py", line 177, in detect_responseType
    return res.json()
  File "C:\Users\Admin\Documents\schedule_crawl_comment\venv\lib\site-packages\requests\models.py", line 975, in json
    raise RequestsJSONDecodeError(e.msg, e.doc, e.pos)
requests.exceptions.JSONDecodeError: Expecting value: line 1 column 1 (char 0)
2022-11-10 16:18:52,604 - ERROR - {'message: exception when get comment in api': 'https://thanhnien.vn/api/comments/get/by-obj?object_type=20&object_id={1519187}', 'status_code': 403, 'link_post': 'https://thanhnien.vn/ra-mat-lang-blockchain-thuc-day-su-phat-trien-cong-nghe-so-post1519187.html'}
Traceback (most recent call last):
  File "C:\Users\Admin\Documents\schedule_crawl_comment\crawl_cmt.py", line 106, in crawl_in_post
    comment = check_regex(config_site['comment_in_post']['detect']['re'], [str(data)])[0]
UnboundLocalError: local variable 'data' referenced before assignment
2022-11-10 16:18:52,615 - ERROR - {'message: exception when call api': 'https://thanhnien.vn/api/comments/get/by-obj?object_type=20&object_id={1519503}', 'status_code': 403, 'link_post': 'https://thanhnien.vn/bv-dh-y-duoc-tphcm-ky-ket-bien-ban-dao-tao-voi-bv-dhyd-shing-mark-post1519503.html'}
Traceback (most recent call last):
  File "C:\Users\Admin\Documents\schedule_crawl_comment\venv\lib\site-packages\requests\models.py", line 971, in json
    return complexjson.loads(self.text, **kwargs)
  File "C:\Python\Python39\lib\json\__init__.py", line 346, in loads
    return _default_decoder.decode(s)
  File "C:\Python\Python39\lib\json\decoder.py", line 337, in decode
    obj, end = self.raw_decode(s, idx=_w(s, 0).end())
  File "C:\Python\Python39\lib\json\decoder.py", line 355, in raw_decode
    raise JSONDecodeError("Expecting value", s, err.value) from None
json.decoder.JSONDecodeError: Expecting value: line 1 column 1 (char 0)

During handling of the above exception, another exception occurred:

Traceback (most recent call last):
  File "C:\Users\Admin\Documents\schedule_crawl_comment\crawl_cmt.py", line 98, in crawl_in_post
    data = detect_responseType(config_site['comment_in_post']['responseType'], res)
  File "C:\Users\Admin\Documents\schedule_crawl_comment\crawl_cmt.py", line 177, in detect_responseType
    return res.json()
  File "C:\Users\Admin\Documents\schedule_crawl_comment\venv\lib\site-packages\requests\models.py", line 975, in json
    raise RequestsJSONDecodeError(e.msg, e.doc, e.pos)
requests.exceptions.JSONDecodeError: Expecting value: line 1 column 1 (char 0)
2022-11-10 16:18:52,625 - ERROR - {'message: exception when get comment in api': 'https://thanhnien.vn/api/comments/get/by-obj?object_type=20&object_id={1519503}', 'status_code': 403, 'link_post': 'https://thanhnien.vn/bv-dh-y-duoc-tphcm-ky-ket-bien-ban-dao-tao-voi-bv-dhyd-shing-mark-post1519503.html'}
Traceback (most recent call last):
  File "C:\Users\Admin\Documents\schedule_crawl_comment\crawl_cmt.py", line 106, in crawl_in_post
    comment = check_regex(config_site['comment_in_post']['detect']['re'], [str(data)])[0]
UnboundLocalError: local variable 'data' referenced before assignment
2022-11-10 16:18:52,688 - ERROR - {'message: exception when call api': 'https://thanhnien.vn/api/comments/get/by-obj?object_type=20&object_id={1519506}', 'status_code': 403, 'link_post': 'https://thanhnien.vn/thang-112022-van-la-mua-cao-diem-phong-chong-dich-sot-xuat-huyet-post1519506.html'}
Traceback (most recent call last):
  File "C:\Users\Admin\Documents\schedule_crawl_comment\venv\lib\site-packages\requests\models.py", line 971, in json
    return complexjson.loads(self.text, **kwargs)
  File "C:\Python\Python39\lib\json\__init__.py", line 346, in loads
    return _default_decoder.decode(s)
  File "C:\Python\Python39\lib\json\decoder.py", line 337, in decode
    obj, end = self.raw_decode(s, idx=_w(s, 0).end())
  File "C:\Python\Python39\lib\json\decoder.py", line 355, in raw_decode
    raise JSONDecodeError("Expecting value", s, err.value) from None
json.decoder.JSONDecodeError: Expecting value: line 1 column 1 (char 0)

During handling of the above exception, another exception occurred:

Traceback (most recent call last):
  File "C:\Users\Admin\Documents\schedule_crawl_comment\crawl_cmt.py", line 98, in crawl_in_post
    data = detect_responseType(config_site['comment_in_post']['responseType'], res)
  File "C:\Users\Admin\Documents\schedule_crawl_comment\crawl_cmt.py", line 177, in detect_responseType
    return res.json()
  File "C:\Users\Admin\Documents\schedule_crawl_comment\venv\lib\site-packages\requests\models.py", line 975, in json
    raise RequestsJSONDecodeError(e.msg, e.doc, e.pos)
requests.exceptions.JSONDecodeError: Expecting value: line 1 column 1 (char 0)
2022-11-10 16:18:52,689 - ERROR - {'message: exception when get comment in api': 'https://thanhnien.vn/api/comments/get/by-obj?object_type=20&object_id={1519506}', 'status_code': 403, 'link_post': 'https://thanhnien.vn/thang-112022-van-la-mua-cao-diem-phong-chong-dich-sot-xuat-huyet-post1519506.html'}
Traceback (most recent call last):
  File "C:\Users\Admin\Documents\schedule_crawl_comment\crawl_cmt.py", line 106, in crawl_in_post
    comment = check_regex(config_site['comment_in_post']['detect']['re'], [str(data)])[0]
UnboundLocalError: local variable 'data' referenced before assignment
2022-11-10 16:18:52,741 - ERROR - {'message: exception when call api': 'https://thanhnien.vn/api/comments/get/by-obj?object_type=20&object_id={1519528}', 'status_code': 403, 'link_post': 'https://thanhnien.vn/o-to-hyundai-tucson-phanh-gap-tren-cau-bi-xe-tai-huc-duoi-ai-dung-ai-sai-post1519528.html'}
Traceback (most recent call last):
  File "C:\Users\Admin\Documents\schedule_crawl_comment\venv\lib\site-packages\requests\models.py", line 971, in json
    return complexjson.loads(self.text, **kwargs)
  File "C:\Python\Python39\lib\json\__init__.py", line 346, in loads
    return _default_decoder.decode(s)
  File "C:\Python\Python39\lib\json\decoder.py", line 337, in decode
    obj, end = self.raw_decode(s, idx=_w(s, 0).end())
  File "C:\Python\Python39\lib\json\decoder.py", line 355, in raw_decode
    raise JSONDecodeError("Expecting value", s, err.value) from None
json.decoder.JSONDecodeError: Expecting value: line 1 column 1 (char 0)

During handling of the above exception, another exception occurred:

Traceback (most recent call last):
  File "C:\Users\Admin\Documents\schedule_crawl_comment\crawl_cmt.py", line 98, in crawl_in_post
    data = detect_responseType(config_site['comment_in_post']['responseType'], res)
  File "C:\Users\Admin\Documents\schedule_crawl_comment\crawl_cmt.py", line 177, in detect_responseType
    return res.json()
  File "C:\Users\Admin\Documents\schedule_crawl_comment\venv\lib\site-packages\requests\models.py", line 975, in json
    raise RequestsJSONDecodeError(e.msg, e.doc, e.pos)
requests.exceptions.JSONDecodeError: Expecting value: line 1 column 1 (char 0)
2022-11-10 16:18:52,751 - ERROR - {'message: exception when get comment in api': 'https://thanhnien.vn/api/comments/get/by-obj?object_type=20&object_id={1519528}', 'status_code': 403, 'link_post': 'https://thanhnien.vn/o-to-hyundai-tucson-phanh-gap-tren-cau-bi-xe-tai-huc-duoi-ai-dung-ai-sai-post1519528.html'}
Traceback (most recent call last):
  File "C:\Users\Admin\Documents\schedule_crawl_comment\crawl_cmt.py", line 106, in crawl_in_post
    comment = check_regex(config_site['comment_in_post']['detect']['re'], [str(data)])[0]
UnboundLocalError: local variable 'data' referenced before assignment
2022-11-10 16:23:14,439 - ERROR - {'message': 'exception when get comment', 'link_post': 'https://linkhay.com/link/5806641/bat-mi-top-phan-mem-hack-xoc-dia-online-xin-nhat'}
Traceback (most recent call last):
  File "C:\Users\Admin\Documents\schedule_crawl_comment\crawl_cmt.py", line 84, in crawl_in_post
    comment = detect_type(1, lxml, config_site['comment_in_post'])[0]
IndexError: list index out of range
2022-11-10 16:23:15,050 - ERROR - {'message': 'exception when get comment', 'link_post': 'https://linkhay.com/link/5806640/bat-mi-cach-chia-bai-lieng-co-tien-cua-ca-lang-cuc-hay'}
Traceback (most recent call last):
  File "C:\Users\Admin\Documents\schedule_crawl_comment\crawl_cmt.py", line 84, in crawl_in_post
    comment = detect_type(1, lxml, config_site['comment_in_post'])[0]
IndexError: list index out of range
2022-11-10 16:23:18,094 - INFO - Thread-1 reupdate link https://linkhay.com/link/5806641/bat-mi-top-phan-mem-hack-xoc-dia-online-xin-nhat
2022-11-10 16:23:18,529 - ERROR - {'message': 'exception when get comment', 'link_post': 'https://linkhay.com/link/5806641/bat-mi-top-phan-mem-hack-xoc-dia-online-xin-nhat'}
Traceback (most recent call last):
  File "C:\Users\Admin\Documents\schedule_crawl_comment\crawl_cmt.py", line 84, in crawl_in_post
    comment = detect_type(1, lxml, config_site['comment_in_post'])[0]
IndexError: list index out of range
2022-11-10 16:23:18,529 - INFO - Thread-1 finish reupdate comment link: https://linkhay.com/link/5806641/bat-mi-top-phan-mem-hack-xoc-dia-online-xin-nhat
2022-11-10 16:23:18,539 - INFO - Thread-1 reupdate link https://linkhay.com/link/5806640/bat-mi-cach-chia-bai-lieng-co-tien-cua-ca-lang-cuc-hay
2022-11-10 16:23:18,995 - ERROR - {'message': 'exception when get comment', 'link_post': 'https://linkhay.com/link/5806640/bat-mi-cach-chia-bai-lieng-co-tien-cua-ca-lang-cuc-hay'}
Traceback (most recent call last):
  File "C:\Users\Admin\Documents\schedule_crawl_comment\crawl_cmt.py", line 84, in crawl_in_post
    comment = detect_type(1, lxml, config_site['comment_in_post'])[0]
IndexError: list index out of range
2022-11-10 16:23:18,995 - INFO - Thread-1 finish reupdate comment link: https://linkhay.com/link/5806640/bat-mi-cach-chia-bai-lieng-co-tien-cua-ca-lang-cuc-hay
2022-11-10 16:24:39,972 - ERROR - {'message': 'exception when get comment', 'link_post': 'https://tuoitre.vn/ket-noi-tuyen-duong-ven-song-co-hoi-huong-thu-song-sai-gon-20221108224326866.htm'}
Traceback (most recent call last):
  File "C:\Users\Admin\Documents\schedule_crawl_comment\crawl_cmt.py", line 88, in crawl_in_post
    website = send_request(link_post, type_crawl, param_scroll_down=False)
  File "C:\Users\Admin\Documents\schedule_crawl_comment\crawl_cmt.py", line 138, in send_request
    browser.get(link_cate)
  File "C:\Users\Admin\Documents\schedule_crawl_comment\venv\lib\site-packages\selenium\webdriver\remote\webdriver.py", line 455, in get
    self.execute(Command.GET, {"url": url})
  File "C:\Users\Admin\Documents\schedule_crawl_comment\venv\lib\site-packages\selenium\webdriver\remote\webdriver.py", line 444, in execute
    self.error_handler.check_response(response)
  File "C:\Users\Admin\Documents\schedule_crawl_comment\venv\lib\site-packages\selenium\webdriver\remote\errorhandler.py", line 249, in check_response
    raise exception_class(message, screen, stacktrace)
selenium.common.exceptions.TimeoutException: Message: timeout: Timed out receiving message from renderer: 299.800
  (Session info: headless chrome=107.0.5304.106)
Stacktrace:
Backtrace:
	Ordinal0 [0x0070ACD3+2075859]
	Ordinal0 [0x0069EE61+1633889]
	Ordinal0 [0x0059B7BD+571325]
	Ordinal0 [0x0058E410+517136]
	Ordinal0 [0x0058E231+516657]
	Ordinal0 [0x0058D0A3+512163]
	Ordinal0 [0x0058D6D8+513752]
	Ordinal0 [0x00596662+550498]
	Ordinal0 [0x005A1BD5+596949]
	Ordinal0 [0x005A4FC0+610240]
	Ordinal0 [0x0058DA81+514689]
	Ordinal0 [0x005A1A0F+596495]
	Ordinal0 [0x005FB93B+964923]
	Ordinal0 [0x005E7136+880950]
	Ordinal0 [0x005BFEFD+720637]
	Ordinal0 [0x005C0F3F+724799]
	GetHandleVerifier [0x009BEED2+2769538]
	GetHandleVerifier [0x009B0D95+2711877]
	GetHandleVerifier [0x0079A03A+521194]
	GetHandleVerifier [0x00798DA0+516432]
	Ordinal0 [0x006A682C+1665068]
	Ordinal0 [0x006AB128+1683752]
	Ordinal0 [0x006AB215+1683989]
	Ordinal0 [0x006B6484+1729668]
	BaseThreadInitThunk [0x76D66939+25]
	RtlGetFullPathName_UEx [0x77598FD2+1218]
	RtlGetFullPathName_UEx [0x77598F9D+1165]

2022-11-10 16:24:42,011 - INFO - Thread-3 reupdate link https://tuoitre.vn/ket-noi-tuyen-duong-ven-song-co-hoi-huong-thu-song-sai-gon-20221108224326866.htm
2022-11-10 16:25:30,314 - INFO - Thread-3 finish reupdate comment link: https://tuoitre.vn/ket-noi-tuyen-duong-ven-song-co-hoi-huong-thu-song-sai-gon-20221108224326866.htm
2022-11-10 16:25:34,900 - INFO - not found data, url: https://thoitrangtre.thanhnien.vn
2022-11-10 16:26:09,823 - INFO - not found data, url: https://vnexpress.net//video.vnexpress.net
2022-11-10 16:26:41,007 - INFO - not found data, url: https://vnexpress.net/podcast
2022-11-10 16:26:47,427 - ERROR - except when crawl out post. 
link cate = https://vnexpress.net/tam-su
 Message: stale element reference: element is not attached to the page document
  (Session info: headless chrome=107.0.5304.106)
Stacktrace:
Backtrace:
	Ordinal0 [0x0070ACD3+2075859]
	Ordinal0 [0x0069EE61+1633889]
	Ordinal0 [0x0059B7BD+571325]
	Ordinal0 [0x0059E374+582516]
	Ordinal0 [0x0059E225+582181]
	Ordinal0 [0x0059EBA5+584613]
	Ordinal0 [0x005FBF4F+966479]
	Ordinal0 [0x005E731C+881436]
	Ordinal0 [0x005FB56A+963946]
	Ordinal0 [0x005E7136+880950]
	Ordinal0 [0x005BFEFD+720637]
	Ordinal0 [0x005C0F3F+724799]
	GetHandleVerifier [0x009BEED2+2769538]
	GetHandleVerifier [0x009B0D95+2711877]
	GetHandleVerifier [0x0079A03A+521194]
	GetHandleVerifier [0x00798DA0+516432]
	Ordinal0 [0x006A682C+1665068]
	Ordinal0 [0x006AB128+1683752]
	Ordinal0 [0x006AB215+1683989]
	Ordinal0 [0x006B6484+1729668]
	BaseThreadInitThunk [0x76D66939+25]
	RtlGetFullPathName_UEx [0x77598FD2+1218]
	RtlGetFullPathName_UEx [0x77598F9D+1165]
Traceback (most recent call last):
  File "C:\Users\Admin\Documents\schedule_crawl_comment\crawl_cmt.py", line 49, in crawl_out_post
    comment = re.findall(r'\d+', obj.get_attribute('textContent'))
  File "C:\Users\Admin\Documents\schedule_crawl_comment\venv\lib\site-packages\selenium\webdriver\remote\webelement.py", line 179, in get_attribute
    attribute_value = self.parent.execute_script(
  File "C:\Users\Admin\Documents\schedule_crawl_comment\venv\lib\site-packages\selenium\webdriver\remote\webdriver.py", line 506, in execute_script
    return self.execute(command, {"script": script, "args": converted_args})["value"]
  File "C:\Users\Admin\Documents\schedule_crawl_comment\venv\lib\site-packages\selenium\webdriver\remote\webdriver.py", line 444, in execute
    self.error_handler.check_response(response)
  File "C:\Users\Admin\Documents\schedule_crawl_comment\venv\lib\site-packages\selenium\webdriver\remote\errorhandler.py", line 249, in check_response
    raise exception_class(message, screen, stacktrace)
selenium.common.exceptions.StaleElementReferenceException: Message: stale element reference: element is not attached to the page document
  (Session info: headless chrome=107.0.5304.106)
Stacktrace:
Backtrace:
	Ordinal0 [0x0070ACD3+2075859]
	Ordinal0 [0x0069EE61+1633889]
	Ordinal0 [0x0059B7BD+571325]
	Ordinal0 [0x0059E374+582516]
	Ordinal0 [0x0059E225+582181]
	Ordinal0 [0x0059EBA5+584613]
	Ordinal0 [0x005FBF4F+966479]
	Ordinal0 [0x005E731C+881436]
	Ordinal0 [0x005FB56A+963946]
	Ordinal0 [0x005E7136+880950]
	Ordinal0 [0x005BFEFD+720637]
	Ordinal0 [0x005C0F3F+724799]
	GetHandleVerifier [0x009BEED2+2769538]
	GetHandleVerifier [0x009B0D95+2711877]
	GetHandleVerifier [0x0079A03A+521194]
	GetHandleVerifier [0x00798DA0+516432]
	Ordinal0 [0x006A682C+1665068]
	Ordinal0 [0x006AB128+1683752]
	Ordinal0 [0x006AB215+1683989]
	Ordinal0 [0x006B6484+1729668]
	BaseThreadInitThunk [0x76D66939+25]
	RtlGetFullPathName_UEx [0x77598FD2+1218]
	RtlGetFullPathName_UEx [0x77598F9D+1165]

2022-11-10 16:26:49,542 - INFO - Thread-7 recrawl url: https://vnexpress.net/tam-su
2022-11-10 16:26:49,735 - INFO - not found data, url: https://vnexpress.net/du-lich
2022-11-10 16:27:05,510 - ERROR - except when crawl out post. 
link cate = https://vnexpress.net/tam-su
 Message: stale element reference: element is not attached to the page document
  (Session info: headless chrome=107.0.5304.106)
Stacktrace:
Backtrace:
	Ordinal0 [0x0070ACD3+2075859]
	Ordinal0 [0x0069EE61+1633889]
	Ordinal0 [0x0059B7BD+571325]
	Ordinal0 [0x0059E374+582516]
	Ordinal0 [0x0059E225+582181]
	Ordinal0 [0x0059EBA5+584613]
	Ordinal0 [0x005FBF4F+966479]
	Ordinal0 [0x005E731C+881436]
	Ordinal0 [0x005FB56A+963946]
	Ordinal0 [0x005E7136+880950]
	Ordinal0 [0x005BFEFD+720637]
	Ordinal0 [0x005C0F3F+724799]
	GetHandleVerifier [0x009BEED2+2769538]
	GetHandleVerifier [0x009B0D95+2711877]
	GetHandleVerifier [0x0079A03A+521194]
	GetHandleVerifier [0x00798DA0+516432]
	Ordinal0 [0x006A682C+1665068]
	Ordinal0 [0x006AB128+1683752]
	Ordinal0 [0x006AB215+1683989]
	Ordinal0 [0x006B6484+1729668]
	BaseThreadInitThunk [0x76D66939+25]
	RtlGetFullPathName_UEx [0x77598FD2+1218]
	RtlGetFullPathName_UEx [0x77598F9D+1165]
Traceback (most recent call last):
  File "C:\Users\Admin\Documents\schedule_crawl_comment\crawl_cmt.py", line 49, in crawl_out_post
    comment = re.findall(r'\d+', obj.get_attribute('textContent'))
  File "C:\Users\Admin\Documents\schedule_crawl_comment\venv\lib\site-packages\selenium\webdriver\remote\webelement.py", line 179, in get_attribute
    attribute_value = self.parent.execute_script(
  File "C:\Users\Admin\Documents\schedule_crawl_comment\venv\lib\site-packages\selenium\webdriver\remote\webdriver.py", line 506, in execute_script
    return self.execute(command, {"script": script, "args": converted_args})["value"]
  File "C:\Users\Admin\Documents\schedule_crawl_comment\venv\lib\site-packages\selenium\webdriver\remote\webdriver.py", line 444, in execute
    self.error_handler.check_response(response)
  File "C:\Users\Admin\Documents\schedule_crawl_comment\venv\lib\site-packages\selenium\webdriver\remote\errorhandler.py", line 249, in check_response
    raise exception_class(message, screen, stacktrace)
selenium.common.exceptions.StaleElementReferenceException: Message: stale element reference: element is not attached to the page document
  (Session info: headless chrome=107.0.5304.106)
Stacktrace:
Backtrace:
	Ordinal0 [0x0070ACD3+2075859]
	Ordinal0 [0x0069EE61+1633889]
	Ordinal0 [0x0059B7BD+571325]
	Ordinal0 [0x0059E374+582516]
	Ordinal0 [0x0059E225+582181]
	Ordinal0 [0x0059EBA5+584613]
	Ordinal0 [0x005FBF4F+966479]
	Ordinal0 [0x005E731C+881436]
	Ordinal0 [0x005FB56A+963946]
	Ordinal0 [0x005E7136+880950]
	Ordinal0 [0x005BFEFD+720637]
	Ordinal0 [0x005C0F3F+724799]
	GetHandleVerifier [0x009BEED2+2769538]
	GetHandleVerifier [0x009B0D95+2711877]
	GetHandleVerifier [0x0079A03A+521194]
	GetHandleVerifier [0x00798DA0+516432]
	Ordinal0 [0x006A682C+1665068]
	Ordinal0 [0x006AB128+1683752]
	Ordinal0 [0x006AB215+1683989]
	Ordinal0 [0x006B6484+1729668]
	BaseThreadInitThunk [0x76D66939+25]
	RtlGetFullPathName_UEx [0x77598FD2+1218]
	RtlGetFullPathName_UEx [0x77598F9D+1165]

2022-11-10 16:27:05,579 - INFO - not found data, url: https://vnexpress.net/tam-su
2022-11-10 16:27:07,583 - INFO - Thread-7 finished recrawl out post url: https://vnexpress.net/tam-su
2022-11-10 16:27:36,855 - INFO - not found data, url: https://tuoitre.vn/media.htm
2022-11-10 16:27:43,033 - INFO - not found data, url: https://congnghe.tuoitre.vn
2022-11-10 16:27:44,892 - INFO - not found data, url: https://tuoitre.vn/xe.htm
2022-11-10 16:27:45,304 - INFO - not found data, url: https://dulich.tuoitre.vn
2022-11-10 16:27:57,949 - INFO - not found data, url: https://tuoitre.vn/giai-tri.htm
2022-11-10 16:28:12,595 - INFO - not found data, url: https://tuoitre.vn/gia-that.htm
2022-11-10 16:28:12,906 - INFO - not found data, url: https://tuoitre.vn/ban-doc-lam-bao.htm
2022-11-10 16:28:37,112 - INFO - not found data, url: https://vietnamnet.vn/kinh-doanh
2022-11-10 16:28:48,523 - INFO - not found data, url: https://vietnamnet.vn/the-gioi
2022-11-10 16:28:50,214 - INFO - not found data, url: https://vietnamnet.vn/thoi-su
2022-11-10 16:29:14,285 - INFO - not found data, url: https://vietnamnet.vn/the-thao
2022-11-10 16:29:24,555 - INFO - not found data, url: https://vietnamnet.vn/phap-luat
2022-11-10 16:29:38,240 - INFO - not found data, url: https://vietnamnet.vn/oto-xe-may
2022-11-10 16:29:59,505 - INFO - not found data, url: https://vietnamnet.vn/giao-duc
2022-11-10 16:30:21,420 - INFO - not found data, url: https://vietnamnet.vn/ban-doc
2022-11-10 16:30:28,311 - INFO - not found data, url: https://vietnamnet.vn/video
2022-11-10 16:30:58,009 - INFO - Job "main (trigger: interval[1:00:00], next run at: 2022-11-10 17:18:47 +07)" executed successfully
