2022-11-10 14:41:04,019 - INFO - 

_____________________________new_log_____________________________
2022-11-10 14:42:04,023 - WARNING - Execution of job "main (trigger: interval[0:01:00], next run at: 2022-11-10 14:42:04 +07)" skipped: maximum number of running instances reached (1)
2022-11-10 14:42:26,586 - ERROR - {'message': 'exception when get comment', 'link_post': 'https://tuoitre.vn/nha-van-phap-marc-levy-xuc-dong-khi-xem-kich-moi-dieu-ta-chua-noi-20221108041647732.htm'}
Traceback (most recent call last):
  File "C:\Users\Admin\Documents\schedule_crawl_comment\venv\lib\site-packages\urllib3\connectionpool.py", line 703, in urlopen
    httplib_response = self._make_request(
  File "C:\Users\Admin\Documents\schedule_crawl_comment\venv\lib\site-packages\urllib3\connectionpool.py", line 449, in _make_request
    six.raise_from(e, None)
  File "<string>", line 3, in raise_from
  File "C:\Users\Admin\Documents\schedule_crawl_comment\venv\lib\site-packages\urllib3\connectionpool.py", line 444, in _make_request
    httplib_response = conn.getresponse()
  File "C:\Python\Python39\lib\http\client.py", line 1377, in getresponse
    response.begin()
  File "C:\Python\Python39\lib\http\client.py", line 320, in begin
    version, status, reason = self._read_status()
  File "C:\Python\Python39\lib\http\client.py", line 281, in _read_status
    line = str(self.fp.readline(_MAXLINE + 1), "iso-8859-1")
  File "C:\Python\Python39\lib\socket.py", line 704, in readinto
    return self._sock.recv_into(b)
ConnectionResetError: [WinError 10054] An existing connection was forcibly closed by the remote host

During handling of the above exception, another exception occurred:

Traceback (most recent call last):
  File "C:\Users\Admin\Documents\schedule_crawl_comment\crawl_cmt.py", line 88, in crawl_in_post
    website = send_request(link_post, type_crawl, param_scroll_down=False)
  File "C:\Users\Admin\Documents\schedule_crawl_comment\crawl_cmt.py", line 138, in send_request
    browser.get(link_cate)
  File "C:\Users\Admin\Documents\schedule_crawl_comment\venv\lib\site-packages\selenium\webdriver\remote\webdriver.py", line 455, in get
    self.execute(Command.GET, {"url": url})
  File "C:\Users\Admin\Documents\schedule_crawl_comment\venv\lib\site-packages\selenium\webdriver\remote\webdriver.py", line 442, in execute
    response = self.command_executor.execute(driver_command, params)
  File "C:\Users\Admin\Documents\schedule_crawl_comment\venv\lib\site-packages\selenium\webdriver\remote\remote_connection.py", line 294, in execute
    return self._request(command_info[0], url, body=data)
  File "C:\Users\Admin\Documents\schedule_crawl_comment\venv\lib\site-packages\selenium\webdriver\remote\remote_connection.py", line 316, in _request
    response = self._conn.request(method, url, body=body, headers=headers)
  File "C:\Users\Admin\Documents\schedule_crawl_comment\venv\lib\site-packages\urllib3\request.py", line 78, in request
    return self.request_encode_body(
  File "C:\Users\Admin\Documents\schedule_crawl_comment\venv\lib\site-packages\urllib3\request.py", line 170, in request_encode_body
    return self.urlopen(method, url, **extra_kw)
  File "C:\Users\Admin\Documents\schedule_crawl_comment\venv\lib\site-packages\urllib3\poolmanager.py", line 376, in urlopen
    response = conn.urlopen(method, u.request_uri, **kw)
  File "C:\Users\Admin\Documents\schedule_crawl_comment\venv\lib\site-packages\urllib3\connectionpool.py", line 787, in urlopen
    retries = retries.increment(
  File "C:\Users\Admin\Documents\schedule_crawl_comment\venv\lib\site-packages\urllib3\util\retry.py", line 550, in increment
    raise six.reraise(type(error), error, _stacktrace)
  File "C:\Users\Admin\Documents\schedule_crawl_comment\venv\lib\site-packages\urllib3\packages\six.py", line 769, in reraise
    raise value.with_traceback(tb)
  File "C:\Users\Admin\Documents\schedule_crawl_comment\venv\lib\site-packages\urllib3\connectionpool.py", line 703, in urlopen
    httplib_response = self._make_request(
  File "C:\Users\Admin\Documents\schedule_crawl_comment\venv\lib\site-packages\urllib3\connectionpool.py", line 449, in _make_request
    six.raise_from(e, None)
  File "<string>", line 3, in raise_from
  File "C:\Users\Admin\Documents\schedule_crawl_comment\venv\lib\site-packages\urllib3\connectionpool.py", line 444, in _make_request
    httplib_response = conn.getresponse()
  File "C:\Python\Python39\lib\http\client.py", line 1377, in getresponse
    response.begin()
  File "C:\Python\Python39\lib\http\client.py", line 320, in begin
    version, status, reason = self._read_status()
  File "C:\Python\Python39\lib\http\client.py", line 281, in _read_status
    line = str(self.fp.readline(_MAXLINE + 1), "iso-8859-1")
  File "C:\Python\Python39\lib\socket.py", line 704, in readinto
    return self._sock.recv_into(b)
urllib3.exceptions.ProtocolError: ('Connection aborted.', ConnectionResetError(10054, 'An existing connection was forcibly closed by the remote host', None, 10054, None))
2022-11-10 14:42:26,588 - ERROR - {'message': 'exception when get comment', 'link_post': 'https://tuoitre.vn/nha-van-phap-marc-levy-xuc-dong-khi-xem-kich-moi-dieu-ta-chua-noi-20221108041647732.htm'}
Traceback (most recent call last):
  File "C:\Users\Admin\Documents\schedule_crawl_comment\venv\lib\site-packages\urllib3\connectionpool.py", line 703, in urlopen
    httplib_response = self._make_request(
  File "C:\Users\Admin\Documents\schedule_crawl_comment\venv\lib\site-packages\urllib3\connectionpool.py", line 449, in _make_request
    six.raise_from(e, None)
  File "<string>", line 3, in raise_from
  File "C:\Users\Admin\Documents\schedule_crawl_comment\venv\lib\site-packages\urllib3\connectionpool.py", line 444, in _make_request
    httplib_response = conn.getresponse()
  File "C:\Python\Python39\lib\http\client.py", line 1377, in getresponse
    response.begin()
  File "C:\Python\Python39\lib\http\client.py", line 320, in begin
    version, status, reason = self._read_status()
  File "C:\Python\Python39\lib\http\client.py", line 281, in _read_status
    line = str(self.fp.readline(_MAXLINE + 1), "iso-8859-1")
  File "C:\Python\Python39\lib\socket.py", line 704, in readinto
    return self._sock.recv_into(b)
ConnectionResetError: [WinError 10054] An existing connection was forcibly closed by the remote host

During handling of the above exception, another exception occurred:

Traceback (most recent call last):
  File "C:\Users\Admin\Documents\schedule_crawl_comment\crawl_cmt.py", line 88, in crawl_in_post
    website = send_request(link_post, type_crawl, param_scroll_down=False)
  File "C:\Users\Admin\Documents\schedule_crawl_comment\crawl_cmt.py", line 138, in send_request
    browser.get(link_cate)
  File "C:\Users\Admin\Documents\schedule_crawl_comment\venv\lib\site-packages\selenium\webdriver\remote\webdriver.py", line 455, in get
    self.execute(Command.GET, {"url": url})
  File "C:\Users\Admin\Documents\schedule_crawl_comment\venv\lib\site-packages\selenium\webdriver\remote\webdriver.py", line 442, in execute
    response = self.command_executor.execute(driver_command, params)
  File "C:\Users\Admin\Documents\schedule_crawl_comment\venv\lib\site-packages\selenium\webdriver\remote\remote_connection.py", line 294, in execute
    return self._request(command_info[0], url, body=data)
  File "C:\Users\Admin\Documents\schedule_crawl_comment\venv\lib\site-packages\selenium\webdriver\remote\remote_connection.py", line 316, in _request
    response = self._conn.request(method, url, body=body, headers=headers)
  File "C:\Users\Admin\Documents\schedule_crawl_comment\venv\lib\site-packages\urllib3\request.py", line 78, in request
    return self.request_encode_body(
  File "C:\Users\Admin\Documents\schedule_crawl_comment\venv\lib\site-packages\urllib3\request.py", line 170, in request_encode_body
    return self.urlopen(method, url, **extra_kw)
  File "C:\Users\Admin\Documents\schedule_crawl_comment\venv\lib\site-packages\urllib3\poolmanager.py", line 376, in urlopen
    response = conn.urlopen(method, u.request_uri, **kw)
  File "C:\Users\Admin\Documents\schedule_crawl_comment\venv\lib\site-packages\urllib3\connectionpool.py", line 787, in urlopen
    retries = retries.increment(
  File "C:\Users\Admin\Documents\schedule_crawl_comment\venv\lib\site-packages\urllib3\util\retry.py", line 550, in increment
    raise six.reraise(type(error), error, _stacktrace)
  File "C:\Users\Admin\Documents\schedule_crawl_comment\venv\lib\site-packages\urllib3\packages\six.py", line 769, in reraise
    raise value.with_traceback(tb)
  File "C:\Users\Admin\Documents\schedule_crawl_comment\venv\lib\site-packages\urllib3\connectionpool.py", line 703, in urlopen
    httplib_response = self._make_request(
  File "C:\Users\Admin\Documents\schedule_crawl_comment\venv\lib\site-packages\urllib3\connectionpool.py", line 449, in _make_request
    six.raise_from(e, None)
  File "<string>", line 3, in raise_from
  File "C:\Users\Admin\Documents\schedule_crawl_comment\venv\lib\site-packages\urllib3\connectionpool.py", line 444, in _make_request
    httplib_response = conn.getresponse()
  File "C:\Python\Python39\lib\http\client.py", line 1377, in getresponse
    response.begin()
  File "C:\Python\Python39\lib\http\client.py", line 320, in begin
    version, status, reason = self._read_status()
  File "C:\Python\Python39\lib\http\client.py", line 281, in _read_status
    line = str(self.fp.readline(_MAXLINE + 1), "iso-8859-1")
  File "C:\Python\Python39\lib\socket.py", line 704, in readinto
    return self._sock.recv_into(b)
urllib3.exceptions.ProtocolError: ('Connection aborted.', ConnectionResetError(10054, 'An existing connection was forcibly closed by the remote host', None, 10054, None))
2022-11-10 14:42:26,588 - ERROR - {'message': 'exception when get comment', 'link_post': 'https://tuoitre.vn/nha-van-phap-marc-levy-xuc-dong-khi-xem-kich-moi-dieu-ta-chua-noi-20221108041647732.htm'}
Traceback (most recent call last):
  File "C:\Users\Admin\Documents\schedule_crawl_comment\venv\lib\site-packages\urllib3\connectionpool.py", line 703, in urlopen
    httplib_response = self._make_request(
  File "C:\Users\Admin\Documents\schedule_crawl_comment\venv\lib\site-packages\urllib3\connectionpool.py", line 449, in _make_request
    six.raise_from(e, None)
  File "<string>", line 3, in raise_from
  File "C:\Users\Admin\Documents\schedule_crawl_comment\venv\lib\site-packages\urllib3\connectionpool.py", line 444, in _make_request
    httplib_response = conn.getresponse()
  File "C:\Python\Python39\lib\http\client.py", line 1377, in getresponse
    response.begin()
  File "C:\Python\Python39\lib\http\client.py", line 320, in begin
    version, status, reason = self._read_status()
  File "C:\Python\Python39\lib\http\client.py", line 281, in _read_status
    line = str(self.fp.readline(_MAXLINE + 1), "iso-8859-1")
  File "C:\Python\Python39\lib\socket.py", line 704, in readinto
    return self._sock.recv_into(b)
ConnectionResetError: [WinError 10054] An existing connection was forcibly closed by the remote host

During handling of the above exception, another exception occurred:

Traceback (most recent call last):
  File "C:\Users\Admin\Documents\schedule_crawl_comment\crawl_cmt.py", line 88, in crawl_in_post
    website = send_request(link_post, type_crawl, param_scroll_down=False)
  File "C:\Users\Admin\Documents\schedule_crawl_comment\crawl_cmt.py", line 138, in send_request
    browser.get(link_cate)
  File "C:\Users\Admin\Documents\schedule_crawl_comment\venv\lib\site-packages\selenium\webdriver\remote\webdriver.py", line 455, in get
    self.execute(Command.GET, {"url": url})
  File "C:\Users\Admin\Documents\schedule_crawl_comment\venv\lib\site-packages\selenium\webdriver\remote\webdriver.py", line 442, in execute
    response = self.command_executor.execute(driver_command, params)
  File "C:\Users\Admin\Documents\schedule_crawl_comment\venv\lib\site-packages\selenium\webdriver\remote\remote_connection.py", line 294, in execute
    return self._request(command_info[0], url, body=data)
  File "C:\Users\Admin\Documents\schedule_crawl_comment\venv\lib\site-packages\selenium\webdriver\remote\remote_connection.py", line 316, in _request
    response = self._conn.request(method, url, body=body, headers=headers)
  File "C:\Users\Admin\Documents\schedule_crawl_comment\venv\lib\site-packages\urllib3\request.py", line 78, in request
    return self.request_encode_body(
  File "C:\Users\Admin\Documents\schedule_crawl_comment\venv\lib\site-packages\urllib3\request.py", line 170, in request_encode_body
    return self.urlopen(method, url, **extra_kw)
  File "C:\Users\Admin\Documents\schedule_crawl_comment\venv\lib\site-packages\urllib3\poolmanager.py", line 376, in urlopen
    response = conn.urlopen(method, u.request_uri, **kw)
  File "C:\Users\Admin\Documents\schedule_crawl_comment\venv\lib\site-packages\urllib3\connectionpool.py", line 787, in urlopen
    retries = retries.increment(
  File "C:\Users\Admin\Documents\schedule_crawl_comment\venv\lib\site-packages\urllib3\util\retry.py", line 550, in increment
    raise six.reraise(type(error), error, _stacktrace)
  File "C:\Users\Admin\Documents\schedule_crawl_comment\venv\lib\site-packages\urllib3\packages\six.py", line 769, in reraise
    raise value.with_traceback(tb)
  File "C:\Users\Admin\Documents\schedule_crawl_comment\venv\lib\site-packages\urllib3\connectionpool.py", line 703, in urlopen
    httplib_response = self._make_request(
  File "C:\Users\Admin\Documents\schedule_crawl_comment\venv\lib\site-packages\urllib3\connectionpool.py", line 449, in _make_request
    six.raise_from(e, None)
  File "<string>", line 3, in raise_from
  File "C:\Users\Admin\Documents\schedule_crawl_comment\venv\lib\site-packages\urllib3\connectionpool.py", line 444, in _make_request
    httplib_response = conn.getresponse()
  File "C:\Python\Python39\lib\http\client.py", line 1377, in getresponse
    response.begin()
  File "C:\Python\Python39\lib\http\client.py", line 320, in begin
    version, status, reason = self._read_status()
  File "C:\Python\Python39\lib\http\client.py", line 281, in _read_status
    line = str(self.fp.readline(_MAXLINE + 1), "iso-8859-1")
  File "C:\Python\Python39\lib\socket.py", line 704, in readinto
    return self._sock.recv_into(b)
urllib3.exceptions.ProtocolError: ('Connection aborted.', ConnectionResetError(10054, 'An existing connection was forcibly closed by the remote host', None, 10054, None))
