2022-11-08 10:38:24,073 - INFO - 

_____________________________new_log_____________________________
2022-11-08 10:38:57,699 - ERROR - {'message': 'exception when get comment', 'link_post': 'https://linkhay.com/link/5799168/ukraine-quay-lung-voi-cuba-nhung-viet-nam-thi-khong-bao-gio'}
Traceback (most recent call last):
  File "C:\Users\Nguyen Hai Long\AppData\Local\Programs\Python\Python310\lib\site-packages\urllib3\connectionpool.py", line 449, in _make_request
    six.raise_from(e, None)
  File "<string>", line 3, in raise_from
  File "C:\Users\Nguyen Hai Long\AppData\Local\Programs\Python\Python310\lib\site-packages\urllib3\connectionpool.py", line 444, in _make_request
    httplib_response = conn.getresponse()
  File "C:\Users\Nguyen Hai Long\AppData\Local\Programs\Python\Python310\lib\http\client.py", line 1374, in getresponse
    response.begin()
  File "C:\Users\Nguyen Hai Long\AppData\Local\Programs\Python\Python310\lib\http\client.py", line 318, in begin
    version, status, reason = self._read_status()
  File "C:\Users\Nguyen Hai Long\AppData\Local\Programs\Python\Python310\lib\http\client.py", line 279, in _read_status
    line = str(self.fp.readline(_MAXLINE + 1), "iso-8859-1")
  File "C:\Users\Nguyen Hai Long\AppData\Local\Programs\Python\Python310\lib\socket.py", line 705, in readinto
    return self._sock.recv_into(b)
  File "C:\Users\Nguyen Hai Long\AppData\Local\Programs\Python\Python310\lib\ssl.py", line 1273, in recv_into
    return self.read(nbytes, buffer)
  File "C:\Users\Nguyen Hai Long\AppData\Local\Programs\Python\Python310\lib\ssl.py", line 1129, in read
    return self._sslobj.read(len, buffer)
TimeoutError: The read operation timed out

During handling of the above exception, another exception occurred:

Traceback (most recent call last):
  File "C:\Users\Nguyen Hai Long\AppData\Local\Programs\Python\Python310\lib\site-packages\requests\adapters.py", line 489, in send
    resp = conn.urlopen(
  File "C:\Users\Nguyen Hai Long\AppData\Local\Programs\Python\Python310\lib\site-packages\urllib3\connectionpool.py", line 787, in urlopen
    retries = retries.increment(
  File "C:\Users\Nguyen Hai Long\AppData\Local\Programs\Python\Python310\lib\site-packages\urllib3\util\retry.py", line 550, in increment
    raise six.reraise(type(error), error, _stacktrace)
  File "C:\Users\Nguyen Hai Long\AppData\Local\Programs\Python\Python310\lib\site-packages\urllib3\packages\six.py", line 770, in reraise
    raise value
  File "C:\Users\Nguyen Hai Long\AppData\Local\Programs\Python\Python310\lib\site-packages\urllib3\connectionpool.py", line 703, in urlopen
    httplib_response = self._make_request(
  File "C:\Users\Nguyen Hai Long\AppData\Local\Programs\Python\Python310\lib\site-packages\urllib3\connectionpool.py", line 451, in _make_request
    self._raise_timeout(err=e, url=url, timeout_value=read_timeout)
  File "C:\Users\Nguyen Hai Long\AppData\Local\Programs\Python\Python310\lib\site-packages\urllib3\connectionpool.py", line 340, in _raise_timeout
    raise ReadTimeoutError(
urllib3.exceptions.ReadTimeoutError: HTTPSConnectionPool(host='linkhay.com', port=443): Read timed out. (read timeout=10)

During handling of the above exception, another exception occurred:

Traceback (most recent call last):
  File "D:\congTacVienVCC\thang11\crawl_cmt.py", line 86, in crawl_in_post
    res = send_request(link_post, type_crawl, param_scroll_down=False)
  File "D:\congTacVienVCC\thang11\crawl_cmt.py", line 126, in send_request
    res = requests.get(link_cate, headers=header, timeout=10)
  File "C:\Users\Nguyen Hai Long\AppData\Local\Programs\Python\Python310\lib\site-packages\requests\api.py", line 73, in get
    return request("get", url, params=params, **kwargs)
  File "C:\Users\Nguyen Hai Long\AppData\Local\Programs\Python\Python310\lib\site-packages\requests\api.py", line 59, in request
    return session.request(method=method, url=url, **kwargs)
  File "C:\Users\Nguyen Hai Long\AppData\Local\Programs\Python\Python310\lib\site-packages\requests\sessions.py", line 587, in request
    resp = self.send(prep, **send_kwargs)
  File "C:\Users\Nguyen Hai Long\AppData\Local\Programs\Python\Python310\lib\site-packages\requests\sessions.py", line 701, in send
    r = adapter.send(request, **kwargs)
  File "C:\Users\Nguyen Hai Long\AppData\Local\Programs\Python\Python310\lib\site-packages\requests\adapters.py", line 578, in send
    raise ReadTimeout(e, request=request)
requests.exceptions.ReadTimeout: HTTPSConnectionPool(host='linkhay.com', port=443): Read timed out. (read timeout=10)
2022-11-08 10:39:38,367 - ERROR - {'message': 'exception when get comment', 'link_post': 'https://linkhay.com/link/5799168/ukraine-quay-lung-voi-cuba-nhung-viet-nam-thi-khong-bao-gio'}
Traceback (most recent call last):
  File "C:\Users\Nguyen Hai Long\AppData\Local\Programs\Python\Python310\lib\site-packages\urllib3\connectionpool.py", line 449, in _make_request
    six.raise_from(e, None)
  File "<string>", line 3, in raise_from
  File "C:\Users\Nguyen Hai Long\AppData\Local\Programs\Python\Python310\lib\site-packages\urllib3\connectionpool.py", line 444, in _make_request
    httplib_response = conn.getresponse()
  File "C:\Users\Nguyen Hai Long\AppData\Local\Programs\Python\Python310\lib\http\client.py", line 1374, in getresponse
    response.begin()
  File "C:\Users\Nguyen Hai Long\AppData\Local\Programs\Python\Python310\lib\http\client.py", line 318, in begin
    version, status, reason = self._read_status()
  File "C:\Users\Nguyen Hai Long\AppData\Local\Programs\Python\Python310\lib\http\client.py", line 279, in _read_status
    line = str(self.fp.readline(_MAXLINE + 1), "iso-8859-1")
  File "C:\Users\Nguyen Hai Long\AppData\Local\Programs\Python\Python310\lib\socket.py", line 705, in readinto
    return self._sock.recv_into(b)
  File "C:\Users\Nguyen Hai Long\AppData\Local\Programs\Python\Python310\lib\ssl.py", line 1273, in recv_into
    return self.read(nbytes, buffer)
  File "C:\Users\Nguyen Hai Long\AppData\Local\Programs\Python\Python310\lib\ssl.py", line 1129, in read
    return self._sslobj.read(len, buffer)
TimeoutError: The read operation timed out

During handling of the above exception, another exception occurred:

Traceback (most recent call last):
  File "C:\Users\Nguyen Hai Long\AppData\Local\Programs\Python\Python310\lib\site-packages\requests\adapters.py", line 489, in send
    resp = conn.urlopen(
  File "C:\Users\Nguyen Hai Long\AppData\Local\Programs\Python\Python310\lib\site-packages\urllib3\connectionpool.py", line 787, in urlopen
    retries = retries.increment(
  File "C:\Users\Nguyen Hai Long\AppData\Local\Programs\Python\Python310\lib\site-packages\urllib3\util\retry.py", line 550, in increment
    raise six.reraise(type(error), error, _stacktrace)
  File "C:\Users\Nguyen Hai Long\AppData\Local\Programs\Python\Python310\lib\site-packages\urllib3\packages\six.py", line 770, in reraise
    raise value
  File "C:\Users\Nguyen Hai Long\AppData\Local\Programs\Python\Python310\lib\site-packages\urllib3\connectionpool.py", line 703, in urlopen
    httplib_response = self._make_request(
  File "C:\Users\Nguyen Hai Long\AppData\Local\Programs\Python\Python310\lib\site-packages\urllib3\connectionpool.py", line 451, in _make_request
    self._raise_timeout(err=e, url=url, timeout_value=read_timeout)
  File "C:\Users\Nguyen Hai Long\AppData\Local\Programs\Python\Python310\lib\site-packages\urllib3\connectionpool.py", line 340, in _raise_timeout
    raise ReadTimeoutError(
urllib3.exceptions.ReadTimeoutError: HTTPSConnectionPool(host='linkhay.com', port=443): Read timed out. (read timeout=10)

During handling of the above exception, another exception occurred:

Traceback (most recent call last):
  File "D:\congTacVienVCC\thang11\crawl_cmt.py", line 86, in crawl_in_post
    res = send_request(link_post, type_crawl, param_scroll_down=False)
  File "D:\congTacVienVCC\thang11\crawl_cmt.py", line 126, in send_request
    res = requests.get(link_cate, headers=header, timeout=10)
  File "C:\Users\Nguyen Hai Long\AppData\Local\Programs\Python\Python310\lib\site-packages\requests\api.py", line 73, in get
    return request("get", url, params=params, **kwargs)
  File "C:\Users\Nguyen Hai Long\AppData\Local\Programs\Python\Python310\lib\site-packages\requests\api.py", line 59, in request
    return session.request(method=method, url=url, **kwargs)
  File "C:\Users\Nguyen Hai Long\AppData\Local\Programs\Python\Python310\lib\site-packages\requests\sessions.py", line 587, in request
    resp = self.send(prep, **send_kwargs)
  File "C:\Users\Nguyen Hai Long\AppData\Local\Programs\Python\Python310\lib\site-packages\requests\sessions.py", line 701, in send
    r = adapter.send(request, **kwargs)
  File "C:\Users\Nguyen Hai Long\AppData\Local\Programs\Python\Python310\lib\site-packages\requests\adapters.py", line 578, in send
    raise ReadTimeout(e, request=request)
requests.exceptions.ReadTimeout: HTTPSConnectionPool(host='linkhay.com', port=443): Read timed out. (read timeout=10)
2022-11-08 10:39:39,651 - INFO - Thread-1 reupdate link https://linkhay.com/link/5799168/ukraine-quay-lung-voi-cuba-nhung-viet-nam-thi-khong-bao-gio
2022-11-08 10:39:48,261 - INFO - Thread-3 reupdate link https://linkhay.com/link/5799168/ukraine-quay-lung-voi-cuba-nhung-viet-nam-thi-khong-bao-gio
2022-11-08 10:39:49,698 - ERROR - {'message': 'exception when get comment', 'link_post': 'https://linkhay.com/link/5799168/ukraine-quay-lung-voi-cuba-nhung-viet-nam-thi-khong-bao-gio'}
Traceback (most recent call last):
  File "C:\Users\Nguyen Hai Long\AppData\Local\Programs\Python\Python310\lib\site-packages\urllib3\connectionpool.py", line 449, in _make_request
    six.raise_from(e, None)
  File "<string>", line 3, in raise_from
  File "C:\Users\Nguyen Hai Long\AppData\Local\Programs\Python\Python310\lib\site-packages\urllib3\connectionpool.py", line 444, in _make_request
    httplib_response = conn.getresponse()
  File "C:\Users\Nguyen Hai Long\AppData\Local\Programs\Python\Python310\lib\http\client.py", line 1374, in getresponse
    response.begin()
  File "C:\Users\Nguyen Hai Long\AppData\Local\Programs\Python\Python310\lib\http\client.py", line 318, in begin
    version, status, reason = self._read_status()
  File "C:\Users\Nguyen Hai Long\AppData\Local\Programs\Python\Python310\lib\http\client.py", line 279, in _read_status
    line = str(self.fp.readline(_MAXLINE + 1), "iso-8859-1")
  File "C:\Users\Nguyen Hai Long\AppData\Local\Programs\Python\Python310\lib\socket.py", line 705, in readinto
    return self._sock.recv_into(b)
  File "C:\Users\Nguyen Hai Long\AppData\Local\Programs\Python\Python310\lib\ssl.py", line 1273, in recv_into
    return self.read(nbytes, buffer)
  File "C:\Users\Nguyen Hai Long\AppData\Local\Programs\Python\Python310\lib\ssl.py", line 1129, in read
    return self._sslobj.read(len, buffer)
TimeoutError: The read operation timed out

During handling of the above exception, another exception occurred:

Traceback (most recent call last):
  File "C:\Users\Nguyen Hai Long\AppData\Local\Programs\Python\Python310\lib\site-packages\requests\adapters.py", line 489, in send
    resp = conn.urlopen(
  File "C:\Users\Nguyen Hai Long\AppData\Local\Programs\Python\Python310\lib\site-packages\urllib3\connectionpool.py", line 787, in urlopen
    retries = retries.increment(
  File "C:\Users\Nguyen Hai Long\AppData\Local\Programs\Python\Python310\lib\site-packages\urllib3\util\retry.py", line 550, in increment
    raise six.reraise(type(error), error, _stacktrace)
  File "C:\Users\Nguyen Hai Long\AppData\Local\Programs\Python\Python310\lib\site-packages\urllib3\packages\six.py", line 770, in reraise
    raise value
  File "C:\Users\Nguyen Hai Long\AppData\Local\Programs\Python\Python310\lib\site-packages\urllib3\connectionpool.py", line 703, in urlopen
    httplib_response = self._make_request(
  File "C:\Users\Nguyen Hai Long\AppData\Local\Programs\Python\Python310\lib\site-packages\urllib3\connectionpool.py", line 451, in _make_request
    self._raise_timeout(err=e, url=url, timeout_value=read_timeout)
  File "C:\Users\Nguyen Hai Long\AppData\Local\Programs\Python\Python310\lib\site-packages\urllib3\connectionpool.py", line 340, in _raise_timeout
    raise ReadTimeoutError(
urllib3.exceptions.ReadTimeoutError: HTTPSConnectionPool(host='linkhay.com', port=443): Read timed out. (read timeout=10)

During handling of the above exception, another exception occurred:

Traceback (most recent call last):
  File "D:\congTacVienVCC\thang11\crawl_cmt.py", line 86, in crawl_in_post
    res = send_request(link_post, type_crawl, param_scroll_down=False)
  File "D:\congTacVienVCC\thang11\crawl_cmt.py", line 126, in send_request
    res = requests.get(link_cate, headers=header, timeout=10)
  File "C:\Users\Nguyen Hai Long\AppData\Local\Programs\Python\Python310\lib\site-packages\requests\api.py", line 73, in get
    return request("get", url, params=params, **kwargs)
  File "C:\Users\Nguyen Hai Long\AppData\Local\Programs\Python\Python310\lib\site-packages\requests\api.py", line 59, in request
    return session.request(method=method, url=url, **kwargs)
  File "C:\Users\Nguyen Hai Long\AppData\Local\Programs\Python\Python310\lib\site-packages\requests\sessions.py", line 587, in request
    resp = self.send(prep, **send_kwargs)
  File "C:\Users\Nguyen Hai Long\AppData\Local\Programs\Python\Python310\lib\site-packages\requests\sessions.py", line 701, in send
    r = adapter.send(request, **kwargs)
  File "C:\Users\Nguyen Hai Long\AppData\Local\Programs\Python\Python310\lib\site-packages\requests\adapters.py", line 578, in send
    raise ReadTimeout(e, request=request)
requests.exceptions.ReadTimeout: HTTPSConnectionPool(host='linkhay.com', port=443): Read timed out. (read timeout=10)
2022-11-08 10:39:49,699 - INFO - Thread-1 finish reupdate comment link: https://linkhay.com/link/5799168/ukraine-quay-lung-voi-cuba-nhung-viet-nam-thi-khong-bao-gio
2022-11-08 10:39:58,305 - ERROR - {'message': 'exception when get comment', 'link_post': 'https://linkhay.com/link/5799168/ukraine-quay-lung-voi-cuba-nhung-viet-nam-thi-khong-bao-gio'}
Traceback (most recent call last):
  File "C:\Users\Nguyen Hai Long\AppData\Local\Programs\Python\Python310\lib\site-packages\urllib3\connectionpool.py", line 449, in _make_request
    six.raise_from(e, None)
  File "<string>", line 3, in raise_from
  File "C:\Users\Nguyen Hai Long\AppData\Local\Programs\Python\Python310\lib\site-packages\urllib3\connectionpool.py", line 444, in _make_request
    httplib_response = conn.getresponse()
  File "C:\Users\Nguyen Hai Long\AppData\Local\Programs\Python\Python310\lib\http\client.py", line 1374, in getresponse
    response.begin()
  File "C:\Users\Nguyen Hai Long\AppData\Local\Programs\Python\Python310\lib\http\client.py", line 318, in begin
    version, status, reason = self._read_status()
  File "C:\Users\Nguyen Hai Long\AppData\Local\Programs\Python\Python310\lib\http\client.py", line 279, in _read_status
    line = str(self.fp.readline(_MAXLINE + 1), "iso-8859-1")
  File "C:\Users\Nguyen Hai Long\AppData\Local\Programs\Python\Python310\lib\socket.py", line 705, in readinto
    return self._sock.recv_into(b)
  File "C:\Users\Nguyen Hai Long\AppData\Local\Programs\Python\Python310\lib\ssl.py", line 1273, in recv_into
    return self.read(nbytes, buffer)
  File "C:\Users\Nguyen Hai Long\AppData\Local\Programs\Python\Python310\lib\ssl.py", line 1129, in read
    return self._sslobj.read(len, buffer)
TimeoutError: The read operation timed out

During handling of the above exception, another exception occurred:

Traceback (most recent call last):
  File "C:\Users\Nguyen Hai Long\AppData\Local\Programs\Python\Python310\lib\site-packages\requests\adapters.py", line 489, in send
    resp = conn.urlopen(
  File "C:\Users\Nguyen Hai Long\AppData\Local\Programs\Python\Python310\lib\site-packages\urllib3\connectionpool.py", line 787, in urlopen
    retries = retries.increment(
  File "C:\Users\Nguyen Hai Long\AppData\Local\Programs\Python\Python310\lib\site-packages\urllib3\util\retry.py", line 550, in increment
    raise six.reraise(type(error), error, _stacktrace)
  File "C:\Users\Nguyen Hai Long\AppData\Local\Programs\Python\Python310\lib\site-packages\urllib3\packages\six.py", line 770, in reraise
    raise value
  File "C:\Users\Nguyen Hai Long\AppData\Local\Programs\Python\Python310\lib\site-packages\urllib3\connectionpool.py", line 703, in urlopen
    httplib_response = self._make_request(
  File "C:\Users\Nguyen Hai Long\AppData\Local\Programs\Python\Python310\lib\site-packages\urllib3\connectionpool.py", line 451, in _make_request
    self._raise_timeout(err=e, url=url, timeout_value=read_timeout)
  File "C:\Users\Nguyen Hai Long\AppData\Local\Programs\Python\Python310\lib\site-packages\urllib3\connectionpool.py", line 340, in _raise_timeout
    raise ReadTimeoutError(
urllib3.exceptions.ReadTimeoutError: HTTPSConnectionPool(host='linkhay.com', port=443): Read timed out. (read timeout=10)

During handling of the above exception, another exception occurred:

Traceback (most recent call last):
  File "D:\congTacVienVCC\thang11\crawl_cmt.py", line 86, in crawl_in_post
    res = send_request(link_post, type_crawl, param_scroll_down=False)
  File "D:\congTacVienVCC\thang11\crawl_cmt.py", line 126, in send_request
    res = requests.get(link_cate, headers=header, timeout=10)
  File "C:\Users\Nguyen Hai Long\AppData\Local\Programs\Python\Python310\lib\site-packages\requests\api.py", line 73, in get
    return request("get", url, params=params, **kwargs)
  File "C:\Users\Nguyen Hai Long\AppData\Local\Programs\Python\Python310\lib\site-packages\requests\api.py", line 59, in request
    return session.request(method=method, url=url, **kwargs)
  File "C:\Users\Nguyen Hai Long\AppData\Local\Programs\Python\Python310\lib\site-packages\requests\sessions.py", line 587, in request
    resp = self.send(prep, **send_kwargs)
  File "C:\Users\Nguyen Hai Long\AppData\Local\Programs\Python\Python310\lib\site-packages\requests\sessions.py", line 701, in send
    r = adapter.send(request, **kwargs)
  File "C:\Users\Nguyen Hai Long\AppData\Local\Programs\Python\Python310\lib\site-packages\requests\adapters.py", line 578, in send
    raise ReadTimeout(e, request=request)
requests.exceptions.ReadTimeout: HTTPSConnectionPool(host='linkhay.com', port=443): Read timed out. (read timeout=10)
2022-11-08 10:39:58,306 - INFO - Thread-3 finish reupdate comment link: https://linkhay.com/link/5799168/ukraine-quay-lung-voi-cuba-nhung-viet-nam-thi-khong-bao-gio
