2022-11-08 11:34:26,261 - INFO - 

_____________________________new_log_____________________________
2022-11-08 11:34:26,306 - INFO - Thread-1 update link: https://thanhnien.vn/thu-tuong-pham-minh-chinh-toi-phnompenh-bat-dau-tham-chinh-thuc-campuchia-post1518996.html
2022-11-08 11:34:26,307 - INFO - Thread-2 update link: https://thanhnien.vn/hoang-phi-dat-vang-mat-bang-tien-ti-bo-trong-vi-co-che-post1518981.html
2022-11-08 11:34:26,307 - INFO - Thread-3 update link: https://thanhnien.vn/dai-bieu-quoc-hoi-dieu-hanh-quy-binh-on-gia-xang-dau-rat-co-van-de-post1518954.html
2022-11-08 11:34:26,432 - INFO - Thread-2 finish update comment link: https://thanhnien.vn/hoang-phi-dat-vang-mat-bang-tien-ti-bo-trong-vi-co-che-post1518981.html
2022-11-08 11:34:26,433 - INFO - Thread-2 update link: https://vnexpress.net/nha-ong-mo-tran-cho-nang-xuyen-thang-vao-trong-4533064.html
2022-11-08 11:34:26,440 - INFO - Thread-3 finish update comment link: https://thanhnien.vn/dai-bieu-quoc-hoi-dieu-hanh-quy-binh-on-gia-xang-dau-rat-co-van-de-post1518954.html
2022-11-08 11:34:26,440 - INFO - Thread-3 update link: https://vnexpress.net/cuoc-chien-cua-hai-me-con-cung-bi-ung-thu-4530818.html
2022-11-08 11:34:26,444 - INFO - Thread-1 finish update comment link: https://thanhnien.vn/thu-tuong-pham-minh-chinh-toi-phnompenh-bat-dau-tham-chinh-thuc-campuchia-post1518996.html
2022-11-08 11:34:26,445 - INFO - Thread-1 update link: https://vnexpress.net/chan-gio-heo-ham-du-du-4533177.html
2022-11-08 11:34:38,839 - INFO - Thread-2 finish update comment link: https://vnexpress.net/nha-ong-mo-tran-cho-nang-xuyen-thang-vao-trong-4533064.html
2022-11-08 11:34:38,839 - INFO - Thread-2 update link: https://tuoitre.vn/biet-phu-4-mat-tien-cua-vo-cuu-bi-thu-thanh-uy-ubnd-tp-kon-tum-co-dau-hieu-co-y-lam-trai-20221107210633113.htm
2022-11-08 11:34:38,840 - INFO - Thread-3 finish update comment link: https://vnexpress.net/cuoc-chien-cua-hai-me-con-cung-bi-ung-thu-4530818.html
2022-11-08 11:34:38,840 - INFO - Thread-3 update link: https://tuoitre.vn/lam-dong-thay-the-bi-thu-thanh-uy-bao-loc-20221107192803721.htm
2022-11-08 11:34:43,883 - INFO - Thread-1 finish update comment link: https://vnexpress.net/chan-gio-heo-ham-du-du-4533177.html
2022-11-08 11:34:43,883 - INFO - Thread-1 update link: https://tuoitre.vn/phai-thu-hoi-toi-da-tai-san-tham-nhung-20221105075130123.htm
2022-11-08 11:34:51,548 - INFO - Thread-2 finish update comment link: https://tuoitre.vn/biet-phu-4-mat-tien-cua-vo-cuu-bi-thu-thanh-uy-ubnd-tp-kon-tum-co-dau-hieu-co-y-lam-trai-20221107210633113.htm
2022-11-08 11:34:51,549 - INFO - Thread-2 update link: https://vietnamnet.vn/de-nghi-bo-quy-binh-on-gia-xang-dau-2078174.html
2022-11-08 11:34:51,633 - INFO - Thread-2 finish update comment link: https://vietnamnet.vn/de-nghi-bo-quy-binh-on-gia-xang-dau-2078174.html
2022-11-08 11:34:51,633 - INFO - Thread-2 update link: https://vietnamnet.vn/bo-truong-noi-vu-se-co-bo-chinh-sach-thu-hut-trong-dung-nhan-tai-2077360.html
2022-11-08 11:34:51,712 - INFO - Thread-2 finish update comment link: https://vietnamnet.vn/bo-truong-noi-vu-se-co-bo-chinh-sach-thu-hut-trong-dung-nhan-tai-2077360.html
2022-11-08 11:34:51,712 - INFO - Thread-2 update link: https://vietnamnet.vn/viet-nam-trung-quoc-khi-hai-ben-deu-dac-biet-coi-trong-vi-the-cua-nhau-2076841.html
2022-11-08 11:34:51,833 - INFO - Thread-2 finish update comment link: https://vietnamnet.vn/viet-nam-trung-quoc-khi-hai-ben-deu-dac-biet-coi-trong-vi-the-cua-nhau-2076841.html
2022-11-08 11:34:51,833 - INFO - Thread-2 update link: https://linkhay.com/link/5798180/ronaldo-xo-xat-voi-trung-ve-cao-1-96-m
2022-11-08 11:34:52,131 - INFO - Thread-3 finish update comment link: https://tuoitre.vn/lam-dong-thay-the-bi-thu-thanh-uy-bao-loc-20221107192803721.htm
2022-11-08 11:34:52,132 - INFO - Thread-3 update link: https://linkhay.com/link/5799168/ukraine-quay-lung-voi-cuba-nhung-viet-nam-thi-khong-bao-gio
2022-11-08 11:34:56,377 - INFO - Thread-2 finish update comment link: https://linkhay.com/link/5798180/ronaldo-xo-xat-voi-trung-ve-cao-1-96-m
2022-11-08 11:34:56,377 - INFO - Thread-2 update link: https://linkhay.com/link/5796013/ha-noi-yeu-cau-dep-bo-toan-bo-cay-xang-via-he
2022-11-08 11:35:00,607 - INFO - Thread-2 finish update comment link: https://linkhay.com/link/5796013/ha-noi-yeu-cau-dep-bo-toan-bo-cay-xang-via-he
2022-11-08 11:35:00,607 - INFO - Thread-2 update link: https://thanhnien.vn/thu-tuong-pham-minh-chinh-toi-phnompenh-bat-dau-tham-chinh-thuc-campuchia-post1518996.html
2022-11-08 11:35:00,715 - INFO - Thread-2 finish update comment link: https://thanhnien.vn/thu-tuong-pham-minh-chinh-toi-phnompenh-bat-dau-tham-chinh-thuc-campuchia-post1518996.html
2022-11-08 11:35:00,715 - INFO - Thread-2 update link: https://thanhnien.vn/hoang-phi-dat-vang-mat-bang-tien-ti-bo-trong-vi-co-che-post1518981.html
2022-11-08 11:35:00,834 - INFO - Thread-2 finish update comment link: https://thanhnien.vn/hoang-phi-dat-vang-mat-bang-tien-ti-bo-trong-vi-co-che-post1518981.html
2022-11-08 11:35:00,834 - INFO - Thread-2 update link: https://thanhnien.vn/dai-bieu-quoc-hoi-dieu-hanh-quy-binh-on-gia-xang-dau-rat-co-van-de-post1518954.html
2022-11-08 11:35:00,936 - INFO - Thread-2 finish update comment link: https://thanhnien.vn/dai-bieu-quoc-hoi-dieu-hanh-quy-binh-on-gia-xang-dau-rat-co-van-de-post1518954.html
2022-11-08 11:35:00,936 - INFO - Thread-2 update link: https://vnexpress.net/nha-ong-mo-tran-cho-nang-xuyen-thang-vao-trong-4533064.html
2022-11-08 11:35:02,217 - ERROR - {'message': 'exception when get comment', 'link_post': 'https://linkhay.com/link/5799168/ukraine-quay-lung-voi-cuba-nhung-viet-nam-thi-khong-bao-gio'}
Traceback (most recent call last):
  File "C:\Users\Nguyen Hai Long\AppData\Local\Programs\Python\Python310\lib\site-packages\urllib3\connectionpool.py", line 449, in _make_request
    six.raise_from(e, None)
  File "<string>", line 3, in raise_from
  File "C:\Users\Nguyen Hai Long\AppData\Local\Programs\Python\Python310\lib\site-packages\urllib3\connectionpool.py", line 444, in _make_request
    httplib_response = conn.getresponse()
  File "C:\Users\Nguyen Hai Long\AppData\Local\Programs\Python\Python310\lib\http\client.py", line 1374, in getresponse
    response.begin()
  File "C:\Users\Nguyen Hai Long\AppData\Local\Programs\Python\Python310\lib\http\client.py", line 318, in begin
    version, status, reason = self._read_status()
  File "C:\Users\Nguyen Hai Long\AppData\Local\Programs\Python\Python310\lib\http\client.py", line 279, in _read_status
    line = str(self.fp.readline(_MAXLINE + 1), "iso-8859-1")
  File "C:\Users\Nguyen Hai Long\AppData\Local\Programs\Python\Python310\lib\socket.py", line 705, in readinto
    return self._sock.recv_into(b)
  File "C:\Users\Nguyen Hai Long\AppData\Local\Programs\Python\Python310\lib\ssl.py", line 1273, in recv_into
    return self.read(nbytes, buffer)
  File "C:\Users\Nguyen Hai Long\AppData\Local\Programs\Python\Python310\lib\ssl.py", line 1129, in read
    return self._sslobj.read(len, buffer)
TimeoutError: The read operation timed out

During handling of the above exception, another exception occurred:

Traceback (most recent call last):
  File "C:\Users\Nguyen Hai Long\AppData\Local\Programs\Python\Python310\lib\site-packages\requests\adapters.py", line 489, in send
    resp = conn.urlopen(
  File "C:\Users\Nguyen Hai Long\AppData\Local\Programs\Python\Python310\lib\site-packages\urllib3\connectionpool.py", line 787, in urlopen
    retries = retries.increment(
  File "C:\Users\Nguyen Hai Long\AppData\Local\Programs\Python\Python310\lib\site-packages\urllib3\util\retry.py", line 550, in increment
    raise six.reraise(type(error), error, _stacktrace)
  File "C:\Users\Nguyen Hai Long\AppData\Local\Programs\Python\Python310\lib\site-packages\urllib3\packages\six.py", line 770, in reraise
    raise value
  File "C:\Users\Nguyen Hai Long\AppData\Local\Programs\Python\Python310\lib\site-packages\urllib3\connectionpool.py", line 703, in urlopen
    httplib_response = self._make_request(
  File "C:\Users\Nguyen Hai Long\AppData\Local\Programs\Python\Python310\lib\site-packages\urllib3\connectionpool.py", line 451, in _make_request
    self._raise_timeout(err=e, url=url, timeout_value=read_timeout)
  File "C:\Users\Nguyen Hai Long\AppData\Local\Programs\Python\Python310\lib\site-packages\urllib3\connectionpool.py", line 340, in _raise_timeout
    raise ReadTimeoutError(
urllib3.exceptions.ReadTimeoutError: HTTPSConnectionPool(host='linkhay.com', port=443): Read timed out. (read timeout=10)

During handling of the above exception, another exception occurred:

Traceback (most recent call last):
  File "d:\congTacVienVCC\thang11\crawl_cmt.py", line 86, in crawl_in_post
    res = send_request(link_post, type_crawl, param_scroll_down=False)
  File "d:\congTacVienVCC\thang11\crawl_cmt.py", line 126, in send_request
    res = requests.get(link_cate, headers=header, timeout=10)
  File "C:\Users\Nguyen Hai Long\AppData\Local\Programs\Python\Python310\lib\site-packages\requests\api.py", line 73, in get
    return request("get", url, params=params, **kwargs)
  File "C:\Users\Nguyen Hai Long\AppData\Local\Programs\Python\Python310\lib\site-packages\requests\api.py", line 59, in request
    return session.request(method=method, url=url, **kwargs)
  File "C:\Users\Nguyen Hai Long\AppData\Local\Programs\Python\Python310\lib\site-packages\requests\sessions.py", line 587, in request
    resp = self.send(prep, **send_kwargs)
  File "C:\Users\Nguyen Hai Long\AppData\Local\Programs\Python\Python310\lib\site-packages\requests\sessions.py", line 701, in send
    r = adapter.send(request, **kwargs)
  File "C:\Users\Nguyen Hai Long\AppData\Local\Programs\Python\Python310\lib\site-packages\requests\adapters.py", line 578, in send
    raise ReadTimeout(e, request=request)
requests.exceptions.ReadTimeout: HTTPSConnectionPool(host='linkhay.com', port=443): Read timed out. (read timeout=10)
2022-11-08 11:35:02,253 - INFO - Thread-3 finish update comment link: https://linkhay.com/link/5799168/ukraine-quay-lung-voi-cuba-nhung-viet-nam-thi-khong-bao-gio
2022-11-08 11:35:02,253 - INFO - Thread-3 update link: https://vnexpress.net/cuoc-chien-cua-hai-me-con-cung-bi-ung-thu-4530818.html
2022-11-08 11:35:09,566 - INFO - Thread-2 finish update comment link: https://vnexpress.net/nha-ong-mo-tran-cho-nang-xuyen-thang-vao-trong-4533064.html
2022-11-08 11:35:09,566 - INFO - Thread-2 update link: https://vnexpress.net/chan-gio-heo-ham-du-du-4533177.html
2022-11-08 11:35:10,400 - INFO - Thread-3 finish update comment link: https://vnexpress.net/cuoc-chien-cua-hai-me-con-cung-bi-ung-thu-4530818.html
2022-11-08 11:35:10,400 - INFO - Thread-3 update link: https://tuoitre.vn/biet-phu-4-mat-tien-cua-vo-cuu-bi-thu-thanh-uy-ubnd-tp-kon-tum-co-dau-hieu-co-y-lam-trai-20221107210633113.htm
2022-11-08 11:35:19,085 - INFO - Thread-2 finish update comment link: https://vnexpress.net/chan-gio-heo-ham-du-du-4533177.html
2022-11-08 11:35:19,085 - INFO - Thread-2 update link: https://tuoitre.vn/lam-dong-thay-the-bi-thu-thanh-uy-bao-loc-20221107192803721.htm
2022-11-08 11:35:22,167 - INFO - Thread-3 finish update comment link: https://tuoitre.vn/biet-phu-4-mat-tien-cua-vo-cuu-bi-thu-thanh-uy-ubnd-tp-kon-tum-co-dau-hieu-co-y-lam-trai-20221107210633113.htm
2022-11-08 11:35:22,167 - INFO - Thread-3 update link: https://tuoitre.vn/phai-thu-hoi-toi-da-tai-san-tham-nhung-20221105075130123.htm
2022-11-08 11:35:30,669 - INFO - Thread-2 finish update comment link: https://tuoitre.vn/lam-dong-thay-the-bi-thu-thanh-uy-bao-loc-20221107192803721.htm
2022-11-08 11:35:30,669 - INFO - Thread-2 update link: https://vietnamnet.vn/de-nghi-bo-quy-binh-on-gia-xang-dau-2078174.html
2022-11-08 11:35:30,747 - INFO - Thread-2 finish update comment link: https://vietnamnet.vn/de-nghi-bo-quy-binh-on-gia-xang-dau-2078174.html
2022-11-08 11:35:30,747 - INFO - Thread-2 update link: https://vietnamnet.vn/bo-truong-noi-vu-se-co-bo-chinh-sach-thu-hut-trong-dung-nhan-tai-2077360.html
2022-11-08 11:35:30,838 - INFO - Thread-2 finish update comment link: https://vietnamnet.vn/bo-truong-noi-vu-se-co-bo-chinh-sach-thu-hut-trong-dung-nhan-tai-2077360.html
2022-11-08 11:35:30,838 - INFO - Thread-2 update link: https://vietnamnet.vn/viet-nam-trung-quoc-khi-hai-ben-deu-dac-biet-coi-trong-vi-the-cua-nhau-2076841.html
2022-11-08 11:35:30,943 - INFO - Thread-2 finish update comment link: https://vietnamnet.vn/viet-nam-trung-quoc-khi-hai-ben-deu-dac-biet-coi-trong-vi-the-cua-nhau-2076841.html
2022-11-08 11:35:30,943 - INFO - Thread-2 update link: https://linkhay.com/link/5798180/ronaldo-xo-xat-voi-trung-ve-cao-1-96-m
2022-11-08 11:35:37,079 - INFO - Thread-2 finish update comment link: https://linkhay.com/link/5798180/ronaldo-xo-xat-voi-trung-ve-cao-1-96-m
2022-11-08 11:35:37,079 - INFO - Thread-2 update link: https://linkhay.com/link/5799168/ukraine-quay-lung-voi-cuba-nhung-viet-nam-thi-khong-bao-gio
2022-11-08 11:35:38,583 - INFO - Thread-1 finish update comment link: https://tuoitre.vn/phai-thu-hoi-toi-da-tai-san-tham-nhung-20221105075130123.htm
2022-11-08 11:35:38,583 - INFO - Thread-1 update link: https://linkhay.com/link/5796013/ha-noi-yeu-cau-dep-bo-toan-bo-cay-xang-via-he
2022-11-08 11:35:42,925 - INFO - Thread-1 finish update comment link: https://linkhay.com/link/5796013/ha-noi-yeu-cau-dep-bo-toan-bo-cay-xang-via-he
2022-11-08 11:35:42,925 - INFO - Thread-1 reupdate link https://linkhay.com/link/5799168/ukraine-quay-lung-voi-cuba-nhung-viet-nam-thi-khong-bao-gio
2022-11-08 11:35:47,120 - ERROR - {'message': 'exception when get comment', 'link_post': 'https://linkhay.com/link/5799168/ukraine-quay-lung-voi-cuba-nhung-viet-nam-thi-khong-bao-gio'}
Traceback (most recent call last):
  File "C:\Users\Nguyen Hai Long\AppData\Local\Programs\Python\Python310\lib\site-packages\urllib3\connectionpool.py", line 449, in _make_request
    six.raise_from(e, None)
  File "<string>", line 3, in raise_from
  File "C:\Users\Nguyen Hai Long\AppData\Local\Programs\Python\Python310\lib\site-packages\urllib3\connectionpool.py", line 444, in _make_request
    httplib_response = conn.getresponse()
  File "C:\Users\Nguyen Hai Long\AppData\Local\Programs\Python\Python310\lib\http\client.py", line 1374, in getresponse
    response.begin()
  File "C:\Users\Nguyen Hai Long\AppData\Local\Programs\Python\Python310\lib\http\client.py", line 318, in begin
    version, status, reason = self._read_status()
  File "C:\Users\Nguyen Hai Long\AppData\Local\Programs\Python\Python310\lib\http\client.py", line 279, in _read_status
    line = str(self.fp.readline(_MAXLINE + 1), "iso-8859-1")
  File "C:\Users\Nguyen Hai Long\AppData\Local\Programs\Python\Python310\lib\socket.py", line 705, in readinto
    return self._sock.recv_into(b)
  File "C:\Users\Nguyen Hai Long\AppData\Local\Programs\Python\Python310\lib\ssl.py", line 1273, in recv_into
    return self.read(nbytes, buffer)
  File "C:\Users\Nguyen Hai Long\AppData\Local\Programs\Python\Python310\lib\ssl.py", line 1129, in read
    return self._sslobj.read(len, buffer)
TimeoutError: The read operation timed out

During handling of the above exception, another exception occurred:

Traceback (most recent call last):
  File "C:\Users\Nguyen Hai Long\AppData\Local\Programs\Python\Python310\lib\site-packages\requests\adapters.py", line 489, in send
    resp = conn.urlopen(
  File "C:\Users\Nguyen Hai Long\AppData\Local\Programs\Python\Python310\lib\site-packages\urllib3\connectionpool.py", line 787, in urlopen
    retries = retries.increment(
  File "C:\Users\Nguyen Hai Long\AppData\Local\Programs\Python\Python310\lib\site-packages\urllib3\util\retry.py", line 550, in increment
    raise six.reraise(type(error), error, _stacktrace)
  File "C:\Users\Nguyen Hai Long\AppData\Local\Programs\Python\Python310\lib\site-packages\urllib3\packages\six.py", line 770, in reraise
    raise value
  File "C:\Users\Nguyen Hai Long\AppData\Local\Programs\Python\Python310\lib\site-packages\urllib3\connectionpool.py", line 703, in urlopen
    httplib_response = self._make_request(
  File "C:\Users\Nguyen Hai Long\AppData\Local\Programs\Python\Python310\lib\site-packages\urllib3\connectionpool.py", line 451, in _make_request
    self._raise_timeout(err=e, url=url, timeout_value=read_timeout)
  File "C:\Users\Nguyen Hai Long\AppData\Local\Programs\Python\Python310\lib\site-packages\urllib3\connectionpool.py", line 340, in _raise_timeout
    raise ReadTimeoutError(
urllib3.exceptions.ReadTimeoutError: HTTPSConnectionPool(host='linkhay.com', port=443): Read timed out. (read timeout=10)

During handling of the above exception, another exception occurred:

Traceback (most recent call last):
  File "d:\congTacVienVCC\thang11\crawl_cmt.py", line 86, in crawl_in_post
    res = send_request(link_post, type_crawl, param_scroll_down=False)
  File "d:\congTacVienVCC\thang11\crawl_cmt.py", line 126, in send_request
    res = requests.get(link_cate, headers=header, timeout=10)
  File "C:\Users\Nguyen Hai Long\AppData\Local\Programs\Python\Python310\lib\site-packages\requests\api.py", line 73, in get
    return request("get", url, params=params, **kwargs)
  File "C:\Users\Nguyen Hai Long\AppData\Local\Programs\Python\Python310\lib\site-packages\requests\api.py", line 59, in request
    return session.request(method=method, url=url, **kwargs)
  File "C:\Users\Nguyen Hai Long\AppData\Local\Programs\Python\Python310\lib\site-packages\requests\sessions.py", line 587, in request
    resp = self.send(prep, **send_kwargs)
  File "C:\Users\Nguyen Hai Long\AppData\Local\Programs\Python\Python310\lib\site-packages\requests\sessions.py", line 701, in send
    r = adapter.send(request, **kwargs)
  File "C:\Users\Nguyen Hai Long\AppData\Local\Programs\Python\Python310\lib\site-packages\requests\adapters.py", line 578, in send
    raise ReadTimeout(e, request=request)
requests.exceptions.ReadTimeout: HTTPSConnectionPool(host='linkhay.com', port=443): Read timed out. (read timeout=10)
2022-11-08 11:35:47,121 - INFO - Thread-2 finish update comment link: https://linkhay.com/link/5799168/ukraine-quay-lung-voi-cuba-nhung-viet-nam-thi-khong-bao-gio
2022-11-08 11:35:47,121 - INFO - Thread-2 reupdate link https://linkhay.com/link/5799168/ukraine-quay-lung-voi-cuba-nhung-viet-nam-thi-khong-bao-gio
2022-11-08 11:35:53,014 - ERROR - {'message': 'exception when get comment', 'link_post': 'https://linkhay.com/link/5799168/ukraine-quay-lung-voi-cuba-nhung-viet-nam-thi-khong-bao-gio'}
Traceback (most recent call last):
  File "C:\Users\Nguyen Hai Long\AppData\Local\Programs\Python\Python310\lib\site-packages\urllib3\connectionpool.py", line 449, in _make_request
    six.raise_from(e, None)
  File "<string>", line 3, in raise_from
  File "C:\Users\Nguyen Hai Long\AppData\Local\Programs\Python\Python310\lib\site-packages\urllib3\connectionpool.py", line 444, in _make_request
    httplib_response = conn.getresponse()
  File "C:\Users\Nguyen Hai Long\AppData\Local\Programs\Python\Python310\lib\http\client.py", line 1374, in getresponse
    response.begin()
  File "C:\Users\Nguyen Hai Long\AppData\Local\Programs\Python\Python310\lib\http\client.py", line 318, in begin
    version, status, reason = self._read_status()
  File "C:\Users\Nguyen Hai Long\AppData\Local\Programs\Python\Python310\lib\http\client.py", line 279, in _read_status
    line = str(self.fp.readline(_MAXLINE + 1), "iso-8859-1")
  File "C:\Users\Nguyen Hai Long\AppData\Local\Programs\Python\Python310\lib\socket.py", line 705, in readinto
    return self._sock.recv_into(b)
  File "C:\Users\Nguyen Hai Long\AppData\Local\Programs\Python\Python310\lib\ssl.py", line 1273, in recv_into
    return self.read(nbytes, buffer)
  File "C:\Users\Nguyen Hai Long\AppData\Local\Programs\Python\Python310\lib\ssl.py", line 1129, in read
    return self._sslobj.read(len, buffer)
TimeoutError: The read operation timed out

During handling of the above exception, another exception occurred:

Traceback (most recent call last):
  File "C:\Users\Nguyen Hai Long\AppData\Local\Programs\Python\Python310\lib\site-packages\requests\adapters.py", line 489, in send
    resp = conn.urlopen(
  File "C:\Users\Nguyen Hai Long\AppData\Local\Programs\Python\Python310\lib\site-packages\urllib3\connectionpool.py", line 787, in urlopen
    retries = retries.increment(
  File "C:\Users\Nguyen Hai Long\AppData\Local\Programs\Python\Python310\lib\site-packages\urllib3\util\retry.py", line 550, in increment
    raise six.reraise(type(error), error, _stacktrace)
  File "C:\Users\Nguyen Hai Long\AppData\Local\Programs\Python\Python310\lib\site-packages\urllib3\packages\six.py", line 770, in reraise
    raise value
  File "C:\Users\Nguyen Hai Long\AppData\Local\Programs\Python\Python310\lib\site-packages\urllib3\connectionpool.py", line 703, in urlopen
    httplib_response = self._make_request(
  File "C:\Users\Nguyen Hai Long\AppData\Local\Programs\Python\Python310\lib\site-packages\urllib3\connectionpool.py", line 451, in _make_request
    self._raise_timeout(err=e, url=url, timeout_value=read_timeout)
  File "C:\Users\Nguyen Hai Long\AppData\Local\Programs\Python\Python310\lib\site-packages\urllib3\connectionpool.py", line 340, in _raise_timeout
    raise ReadTimeoutError(
urllib3.exceptions.ReadTimeoutError: HTTPSConnectionPool(host='linkhay.com', port=443): Read timed out. (read timeout=10)

During handling of the above exception, another exception occurred:

Traceback (most recent call last):
  File "d:\congTacVienVCC\thang11\crawl_cmt.py", line 86, in crawl_in_post
    res = send_request(link_post, type_crawl, param_scroll_down=False)
  File "d:\congTacVienVCC\thang11\crawl_cmt.py", line 126, in send_request
    res = requests.get(link_cate, headers=header, timeout=10)
  File "C:\Users\Nguyen Hai Long\AppData\Local\Programs\Python\Python310\lib\site-packages\requests\api.py", line 73, in get
    return request("get", url, params=params, **kwargs)
  File "C:\Users\Nguyen Hai Long\AppData\Local\Programs\Python\Python310\lib\site-packages\requests\api.py", line 59, in request
    return session.request(method=method, url=url, **kwargs)
  File "C:\Users\Nguyen Hai Long\AppData\Local\Programs\Python\Python310\lib\site-packages\requests\sessions.py", line 587, in request
    resp = self.send(prep, **send_kwargs)
  File "C:\Users\Nguyen Hai Long\AppData\Local\Programs\Python\Python310\lib\site-packages\requests\sessions.py", line 701, in send
    r = adapter.send(request, **kwargs)
  File "C:\Users\Nguyen Hai Long\AppData\Local\Programs\Python\Python310\lib\site-packages\requests\adapters.py", line 578, in send
    raise ReadTimeout(e, request=request)
requests.exceptions.ReadTimeout: HTTPSConnectionPool(host='linkhay.com', port=443): Read timed out. (read timeout=10)
2022-11-08 11:35:53,015 - INFO - Thread-1 finish reupdate comment link: https://linkhay.com/link/5799168/ukraine-quay-lung-voi-cuba-nhung-viet-nam-thi-khong-bao-gio
2022-11-08 11:35:57,179 - ERROR - {'message': 'exception when get comment', 'link_post': 'https://linkhay.com/link/5799168/ukraine-quay-lung-voi-cuba-nhung-viet-nam-thi-khong-bao-gio'}
Traceback (most recent call last):
  File "C:\Users\Nguyen Hai Long\AppData\Local\Programs\Python\Python310\lib\site-packages\urllib3\connectionpool.py", line 449, in _make_request
    six.raise_from(e, None)
  File "<string>", line 3, in raise_from
  File "C:\Users\Nguyen Hai Long\AppData\Local\Programs\Python\Python310\lib\site-packages\urllib3\connectionpool.py", line 444, in _make_request
    httplib_response = conn.getresponse()
  File "C:\Users\Nguyen Hai Long\AppData\Local\Programs\Python\Python310\lib\http\client.py", line 1374, in getresponse
    response.begin()
  File "C:\Users\Nguyen Hai Long\AppData\Local\Programs\Python\Python310\lib\http\client.py", line 318, in begin
    version, status, reason = self._read_status()
  File "C:\Users\Nguyen Hai Long\AppData\Local\Programs\Python\Python310\lib\http\client.py", line 279, in _read_status
    line = str(self.fp.readline(_MAXLINE + 1), "iso-8859-1")
  File "C:\Users\Nguyen Hai Long\AppData\Local\Programs\Python\Python310\lib\socket.py", line 705, in readinto
    return self._sock.recv_into(b)
  File "C:\Users\Nguyen Hai Long\AppData\Local\Programs\Python\Python310\lib\ssl.py", line 1273, in recv_into
    return self.read(nbytes, buffer)
  File "C:\Users\Nguyen Hai Long\AppData\Local\Programs\Python\Python310\lib\ssl.py", line 1129, in read
    return self._sslobj.read(len, buffer)
TimeoutError: The read operation timed out

During handling of the above exception, another exception occurred:

Traceback (most recent call last):
  File "C:\Users\Nguyen Hai Long\AppData\Local\Programs\Python\Python310\lib\site-packages\requests\adapters.py", line 489, in send
    resp = conn.urlopen(
  File "C:\Users\Nguyen Hai Long\AppData\Local\Programs\Python\Python310\lib\site-packages\urllib3\connectionpool.py", line 787, in urlopen
    retries = retries.increment(
  File "C:\Users\Nguyen Hai Long\AppData\Local\Programs\Python\Python310\lib\site-packages\urllib3\util\retry.py", line 550, in increment
    raise six.reraise(type(error), error, _stacktrace)
  File "C:\Users\Nguyen Hai Long\AppData\Local\Programs\Python\Python310\lib\site-packages\urllib3\packages\six.py", line 770, in reraise
    raise value
  File "C:\Users\Nguyen Hai Long\AppData\Local\Programs\Python\Python310\lib\site-packages\urllib3\connectionpool.py", line 703, in urlopen
    httplib_response = self._make_request(
  File "C:\Users\Nguyen Hai Long\AppData\Local\Programs\Python\Python310\lib\site-packages\urllib3\connectionpool.py", line 451, in _make_request
    self._raise_timeout(err=e, url=url, timeout_value=read_timeout)
  File "C:\Users\Nguyen Hai Long\AppData\Local\Programs\Python\Python310\lib\site-packages\urllib3\connectionpool.py", line 340, in _raise_timeout
    raise ReadTimeoutError(
urllib3.exceptions.ReadTimeoutError: HTTPSConnectionPool(host='linkhay.com', port=443): Read timed out. (read timeout=10)

During handling of the above exception, another exception occurred:

Traceback (most recent call last):
  File "d:\congTacVienVCC\thang11\crawl_cmt.py", line 86, in crawl_in_post
    res = send_request(link_post, type_crawl, param_scroll_down=False)
  File "d:\congTacVienVCC\thang11\crawl_cmt.py", line 126, in send_request
    res = requests.get(link_cate, headers=header, timeout=10)
  File "C:\Users\Nguyen Hai Long\AppData\Local\Programs\Python\Python310\lib\site-packages\requests\api.py", line 73, in get
    return request("get", url, params=params, **kwargs)
  File "C:\Users\Nguyen Hai Long\AppData\Local\Programs\Python\Python310\lib\site-packages\requests\api.py", line 59, in request
    return session.request(method=method, url=url, **kwargs)
  File "C:\Users\Nguyen Hai Long\AppData\Local\Programs\Python\Python310\lib\site-packages\requests\sessions.py", line 587, in request
    resp = self.send(prep, **send_kwargs)
  File "C:\Users\Nguyen Hai Long\AppData\Local\Programs\Python\Python310\lib\site-packages\requests\sessions.py", line 701, in send
    r = adapter.send(request, **kwargs)
  File "C:\Users\Nguyen Hai Long\AppData\Local\Programs\Python\Python310\lib\site-packages\requests\adapters.py", line 578, in send
    raise ReadTimeout(e, request=request)
requests.exceptions.ReadTimeout: HTTPSConnectionPool(host='linkhay.com', port=443): Read timed out. (read timeout=10)
2022-11-08 11:35:57,180 - INFO - Thread-2 finish reupdate comment link: https://linkhay.com/link/5799168/ukraine-quay-lung-voi-cuba-nhung-viet-nam-thi-khong-bao-gio
2022-11-08 11:36:16,050 - INFO - Thread-3 finish update comment link: https://tuoitre.vn/phai-thu-hoi-toi-da-tai-san-tham-nhung-20221105075130123.htm
